[2025-05-15T20:48:17.388+0000] {local_task_job_runner.py:123} INFO - ::group::Pre task execution logs
[2025-05-15T20:48:17.414+0000] {taskinstance.py:2613} INFO - Dependencies all met for dep_context=non-requeueable deps ti=<TaskInstance: 03_load_data.load_shopee manual__2025-05-15T20:48:15.543774+00:00 [queued]>
[2025-05-15T20:48:17.426+0000] {taskinstance.py:2613} INFO - Dependencies all met for dep_context=requeueable deps ti=<TaskInstance: 03_load_data.load_shopee manual__2025-05-15T20:48:15.543774+00:00 [queued]>
[2025-05-15T20:48:17.427+0000] {taskinstance.py:2866} INFO - Starting attempt 1 of 1
[2025-05-15T20:48:17.444+0000] {taskinstance.py:2889} INFO - Executing <Task(PythonOperator): load_shopee> on 2025-05-15 20:48:15.543774+00:00
[2025-05-15T20:48:17.450+0000] {standard_task_runner.py:72} INFO - Started process 588 to run task
[2025-05-15T20:48:17.455+0000] {standard_task_runner.py:104} INFO - Running: ['***', 'tasks', 'run', '03_load_data', 'load_shopee', 'manual__2025-05-15T20:48:15.543774+00:00', '--job-id', '22', '--raw', '--subdir', 'DAGS_FOLDER/03_load_data.py', '--cfg-path', '/tmp/tmpqzimds24']
[2025-05-15T20:48:17.458+0000] {standard_task_runner.py:105} INFO - Job 22: Subtask load_shopee
[2025-05-15T20:48:17.545+0000] {task_command.py:467} INFO - Running <TaskInstance: 03_load_data.load_shopee manual__2025-05-15T20:48:15.543774+00:00 [running]> on host b43b94ab59b1
[2025-05-15T20:48:17.645+0000] {taskinstance.py:3132} INFO - Exporting env vars: AIRFLOW_CTX_DAG_OWNER='***' AIRFLOW_CTX_DAG_ID='03_load_data' AIRFLOW_CTX_TASK_ID='load_shopee' AIRFLOW_CTX_EXECUTION_DATE='2025-05-15T20:48:15.543774+00:00' AIRFLOW_CTX_TRY_NUMBER='1' AIRFLOW_CTX_DAG_RUN_ID='manual__2025-05-15T20:48:15.543774+00:00'
[2025-05-15T20:48:17.647+0000] {taskinstance.py:731} INFO - ::endgroup::
[2025-05-15T20:48:19.256+0000] {logging_mixin.py:190} INFO - Loading file ./extraction/shopee/data/raw/Order.completed.20240701_20240731.xlsx to sales_db
[2025-05-15T20:48:19.260+0000] {logging_mixin.py:190} INFO - An exception has occured on file ./extraction/shopee/data/raw/Order.completed.20240701_20240731.xlsx.
[2025-05-15T20:48:19.261+0000] {logging_mixin.py:190} INFO - --------------------------------------------------
[2025-05-15T20:48:19.262+0000] {logging_mixin.py:190} INFO - (psycopg2.OperationalError) connection to server at "localhost" (::1), port 5432 failed: Connection refused
	Is the server running on that host and accepting TCP/IP connections?
connection to server at "localhost" (127.0.0.1), port 5432 failed: Connection refused
	Is the server running on that host and accepting TCP/IP connections?

(Background on this error at: https://sqlalche.me/e/14/e3q8)
[2025-05-15T20:48:19.262+0000] {logging_mixin.py:190} INFO - --------------------------------------------------
[2025-05-15T20:48:19.263+0000] {python.py:240} INFO - Done. Returned value was: None
[2025-05-15T20:48:19.278+0000] {taskinstance.py:340} INFO - ::group::Post task execution logs
[2025-05-15T20:48:19.279+0000] {taskinstance.py:352} INFO - Marking task as SUCCESS. dag_id=03_load_data, task_id=load_shopee, run_id=manual__2025-05-15T20:48:15.543774+00:00, execution_date=20250515T204815, start_date=20250515T204817, end_date=20250515T204819
[2025-05-15T20:48:19.316+0000] {local_task_job_runner.py:266} INFO - Task exited with return code 0
[2025-05-15T20:48:19.334+0000] {taskinstance.py:3895} INFO - 0 downstream tasks scheduled from follow-on schedule check
[2025-05-15T20:48:19.337+0000] {local_task_job_runner.py:245} INFO - ::endgroup::
