[2025-05-20T17:22:02.089+0000] {local_task_job_runner.py:123} INFO - ::group::Pre task execution logs
[2025-05-20T17:22:02.106+0000] {taskinstance.py:2613} INFO - Dependencies all met for dep_context=non-requeueable deps ti=<TaskInstance: 04_transform_data.run_dbt manual__2025-05-20T17:21:59.992165+00:00 [queued]>
[2025-05-20T17:22:02.115+0000] {taskinstance.py:2613} INFO - Dependencies all met for dep_context=requeueable deps ti=<TaskInstance: 04_transform_data.run_dbt manual__2025-05-20T17:21:59.992165+00:00 [queued]>
[2025-05-20T17:22:02.117+0000] {taskinstance.py:2866} INFO - Starting attempt 1 of 1
[2025-05-20T17:22:02.129+0000] {taskinstance.py:2889} INFO - Executing <Task(PythonOperator): run_dbt> on 2025-05-20 17:21:59.992165+00:00
[2025-05-20T17:22:02.133+0000] {standard_task_runner.py:72} INFO - Started process 1844 to run task
[2025-05-20T17:22:02.136+0000] {standard_task_runner.py:104} INFO - Running: ['***', 'tasks', 'run', '04_transform_data', 'run_dbt', 'manual__2025-05-20T17:21:59.992165+00:00', '--job-id', '17', '--raw', '--subdir', 'DAGS_FOLDER/04_transform_data.py', '--cfg-path', '/tmp/tmp4p4_jg3v']
[2025-05-20T17:22:02.138+0000] {standard_task_runner.py:105} INFO - Job 17: Subtask run_dbt
[2025-05-20T17:22:02.189+0000] {task_command.py:467} INFO - Running <TaskInstance: 04_transform_data.run_dbt manual__2025-05-20T17:21:59.992165+00:00 [running]> on host e27e96d1841a
[2025-05-20T17:22:02.266+0000] {taskinstance.py:3132} INFO - Exporting env vars: AIRFLOW_CTX_DAG_OWNER='***' AIRFLOW_CTX_DAG_ID='04_transform_data' AIRFLOW_CTX_TASK_ID='run_dbt' AIRFLOW_CTX_EXECUTION_DATE='2025-05-20T17:21:59.992165+00:00' AIRFLOW_CTX_TRY_NUMBER='1' AIRFLOW_CTX_DAG_RUN_ID='manual__2025-05-20T17:21:59.992165+00:00'
[2025-05-20T17:22:02.267+0000] {taskinstance.py:731} INFO - ::endgroup::
[2025-05-20T17:22:03.992+0000] {logging_mixin.py:190} INFO - 17:22:03  Running with dbt=1.9.4
[2025-05-20T17:22:04.348+0000] {logging_mixin.py:190} INFO - 17:22:04  Registered adapter: postgres=1.9.0
[2025-05-20T17:22:05.505+0000] {logging_mixin.py:190} INFO - 17:22:05  [WARNING]: Configuration paths exist in your dbt_project.yml file which do not apply to any resources.
There are 1 unused configuration paths:
- models.e_commerce_sales.example
[2025-05-20T17:22:05.694+0000] {logging_mixin.py:190} INFO - 17:22:05  Found 6 models, 12 sources, 433 macros
[2025-05-20T17:22:05.699+0000] {logging_mixin.py:190} INFO - 17:22:05
[2025-05-20T17:22:05.702+0000] {logging_mixin.py:190} INFO - 17:22:05  Concurrency: 4 threads (target='dev')
[2025-05-20T17:22:05.703+0000] {logging_mixin.py:190} INFO - 17:22:05
[2025-05-20T17:22:05.852+0000] {logging_mixin.py:190} INFO - 17:22:05  1 of 6 START sql incremental model sales.mercadolivre_orders_results ........... [RUN]
[2025-05-20T17:22:05.854+0000] {logging_mixin.py:190} INFO - 17:22:05  2 of 6 START sql incremental model sales.shopee_new_id ......................... [RUN]
[2025-05-20T17:22:06.223+0000] {logging_mixin.py:190} INFO - 17:22:06  2 of 6 OK created sql incremental model sales.shopee_new_id .................... [MERGE 0 in 0.36s]
[2025-05-20T17:22:06.226+0000] {logging_mixin.py:190} INFO - 17:22:06  1 of 6 OK created sql incremental model sales.mercadolivre_orders_results ...... [MERGE 255 in 0.37s]
[2025-05-20T17:22:06.232+0000] {logging_mixin.py:190} INFO - 17:22:06  3 of 6 START sql incremental model sales.shopee_orders_results ................. [RUN]
[2025-05-20T17:22:06.236+0000] {logging_mixin.py:190} INFO - 17:22:06  4 of 6 START sql incremental model sales.mercadolivre_profits .................. [RUN]
[2025-05-20T17:22:06.316+0000] {logging_mixin.py:190} INFO - 17:22:06  3 of 6 ERROR creating sql incremental model sales.shopee_orders_results ........ [ERROR in 0.08s]
[2025-05-20T17:22:06.324+0000] {logging_mixin.py:190} INFO - 17:22:06  5 of 6 SKIP relation sales.dim_shopee_orders ................................... [SKIP]
[2025-05-20T17:22:06.326+0000] {logging_mixin.py:190} INFO - 17:22:06  6 of 6 SKIP relation sales.dim_shopee_product .................................. [SKIP]
[2025-05-20T17:22:06.375+0000] {logging_mixin.py:190} INFO - 17:22:06  4 of 6 OK created sql incremental model sales.mercadolivre_profits ............. [MERGE 250 in 0.12s]
[2025-05-20T17:22:06.402+0000] {logging_mixin.py:190} INFO - 17:22:06
[2025-05-20T17:22:06.405+0000] {logging_mixin.py:190} INFO - 17:22:06  Finished running 6 incremental models in 0 hours 0 minutes and 0.70 seconds (0.70s).
[2025-05-20T17:22:06.472+0000] {logging_mixin.py:190} INFO - 17:22:06
[2025-05-20T17:22:06.474+0000] {logging_mixin.py:190} INFO - 17:22:06  Completed with 1 error, 0 partial successes, and 0 warnings:
[2025-05-20T17:22:06.475+0000] {logging_mixin.py:190} INFO - 17:22:06
[2025-05-20T17:22:06.477+0000] {logging_mixin.py:190} INFO - 17:22:06    Database Error in model shopee_orders_results (models/core/shopee_orders_results.sql)
  column "new_id_load_timestamp" does not exist
  LINE 42:                  new_id_load_timestamp,
                            ^
  compiled code at target/run/e_commerce_sales/models/core/shopee_orders_results.sql
[2025-05-20T17:22:06.479+0000] {logging_mixin.py:190} INFO - 17:22:06
[2025-05-20T17:22:06.480+0000] {logging_mixin.py:190} INFO - 17:22:06  Done. PASS=3 WARN=0 ERROR=1 SKIP=2 TOTAL=6
[2025-05-20T17:22:07.310+0000] {logging_mixin.py:190} INFO - dbt run failed!
[2025-05-20T17:22:07.313+0000] {logging_mixin.py:190} INFO - None
[2025-05-20T17:22:07.315+0000] {taskinstance.py:3311} ERROR - Task failed with exception
Traceback (most recent call last):
  File "/home/airflow/.local/lib/python3.9/site-packages/airflow/models/taskinstance.py", line 767, in _execute_task
    result = _execute_callable(context=context, **execute_callable_kwargs)
  File "/home/airflow/.local/lib/python3.9/site-packages/airflow/models/taskinstance.py", line 733, in _execute_callable
    return ExecutionCallableRunner(
  File "/home/airflow/.local/lib/python3.9/site-packages/airflow/utils/operator_helpers.py", line 252, in run
    return self.func(*args, **kwargs)
  File "/home/airflow/.local/lib/python3.9/site-packages/airflow/models/baseoperator.py", line 422, in wrapper
    return func(self, *args, **kwargs)
  File "/home/airflow/.local/lib/python3.9/site-packages/airflow/operators/python.py", line 238, in execute
    return_value = self.execute_callable()
  File "/home/airflow/.local/lib/python3.9/site-packages/airflow/operators/python.py", line 256, in execute_callable
    return runner.run(*self.op_args, **self.op_kwargs)
  File "/home/airflow/.local/lib/python3.9/site-packages/airflow/utils/operator_helpers.py", line 252, in run
    return self.func(*args, **kwargs)
  File "/opt/airflow/dbt/run_dbt.py", line 22, in transform_data
    raise RuntimeError("dbt run failed")
RuntimeError: dbt run failed
[2025-05-20T17:22:07.326+0000] {taskinstance.py:1225} INFO - Marking task as FAILED. dag_id=04_transform_data, task_id=run_dbt, run_id=manual__2025-05-20T17:21:59.992165+00:00, execution_date=20250520T172159, start_date=20250520T172202, end_date=20250520T172207
[2025-05-20T17:22:07.337+0000] {taskinstance.py:340} INFO - ::group::Post task execution logs
[2025-05-20T17:22:07.338+0000] {standard_task_runner.py:124} ERROR - Failed to execute job 17 for task run_dbt (dbt run failed; 1844)
Traceback (most recent call last):
  File "/home/airflow/.local/lib/python3.9/site-packages/airflow/task/task_runner/standard_task_runner.py", line 117, in _start_by_fork
    ret = args.func(args, dag=self.dag)
  File "/home/airflow/.local/lib/python3.9/site-packages/airflow/cli/cli_config.py", line 49, in command
    return func(*args, **kwargs)
  File "/home/airflow/.local/lib/python3.9/site-packages/airflow/utils/cli.py", line 116, in wrapper
    return f(*args, **kwargs)
  File "/home/airflow/.local/lib/python3.9/site-packages/airflow/cli/commands/task_command.py", line 483, in task_run
    task_return_code = _run_task_by_selected_method(args, _dag, ti)
  File "/home/airflow/.local/lib/python3.9/site-packages/airflow/cli/commands/task_command.py", line 256, in _run_task_by_selected_method
    return _run_raw_task(args, ti)
  File "/home/airflow/.local/lib/python3.9/site-packages/airflow/cli/commands/task_command.py", line 341, in _run_raw_task
    return ti._run_raw_task(
  File "/home/airflow/.local/lib/python3.9/site-packages/airflow/utils/session.py", line 97, in wrapper
    return func(*args, session=session, **kwargs)
  File "/home/airflow/.local/lib/python3.9/site-packages/airflow/models/taskinstance.py", line 3005, in _run_raw_task
    return _run_raw_task(
  File "/home/airflow/.local/lib/python3.9/site-packages/airflow/models/taskinstance.py", line 273, in _run_raw_task
    TaskInstance._execute_task_with_callbacks(
  File "/home/airflow/.local/lib/python3.9/site-packages/airflow/models/taskinstance.py", line 3159, in _execute_task_with_callbacks
    result = self._execute_task(context, task_orig)
  File "/home/airflow/.local/lib/python3.9/site-packages/airflow/models/taskinstance.py", line 3183, in _execute_task
    return _execute_task(self, context, task_orig)
  File "/home/airflow/.local/lib/python3.9/site-packages/airflow/models/taskinstance.py", line 767, in _execute_task
    result = _execute_callable(context=context, **execute_callable_kwargs)
  File "/home/airflow/.local/lib/python3.9/site-packages/airflow/models/taskinstance.py", line 733, in _execute_callable
    return ExecutionCallableRunner(
  File "/home/airflow/.local/lib/python3.9/site-packages/airflow/utils/operator_helpers.py", line 252, in run
    return self.func(*args, **kwargs)
  File "/home/airflow/.local/lib/python3.9/site-packages/airflow/models/baseoperator.py", line 422, in wrapper
    return func(self, *args, **kwargs)
  File "/home/airflow/.local/lib/python3.9/site-packages/airflow/operators/python.py", line 238, in execute
    return_value = self.execute_callable()
  File "/home/airflow/.local/lib/python3.9/site-packages/airflow/operators/python.py", line 256, in execute_callable
    return runner.run(*self.op_args, **self.op_kwargs)
  File "/home/airflow/.local/lib/python3.9/site-packages/airflow/utils/operator_helpers.py", line 252, in run
    return self.func(*args, **kwargs)
  File "/opt/airflow/dbt/run_dbt.py", line 22, in transform_data
    raise RuntimeError("dbt run failed")
RuntimeError: dbt run failed
[2025-05-20T17:22:07.369+0000] {local_task_job_runner.py:266} INFO - Task exited with return code 1
[2025-05-20T17:22:07.385+0000] {taskinstance.py:3895} INFO - 0 downstream tasks scheduled from follow-on schedule check
[2025-05-20T17:22:07.388+0000] {local_task_job_runner.py:245} INFO - ::endgroup::
