[2025-05-21T20:34:36.145+0000] {local_task_job_runner.py:123} INFO - ::group::Pre task execution logs
[2025-05-21T20:34:36.166+0000] {taskinstance.py:2613} INFO - Dependencies all met for dep_context=non-requeueable deps ti=<TaskInstance: 04_transform_data.run_dbt manual__2025-05-21T20:34:34.238239+00:00 [queued]>
[2025-05-21T20:34:36.175+0000] {taskinstance.py:2613} INFO - Dependencies all met for dep_context=requeueable deps ti=<TaskInstance: 04_transform_data.run_dbt manual__2025-05-21T20:34:34.238239+00:00 [queued]>
[2025-05-21T20:34:36.176+0000] {taskinstance.py:2866} INFO - Starting attempt 1 of 1
[2025-05-21T20:34:36.189+0000] {taskinstance.py:2889} INFO - Executing <Task(PythonOperator): run_dbt> on 2025-05-21 20:34:34.238239+00:00
[2025-05-21T20:34:36.194+0000] {standard_task_runner.py:72} INFO - Started process 5188 to run task
[2025-05-21T20:34:36.197+0000] {standard_task_runner.py:104} INFO - Running: ['***', 'tasks', 'run', '04_transform_data', 'run_dbt', 'manual__2025-05-21T20:34:34.238239+00:00', '--job-id', '128', '--raw', '--subdir', 'DAGS_FOLDER/04_transform_data.py', '--cfg-path', '/tmp/tmph9tdardo']
[2025-05-21T20:34:36.199+0000] {standard_task_runner.py:105} INFO - Job 128: Subtask run_dbt
[2025-05-21T20:34:36.254+0000] {task_command.py:467} INFO - Running <TaskInstance: 04_transform_data.run_dbt manual__2025-05-21T20:34:34.238239+00:00 [running]> on host e27e96d1841a
[2025-05-21T20:34:36.339+0000] {taskinstance.py:3132} INFO - Exporting env vars: AIRFLOW_CTX_DAG_OWNER='***' AIRFLOW_CTX_DAG_ID='04_transform_data' AIRFLOW_CTX_TASK_ID='run_dbt' AIRFLOW_CTX_EXECUTION_DATE='2025-05-21T20:34:34.238239+00:00' AIRFLOW_CTX_TRY_NUMBER='1' AIRFLOW_CTX_DAG_RUN_ID='manual__2025-05-21T20:34:34.238239+00:00'
[2025-05-21T20:34:36.341+0000] {taskinstance.py:731} INFO - ::endgroup::
[2025-05-21T20:34:38.041+0000] {logging_mixin.py:190} INFO - 20:34:38  Running with dbt=1.9.4
[2025-05-21T20:34:38.388+0000] {logging_mixin.py:190} INFO - 20:34:38  Registered adapter: postgres=1.9.0
[2025-05-21T20:34:39.506+0000] {logging_mixin.py:190} INFO - 20:34:39  [WARNING]: Configuration paths exist in your dbt_project.yml file which do not apply to any resources.
There are 1 unused configuration paths:
- models.e_commerce_sales.example
[2025-05-21T20:34:39.674+0000] {logging_mixin.py:190} INFO - 20:34:39  Found 11 models, 12 sources, 433 macros
[2025-05-21T20:34:39.678+0000] {logging_mixin.py:190} INFO - 20:34:39
[2025-05-21T20:34:39.680+0000] {logging_mixin.py:190} INFO - 20:34:39  Concurrency: 4 threads (target='dev')
[2025-05-21T20:34:39.681+0000] {logging_mixin.py:190} INFO - 20:34:39
[2025-05-21T20:34:39.816+0000] {logging_mixin.py:190} INFO - 20:34:39  1 of 11 START sql incremental model sales.mercadolivre_orders_results .......... [RUN]
[2025-05-21T20:34:39.818+0000] {logging_mixin.py:190} INFO - 20:34:39  2 of 11 START sql incremental model sales.shopee_new_id ........................ [RUN]
[2025-05-21T20:34:40.179+0000] {logging_mixin.py:190} INFO - 20:34:40  2 of 11 OK created sql incremental model sales.shopee_new_id ................... [MERGE 0 in 0.35s]
[2025-05-21T20:34:40.184+0000] {logging_mixin.py:190} INFO - 20:34:40  1 of 11 OK created sql incremental model sales.mercadolivre_orders_results ..... [MERGE 255 in 0.36s]
[2025-05-21T20:34:40.189+0000] {logging_mixin.py:190} INFO - 20:34:40  3 of 11 START sql incremental model sales.shopee_orders_results ................ [RUN]
[2025-05-21T20:34:40.194+0000] {logging_mixin.py:190} INFO - 20:34:40  4 of 11 START sql incremental model sales.dim_mercadolivre_buyer ............... [RUN]
[2025-05-21T20:34:40.196+0000] {logging_mixin.py:190} INFO - 20:34:40  5 of 11 START sql incremental model sales.dim_mercadolivre_date ................ [RUN]
[2025-05-21T20:34:40.198+0000] {logging_mixin.py:190} INFO - 20:34:40  6 of 11 START sql incremental model sales.dim_mercadolivre_product ............. [RUN]
[2025-05-21T20:34:40.449+0000] {logging_mixin.py:190} INFO - 20:34:40  3 of 11 OK created sql incremental model sales.shopee_orders_results ........... [MERGE 0 in 0.25s]
[2025-05-21T20:34:40.461+0000] {logging_mixin.py:190} INFO - 20:34:40  7 of 11 START sql incremental model sales.mercadolivre_profits ................. [RUN]
[2025-05-21T20:34:40.499+0000] {logging_mixin.py:190} INFO - 20:34:40  4 of 11 ERROR creating sql incremental model sales.dim_mercadolivre_buyer ...... [ERROR in 0.29s]
[2025-05-21T20:34:40.501+0000] {logging_mixin.py:190} INFO - 20:34:40  5 of 11 ERROR creating sql incremental model sales.dim_mercadolivre_date ....... [ERROR in 0.29s]
[2025-05-21T20:34:40.514+0000] {logging_mixin.py:190} INFO - 20:34:40  6 of 11 OK created sql incremental model sales.dim_mercadolivre_product ........ [MERGE 250 in 0.29s]
[2025-05-21T20:34:40.523+0000] {logging_mixin.py:190} INFO - 20:34:40  8 of 11 START sql incremental model sales.dim_shopee_buyer_id .................. [RUN]
[2025-05-21T20:34:40.525+0000] {logging_mixin.py:190} INFO - 20:34:40  9 of 11 START sql incremental model sales.dim_shopee_date ...................... [RUN]
[2025-05-21T20:34:40.532+0000] {logging_mixin.py:190} INFO - 20:34:40  10 of 11 START sql incremental model sales.dim_shopee_orders_status ............ [RUN]
[2025-05-21T20:34:40.775+0000] {logging_mixin.py:190} INFO - 20:34:40  7 of 11 OK created sql incremental model sales.mercadolivre_profits ............ [MERGE 250 in 0.30s]
[2025-05-21T20:34:40.788+0000] {logging_mixin.py:190} INFO - 20:34:40  11 of 11 START sql incremental model sales.dim_shopee_product .................. [RUN]
[2025-05-21T20:34:40.828+0000] {logging_mixin.py:190} INFO - 20:34:40  9 of 11 OK created sql incremental model sales.dim_shopee_date ................. [MERGE 0 in 0.29s]
[2025-05-21T20:34:40.831+0000] {logging_mixin.py:190} INFO - 20:34:40  10 of 11 OK created sql incremental model sales.dim_shopee_orders_status ....... [MERGE 0 in 0.29s]
[2025-05-21T20:34:40.842+0000] {logging_mixin.py:190} INFO - 20:34:40  8 of 11 OK created sql incremental model sales.dim_shopee_buyer_id ............. [MERGE 0 in 0.30s]
[2025-05-21T20:34:40.921+0000] {logging_mixin.py:190} INFO - 20:34:40  11 of 11 OK created sql incremental model sales.dim_shopee_product ............. [MERGE 0 in 0.12s]
[2025-05-21T20:34:40.943+0000] {logging_mixin.py:190} INFO - 20:34:40
[2025-05-21T20:34:40.945+0000] {logging_mixin.py:190} INFO - 20:34:40  Finished running 11 incremental models in 0 hours 0 minutes and 1.26 seconds (1.26s).
[2025-05-21T20:34:41.010+0000] {logging_mixin.py:190} INFO - 20:34:41
[2025-05-21T20:34:41.012+0000] {logging_mixin.py:190} INFO - 20:34:41  Completed with 2 errors, 0 partial successes, and 0 warnings:
[2025-05-21T20:34:41.013+0000] {logging_mixin.py:190} INFO - 20:34:41
[2025-05-21T20:34:41.015+0000] {logging_mixin.py:190} INFO - 20:34:41    Database Error in model dim_mercadolivre_buyer (models/core/dim_mercadolivre_buyer.sql)
  MERGE command cannot affect row a second time
  HINT:  Ensure that not more than one source row matches any one target row.
  compiled code at target/run/e_commerce_sales/models/core/dim_mercadolivre_buyer.sql
[2025-05-21T20:34:41.016+0000] {logging_mixin.py:190} INFO - 20:34:41
[2025-05-21T20:34:41.018+0000] {logging_mixin.py:190} INFO - 20:34:41    Database Error in model dim_mercadolivre_date (models/core/dim_mercadolivre_date.sql)
  MERGE command cannot affect row a second time
  HINT:  Ensure that not more than one source row matches any one target row.
  compiled code at target/run/e_commerce_sales/models/core/dim_mercadolivre_date.sql
[2025-05-21T20:34:41.019+0000] {logging_mixin.py:190} INFO - 20:34:41
[2025-05-21T20:34:41.020+0000] {logging_mixin.py:190} INFO - 20:34:41  Done. PASS=9 WARN=0 ERROR=2 SKIP=0 TOTAL=11
[2025-05-21T20:34:41.937+0000] {logging_mixin.py:190} INFO - dbt run failed!
[2025-05-21T20:34:41.941+0000] {logging_mixin.py:190} INFO - None
[2025-05-21T20:34:41.943+0000] {taskinstance.py:3311} ERROR - Task failed with exception
Traceback (most recent call last):
  File "/home/airflow/.local/lib/python3.9/site-packages/airflow/models/taskinstance.py", line 767, in _execute_task
    result = _execute_callable(context=context, **execute_callable_kwargs)
  File "/home/airflow/.local/lib/python3.9/site-packages/airflow/models/taskinstance.py", line 733, in _execute_callable
    return ExecutionCallableRunner(
  File "/home/airflow/.local/lib/python3.9/site-packages/airflow/utils/operator_helpers.py", line 252, in run
    return self.func(*args, **kwargs)
  File "/home/airflow/.local/lib/python3.9/site-packages/airflow/models/baseoperator.py", line 422, in wrapper
    return func(self, *args, **kwargs)
  File "/home/airflow/.local/lib/python3.9/site-packages/airflow/operators/python.py", line 238, in execute
    return_value = self.execute_callable()
  File "/home/airflow/.local/lib/python3.9/site-packages/airflow/operators/python.py", line 256, in execute_callable
    return runner.run(*self.op_args, **self.op_kwargs)
  File "/home/airflow/.local/lib/python3.9/site-packages/airflow/utils/operator_helpers.py", line 252, in run
    return self.func(*args, **kwargs)
  File "/opt/airflow/dbt/run_dbt.py", line 22, in transform_data
    raise RuntimeError("dbt run failed")
RuntimeError: dbt run failed
[2025-05-21T20:34:41.955+0000] {taskinstance.py:1225} INFO - Marking task as FAILED. dag_id=04_transform_data, task_id=run_dbt, run_id=manual__2025-05-21T20:34:34.238239+00:00, execution_date=20250521T203434, start_date=20250521T203436, end_date=20250521T203441
[2025-05-21T20:34:41.966+0000] {taskinstance.py:340} INFO - ::group::Post task execution logs
[2025-05-21T20:34:41.967+0000] {standard_task_runner.py:124} ERROR - Failed to execute job 128 for task run_dbt (dbt run failed; 5188)
Traceback (most recent call last):
  File "/home/airflow/.local/lib/python3.9/site-packages/airflow/task/task_runner/standard_task_runner.py", line 117, in _start_by_fork
    ret = args.func(args, dag=self.dag)
  File "/home/airflow/.local/lib/python3.9/site-packages/airflow/cli/cli_config.py", line 49, in command
    return func(*args, **kwargs)
  File "/home/airflow/.local/lib/python3.9/site-packages/airflow/utils/cli.py", line 116, in wrapper
    return f(*args, **kwargs)
  File "/home/airflow/.local/lib/python3.9/site-packages/airflow/cli/commands/task_command.py", line 483, in task_run
    task_return_code = _run_task_by_selected_method(args, _dag, ti)
  File "/home/airflow/.local/lib/python3.9/site-packages/airflow/cli/commands/task_command.py", line 256, in _run_task_by_selected_method
    return _run_raw_task(args, ti)
  File "/home/airflow/.local/lib/python3.9/site-packages/airflow/cli/commands/task_command.py", line 341, in _run_raw_task
    return ti._run_raw_task(
  File "/home/airflow/.local/lib/python3.9/site-packages/airflow/utils/session.py", line 97, in wrapper
    return func(*args, session=session, **kwargs)
  File "/home/airflow/.local/lib/python3.9/site-packages/airflow/models/taskinstance.py", line 3005, in _run_raw_task
    return _run_raw_task(
  File "/home/airflow/.local/lib/python3.9/site-packages/airflow/models/taskinstance.py", line 273, in _run_raw_task
    TaskInstance._execute_task_with_callbacks(
  File "/home/airflow/.local/lib/python3.9/site-packages/airflow/models/taskinstance.py", line 3159, in _execute_task_with_callbacks
    result = self._execute_task(context, task_orig)
  File "/home/airflow/.local/lib/python3.9/site-packages/airflow/models/taskinstance.py", line 3183, in _execute_task
    return _execute_task(self, context, task_orig)
  File "/home/airflow/.local/lib/python3.9/site-packages/airflow/models/taskinstance.py", line 767, in _execute_task
    result = _execute_callable(context=context, **execute_callable_kwargs)
  File "/home/airflow/.local/lib/python3.9/site-packages/airflow/models/taskinstance.py", line 733, in _execute_callable
    return ExecutionCallableRunner(
  File "/home/airflow/.local/lib/python3.9/site-packages/airflow/utils/operator_helpers.py", line 252, in run
    return self.func(*args, **kwargs)
  File "/home/airflow/.local/lib/python3.9/site-packages/airflow/models/baseoperator.py", line 422, in wrapper
    return func(self, *args, **kwargs)
  File "/home/airflow/.local/lib/python3.9/site-packages/airflow/operators/python.py", line 238, in execute
    return_value = self.execute_callable()
  File "/home/airflow/.local/lib/python3.9/site-packages/airflow/operators/python.py", line 256, in execute_callable
    return runner.run(*self.op_args, **self.op_kwargs)
  File "/home/airflow/.local/lib/python3.9/site-packages/airflow/utils/operator_helpers.py", line 252, in run
    return self.func(*args, **kwargs)
  File "/opt/airflow/dbt/run_dbt.py", line 22, in transform_data
    raise RuntimeError("dbt run failed")
RuntimeError: dbt run failed
[2025-05-21T20:34:41.994+0000] {local_task_job_runner.py:266} INFO - Task exited with return code 1
[2025-05-21T20:34:42.012+0000] {taskinstance.py:3895} INFO - 0 downstream tasks scheduled from follow-on schedule check
[2025-05-21T20:34:42.016+0000] {local_task_job_runner.py:245} INFO - ::endgroup::
