[2025-05-21T14:06:20.970+0000] {local_task_job_runner.py:123} INFO - ::group::Pre task execution logs
[2025-05-21T14:06:20.989+0000] {taskinstance.py:2613} INFO - Dependencies all met for dep_context=non-requeueable deps ti=<TaskInstance: 04_transform_data.run_dbt manual__2025-05-21T14:06:19.177435+00:00 [queued]>
[2025-05-21T14:06:20.997+0000] {taskinstance.py:2613} INFO - Dependencies all met for dep_context=requeueable deps ti=<TaskInstance: 04_transform_data.run_dbt manual__2025-05-21T14:06:19.177435+00:00 [queued]>
[2025-05-21T14:06:20.998+0000] {taskinstance.py:2866} INFO - Starting attempt 1 of 1
[2025-05-21T14:06:21.010+0000] {taskinstance.py:2889} INFO - Executing <Task(PythonOperator): run_dbt> on 2025-05-21 14:06:19.177435+00:00
[2025-05-21T14:06:21.015+0000] {standard_task_runner.py:72} INFO - Started process 1193 to run task
[2025-05-21T14:06:21.018+0000] {standard_task_runner.py:104} INFO - Running: ['***', 'tasks', 'run', '04_transform_data', 'run_dbt', 'manual__2025-05-21T14:06:19.177435+00:00', '--job-id', '88', '--raw', '--subdir', 'DAGS_FOLDER/04_transform_data.py', '--cfg-path', '/tmp/tmpsiecxfgs']
[2025-05-21T14:06:21.020+0000] {standard_task_runner.py:105} INFO - Job 88: Subtask run_dbt
[2025-05-21T14:06:21.069+0000] {task_command.py:467} INFO - Running <TaskInstance: 04_transform_data.run_dbt manual__2025-05-21T14:06:19.177435+00:00 [running]> on host e27e96d1841a
[2025-05-21T14:06:21.151+0000] {taskinstance.py:3132} INFO - Exporting env vars: AIRFLOW_CTX_DAG_OWNER='***' AIRFLOW_CTX_DAG_ID='04_transform_data' AIRFLOW_CTX_TASK_ID='run_dbt' AIRFLOW_CTX_EXECUTION_DATE='2025-05-21T14:06:19.177435+00:00' AIRFLOW_CTX_TRY_NUMBER='1' AIRFLOW_CTX_DAG_RUN_ID='manual__2025-05-21T14:06:19.177435+00:00'
[2025-05-21T14:06:21.153+0000] {taskinstance.py:731} INFO - ::endgroup::
[2025-05-21T14:06:22.918+0000] {logging_mixin.py:190} INFO - 14:06:22  Running with dbt=1.9.4
[2025-05-21T14:06:23.269+0000] {logging_mixin.py:190} INFO - 14:06:23  Registered adapter: postgres=1.9.0
[2025-05-21T14:06:24.450+0000] {logging_mixin.py:190} INFO - 14:06:24  [WARNING]: Configuration paths exist in your dbt_project.yml file which do not apply to any resources.
There are 1 unused configuration paths:
- models.e_commerce_sales.example
[2025-05-21T14:06:24.618+0000] {logging_mixin.py:190} INFO - 14:06:24  Found 8 models, 12 sources, 433 macros
[2025-05-21T14:06:24.623+0000] {logging_mixin.py:190} INFO - 14:06:24
[2025-05-21T14:06:24.625+0000] {logging_mixin.py:190} INFO - 14:06:24  Concurrency: 4 threads (target='dev')
[2025-05-21T14:06:24.627+0000] {logging_mixin.py:190} INFO - 14:06:24
[2025-05-21T14:06:24.763+0000] {logging_mixin.py:190} INFO - 14:06:24  1 of 8 START sql incremental model sales.mercadolivre_orders_results ........... [RUN]
[2025-05-21T14:06:24.765+0000] {logging_mixin.py:190} INFO - 14:06:24  2 of 8 START sql incremental model sales.shopee_new_id ......................... [RUN]
[2025-05-21T14:06:25.129+0000] {logging_mixin.py:190} INFO - 14:06:25  2 of 8 OK created sql incremental model sales.shopee_new_id .................... [MERGE 0 in 0.36s]
[2025-05-21T14:06:25.131+0000] {logging_mixin.py:190} INFO - 14:06:25  1 of 8 OK created sql incremental model sales.mercadolivre_orders_results ...... [MERGE 255 in 0.36s]
[2025-05-21T14:06:25.137+0000] {logging_mixin.py:190} INFO - 14:06:25  3 of 8 START sql incremental model sales.shopee_orders_results ................. [RUN]
[2025-05-21T14:06:25.141+0000] {logging_mixin.py:190} INFO - 14:06:25  4 of 8 START sql incremental model sales.mercadolivre_profits .................. [RUN]
[2025-05-21T14:06:25.302+0000] {logging_mixin.py:190} INFO - 14:06:25  3 of 8 OK created sql incremental model sales.shopee_orders_results ............ [MERGE 0 in 0.16s]
[2025-05-21T14:06:25.307+0000] {logging_mixin.py:190} INFO - 14:06:25  4 of 8 OK created sql incremental model sales.mercadolivre_profits ............. [MERGE 250 in 0.16s]
[2025-05-21T14:06:25.313+0000] {logging_mixin.py:190} INFO - 14:06:25  5 of 8 START sql incremental model sales.dim_shopee_buyer_id ................... [RUN]
[2025-05-21T14:06:25.315+0000] {logging_mixin.py:190} INFO - 14:06:25  6 of 8 START sql incremental model sales.dim_shopee_orders ..................... [RUN]
[2025-05-21T14:06:25.316+0000] {logging_mixin.py:190} INFO - 14:06:25  7 of 8 START sql incremental model sales.dim_shopee_orders_status .............. [RUN]
[2025-05-21T14:06:25.323+0000] {logging_mixin.py:190} INFO - 14:06:25  8 of 8 START sql incremental model sales.dim_shopee_product .................... [RUN]
[2025-05-21T14:06:25.488+0000] {logging_mixin.py:190} INFO - 14:06:25  7 of 8 ERROR creating sql incremental model sales.dim_shopee_orders_status ..... [ERROR in 0.16s]
[2025-05-21T14:06:25.584+0000] {logging_mixin.py:190} INFO - 14:06:25  8 of 8 OK created sql incremental model sales.dim_shopee_product ............... [MERGE 0 in 0.25s]
[2025-05-21T14:06:25.588+0000] {logging_mixin.py:190} INFO - 14:06:25  5 of 8 OK created sql incremental model sales.dim_shopee_buyer_id .............. [MERGE 0 in 0.26s]
[2025-05-21T14:06:25.591+0000] {logging_mixin.py:190} INFO - 14:06:25  6 of 8 OK created sql incremental model sales.dim_shopee_orders ................ [MERGE 0 in 0.26s]
[2025-05-21T14:06:25.625+0000] {logging_mixin.py:190} INFO - 14:06:25
[2025-05-21T14:06:25.626+0000] {logging_mixin.py:190} INFO - 14:06:25  Finished running 8 incremental models in 0 hours 0 minutes and 1.00 seconds (1.00s).
[2025-05-21T14:06:25.691+0000] {logging_mixin.py:190} INFO - 14:06:25
[2025-05-21T14:06:25.693+0000] {logging_mixin.py:190} INFO - 14:06:25  Completed with 1 error, 0 partial successes, and 0 warnings:
[2025-05-21T14:06:25.694+0000] {logging_mixin.py:190} INFO - 14:06:25
[2025-05-21T14:06:25.696+0000] {logging_mixin.py:190} INFO - 14:06:25    Database Error in model dim_shopee_orders_status (models/core/dim_shopee_orders_status.sql)
  column delivery_data.status_do_pedido does not exist
  LINE 28:             delivery_data.status_do_pedido AS order_status,
                       ^
  compiled code at target/run/e_commerce_sales/models/core/dim_shopee_orders_status.sql
[2025-05-21T14:06:25.697+0000] {logging_mixin.py:190} INFO - 14:06:25
[2025-05-21T14:06:25.698+0000] {logging_mixin.py:190} INFO - 14:06:25  Done. PASS=7 WARN=0 ERROR=1 SKIP=0 TOTAL=8
[2025-05-21T14:06:27.450+0000] {logging_mixin.py:190} INFO - dbt run failed!
[2025-05-21T14:06:27.451+0000] {logging_mixin.py:190} INFO - None
[2025-05-21T14:06:27.452+0000] {taskinstance.py:3311} ERROR - Task failed with exception
Traceback (most recent call last):
  File "/home/airflow/.local/lib/python3.9/site-packages/airflow/models/taskinstance.py", line 767, in _execute_task
    result = _execute_callable(context=context, **execute_callable_kwargs)
  File "/home/airflow/.local/lib/python3.9/site-packages/airflow/models/taskinstance.py", line 733, in _execute_callable
    return ExecutionCallableRunner(
  File "/home/airflow/.local/lib/python3.9/site-packages/airflow/utils/operator_helpers.py", line 252, in run
    return self.func(*args, **kwargs)
  File "/home/airflow/.local/lib/python3.9/site-packages/airflow/models/baseoperator.py", line 422, in wrapper
    return func(self, *args, **kwargs)
  File "/home/airflow/.local/lib/python3.9/site-packages/airflow/operators/python.py", line 238, in execute
    return_value = self.execute_callable()
  File "/home/airflow/.local/lib/python3.9/site-packages/airflow/operators/python.py", line 256, in execute_callable
    return runner.run(*self.op_args, **self.op_kwargs)
  File "/home/airflow/.local/lib/python3.9/site-packages/airflow/utils/operator_helpers.py", line 252, in run
    return self.func(*args, **kwargs)
  File "/opt/airflow/dbt/run_dbt.py", line 22, in transform_data
    raise RuntimeError("dbt run failed")
RuntimeError: dbt run failed
[2025-05-21T14:06:27.463+0000] {taskinstance.py:1225} INFO - Marking task as FAILED. dag_id=04_transform_data, task_id=run_dbt, run_id=manual__2025-05-21T14:06:19.177435+00:00, execution_date=20250521T140619, start_date=20250521T140620, end_date=20250521T140627
[2025-05-21T14:06:27.476+0000] {taskinstance.py:340} INFO - ::group::Post task execution logs
[2025-05-21T14:06:27.478+0000] {standard_task_runner.py:124} ERROR - Failed to execute job 88 for task run_dbt (dbt run failed; 1193)
Traceback (most recent call last):
  File "/home/airflow/.local/lib/python3.9/site-packages/airflow/task/task_runner/standard_task_runner.py", line 117, in _start_by_fork
    ret = args.func(args, dag=self.dag)
  File "/home/airflow/.local/lib/python3.9/site-packages/airflow/cli/cli_config.py", line 49, in command
    return func(*args, **kwargs)
  File "/home/airflow/.local/lib/python3.9/site-packages/airflow/utils/cli.py", line 116, in wrapper
    return f(*args, **kwargs)
  File "/home/airflow/.local/lib/python3.9/site-packages/airflow/cli/commands/task_command.py", line 483, in task_run
    task_return_code = _run_task_by_selected_method(args, _dag, ti)
  File "/home/airflow/.local/lib/python3.9/site-packages/airflow/cli/commands/task_command.py", line 256, in _run_task_by_selected_method
    return _run_raw_task(args, ti)
  File "/home/airflow/.local/lib/python3.9/site-packages/airflow/cli/commands/task_command.py", line 341, in _run_raw_task
    return ti._run_raw_task(
  File "/home/airflow/.local/lib/python3.9/site-packages/airflow/utils/session.py", line 97, in wrapper
    return func(*args, session=session, **kwargs)
  File "/home/airflow/.local/lib/python3.9/site-packages/airflow/models/taskinstance.py", line 3005, in _run_raw_task
    return _run_raw_task(
  File "/home/airflow/.local/lib/python3.9/site-packages/airflow/models/taskinstance.py", line 273, in _run_raw_task
    TaskInstance._execute_task_with_callbacks(
  File "/home/airflow/.local/lib/python3.9/site-packages/airflow/models/taskinstance.py", line 3159, in _execute_task_with_callbacks
    result = self._execute_task(context, task_orig)
  File "/home/airflow/.local/lib/python3.9/site-packages/airflow/models/taskinstance.py", line 3183, in _execute_task
    return _execute_task(self, context, task_orig)
  File "/home/airflow/.local/lib/python3.9/site-packages/airflow/models/taskinstance.py", line 767, in _execute_task
    result = _execute_callable(context=context, **execute_callable_kwargs)
  File "/home/airflow/.local/lib/python3.9/site-packages/airflow/models/taskinstance.py", line 733, in _execute_callable
    return ExecutionCallableRunner(
  File "/home/airflow/.local/lib/python3.9/site-packages/airflow/utils/operator_helpers.py", line 252, in run
    return self.func(*args, **kwargs)
  File "/home/airflow/.local/lib/python3.9/site-packages/airflow/models/baseoperator.py", line 422, in wrapper
    return func(self, *args, **kwargs)
  File "/home/airflow/.local/lib/python3.9/site-packages/airflow/operators/python.py", line 238, in execute
    return_value = self.execute_callable()
  File "/home/airflow/.local/lib/python3.9/site-packages/airflow/operators/python.py", line 256, in execute_callable
    return runner.run(*self.op_args, **self.op_kwargs)
  File "/home/airflow/.local/lib/python3.9/site-packages/airflow/utils/operator_helpers.py", line 252, in run
    return self.func(*args, **kwargs)
  File "/opt/airflow/dbt/run_dbt.py", line 22, in transform_data
    raise RuntimeError("dbt run failed")
RuntimeError: dbt run failed
[2025-05-21T14:06:27.518+0000] {local_task_job_runner.py:266} INFO - Task exited with return code 1
[2025-05-21T14:06:27.535+0000] {taskinstance.py:3895} INFO - 0 downstream tasks scheduled from follow-on schedule check
[2025-05-21T14:06:27.538+0000] {local_task_job_runner.py:245} INFO - ::endgroup::
