[2025-05-29T13:22:50.414+0000] {local_task_job_runner.py:123} INFO - ::group::Pre task execution logs
[2025-05-29T13:22:50.432+0000] {taskinstance.py:2613} INFO - Dependencies all met for dep_context=non-requeueable deps ti=<TaskInstance: 01_extract_data.ml_access_token manual__2025-05-29T13:22:48.296931+00:00 [queued]>
[2025-05-29T13:22:50.440+0000] {taskinstance.py:2613} INFO - Dependencies all met for dep_context=requeueable deps ti=<TaskInstance: 01_extract_data.ml_access_token manual__2025-05-29T13:22:48.296931+00:00 [queued]>
[2025-05-29T13:22:50.442+0000] {taskinstance.py:2866} INFO - Starting attempt 1 of 1
[2025-05-29T13:22:50.454+0000] {taskinstance.py:2889} INFO - Executing <Task(PythonOperator): ml_access_token> on 2025-05-29 13:22:48.296931+00:00
[2025-05-29T13:22:50.459+0000] {standard_task_runner.py:72} INFO - Started process 293 to run task
[2025-05-29T13:22:50.463+0000] {standard_task_runner.py:104} INFO - Running: ['***', 'tasks', 'run', '01_extract_data', 'ml_access_token', 'manual__2025-05-29T13:22:48.296931+00:00', '--job-id', '271', '--raw', '--subdir', 'DAGS_FOLDER/01_extract_dag.py', '--cfg-path', '/tmp/tmp2cield0g']
[2025-05-29T13:22:50.465+0000] {standard_task_runner.py:105} INFO - Job 271: Subtask ml_access_token
[2025-05-29T13:22:50.523+0000] {task_command.py:467} INFO - Running <TaskInstance: 01_extract_data.ml_access_token manual__2025-05-29T13:22:48.296931+00:00 [running]> on host 4465d1a8efb0
[2025-05-29T13:22:50.610+0000] {taskinstance.py:3132} INFO - Exporting env vars: AIRFLOW_CTX_DAG_OWNER='***' AIRFLOW_CTX_DAG_ID='01_extract_data' AIRFLOW_CTX_TASK_ID='ml_access_token' AIRFLOW_CTX_EXECUTION_DATE='2025-05-29T13:22:48.296931+00:00' AIRFLOW_CTX_TRY_NUMBER='1' AIRFLOW_CTX_DAG_RUN_ID='manual__2025-05-29T13:22:48.296931+00:00'
[2025-05-29T13:22:50.612+0000] {taskinstance.py:731} INFO - ::endgroup::
[2025-05-29T13:22:51.057+0000] {taskinstance.py:3311} ERROR - Task failed with exception
Traceback (most recent call last):
  File "/usr/local/lib/python3.9/shutil.py", line 825, in move
    os.rename(src, real_dst)
OSError: [Errno 16] Device or resource busy: '/tmp/tmpj4uob3zc' -> '.env'

During handling of the above exception, another exception occurred:

Traceback (most recent call last):
  File "/home/airflow/.local/lib/python3.9/site-packages/airflow/models/taskinstance.py", line 767, in _execute_task
    result = _execute_callable(context=context, **execute_callable_kwargs)
  File "/home/airflow/.local/lib/python3.9/site-packages/airflow/models/taskinstance.py", line 733, in _execute_callable
    return ExecutionCallableRunner(
  File "/home/airflow/.local/lib/python3.9/site-packages/airflow/utils/operator_helpers.py", line 252, in run
    return self.func(*args, **kwargs)
  File "/home/airflow/.local/lib/python3.9/site-packages/airflow/models/baseoperator.py", line 422, in wrapper
    return func(self, *args, **kwargs)
  File "/home/airflow/.local/lib/python3.9/site-packages/airflow/operators/python.py", line 238, in execute
    return_value = self.execute_callable()
  File "/home/airflow/.local/lib/python3.9/site-packages/airflow/operators/python.py", line 256, in execute_callable
    return runner.run(*self.op_args, **self.op_kwargs)
  File "/home/airflow/.local/lib/python3.9/site-packages/airflow/utils/operator_helpers.py", line 252, in run
    return self.func(*args, **kwargs)
  File "/opt/airflow/extraction/mercadolivre/script/get_access_token.py", line 38, in get_access_token
    set_key(".env", "ACCESS_TOKEN", token_data["access_token"])
  File "/home/airflow/.local/lib/python3.9/site-packages/dotenv/main.py", line 196, in set_key
    dest.write(line_out)
  File "/usr/local/lib/python3.9/contextlib.py", line 126, in __exit__
    next(self.gen)
  File "/home/airflow/.local/lib/python3.9/site-packages/dotenv/main.py", line 146, in rewrite
    shutil.move(dest.name, path)
  File "/usr/local/lib/python3.9/shutil.py", line 845, in move
    copy_function(src, real_dst)
  File "/usr/local/lib/python3.9/shutil.py", line 445, in copy2
    copystat(src, dst, follow_symlinks=follow_symlinks)
  File "/usr/local/lib/python3.9/shutil.py", line 384, in copystat
    lookup("utime")(dst, ns=(st.st_atime_ns, st.st_mtime_ns),
PermissionError: [Errno 1] Operation not permitted
[2025-05-29T13:22:51.074+0000] {taskinstance.py:1225} INFO - Marking task as FAILED. dag_id=01_extract_data, task_id=ml_access_token, run_id=manual__2025-05-29T13:22:48.296931+00:00, execution_date=20250529T132248, start_date=20250529T132250, end_date=20250529T132251
[2025-05-29T13:22:51.087+0000] {taskinstance.py:340} INFO - ::group::Post task execution logs
[2025-05-29T13:22:51.088+0000] {standard_task_runner.py:124} ERROR - Failed to execute job 271 for task ml_access_token ([Errno 1] Operation not permitted; 293)
Traceback (most recent call last):
  File "/usr/local/lib/python3.9/shutil.py", line 825, in move
    os.rename(src, real_dst)
OSError: [Errno 16] Device or resource busy: '/tmp/tmpj4uob3zc' -> '.env'

During handling of the above exception, another exception occurred:

Traceback (most recent call last):
  File "/home/airflow/.local/lib/python3.9/site-packages/airflow/task/task_runner/standard_task_runner.py", line 117, in _start_by_fork
    ret = args.func(args, dag=self.dag)
  File "/home/airflow/.local/lib/python3.9/site-packages/airflow/cli/cli_config.py", line 49, in command
    return func(*args, **kwargs)
  File "/home/airflow/.local/lib/python3.9/site-packages/airflow/utils/cli.py", line 116, in wrapper
    return f(*args, **kwargs)
  File "/home/airflow/.local/lib/python3.9/site-packages/airflow/cli/commands/task_command.py", line 483, in task_run
    task_return_code = _run_task_by_selected_method(args, _dag, ti)
  File "/home/airflow/.local/lib/python3.9/site-packages/airflow/cli/commands/task_command.py", line 256, in _run_task_by_selected_method
    return _run_raw_task(args, ti)
  File "/home/airflow/.local/lib/python3.9/site-packages/airflow/cli/commands/task_command.py", line 341, in _run_raw_task
    return ti._run_raw_task(
  File "/home/airflow/.local/lib/python3.9/site-packages/airflow/utils/session.py", line 97, in wrapper
    return func(*args, session=session, **kwargs)
  File "/home/airflow/.local/lib/python3.9/site-packages/airflow/models/taskinstance.py", line 3005, in _run_raw_task
    return _run_raw_task(
  File "/home/airflow/.local/lib/python3.9/site-packages/airflow/models/taskinstance.py", line 273, in _run_raw_task
    TaskInstance._execute_task_with_callbacks(
  File "/home/airflow/.local/lib/python3.9/site-packages/airflow/models/taskinstance.py", line 3159, in _execute_task_with_callbacks
    result = self._execute_task(context, task_orig)
  File "/home/airflow/.local/lib/python3.9/site-packages/airflow/models/taskinstance.py", line 3183, in _execute_task
    return _execute_task(self, context, task_orig)
  File "/home/airflow/.local/lib/python3.9/site-packages/airflow/models/taskinstance.py", line 767, in _execute_task
    result = _execute_callable(context=context, **execute_callable_kwargs)
  File "/home/airflow/.local/lib/python3.9/site-packages/airflow/models/taskinstance.py", line 733, in _execute_callable
    return ExecutionCallableRunner(
  File "/home/airflow/.local/lib/python3.9/site-packages/airflow/utils/operator_helpers.py", line 252, in run
    return self.func(*args, **kwargs)
  File "/home/airflow/.local/lib/python3.9/site-packages/airflow/models/baseoperator.py", line 422, in wrapper
    return func(self, *args, **kwargs)
  File "/home/airflow/.local/lib/python3.9/site-packages/airflow/operators/python.py", line 238, in execute
    return_value = self.execute_callable()
  File "/home/airflow/.local/lib/python3.9/site-packages/airflow/operators/python.py", line 256, in execute_callable
    return runner.run(*self.op_args, **self.op_kwargs)
  File "/home/airflow/.local/lib/python3.9/site-packages/airflow/utils/operator_helpers.py", line 252, in run
    return self.func(*args, **kwargs)
  File "/opt/airflow/extraction/mercadolivre/script/get_access_token.py", line 38, in get_access_token
    set_key(".env", "ACCESS_TOKEN", token_data["access_token"])
  File "/home/airflow/.local/lib/python3.9/site-packages/dotenv/main.py", line 196, in set_key
    dest.write(line_out)
  File "/usr/local/lib/python3.9/contextlib.py", line 126, in __exit__
    next(self.gen)
  File "/home/airflow/.local/lib/python3.9/site-packages/dotenv/main.py", line 146, in rewrite
    shutil.move(dest.name, path)
  File "/usr/local/lib/python3.9/shutil.py", line 845, in move
    copy_function(src, real_dst)
  File "/usr/local/lib/python3.9/shutil.py", line 445, in copy2
    copystat(src, dst, follow_symlinks=follow_symlinks)
  File "/usr/local/lib/python3.9/shutil.py", line 384, in copystat
    lookup("utime")(dst, ns=(st.st_atime_ns, st.st_mtime_ns),
PermissionError: [Errno 1] Operation not permitted
[2025-05-29T13:22:51.119+0000] {local_task_job_runner.py:266} INFO - Task exited with return code 1
[2025-05-29T13:22:51.138+0000] {taskinstance.py:3895} INFO - 0 downstream tasks scheduled from follow-on schedule check
[2025-05-29T13:22:51.140+0000] {local_task_job_runner.py:245} INFO - ::endgroup::
