[2025-05-21T14:04:13.432+0000] {local_task_job_runner.py:123} INFO - ::group::Pre task execution logs
[2025-05-21T14:04:13.450+0000] {taskinstance.py:2613} INFO - Dependencies all met for dep_context=non-requeueable deps ti=<TaskInstance: 04_transform_data.run_dbt manual__2025-05-21T14:04:11.511661+00:00 [queued]>
[2025-05-21T14:04:13.458+0000] {taskinstance.py:2613} INFO - Dependencies all met for dep_context=requeueable deps ti=<TaskInstance: 04_transform_data.run_dbt manual__2025-05-21T14:04:11.511661+00:00 [queued]>
[2025-05-21T14:04:13.460+0000] {taskinstance.py:2866} INFO - Starting attempt 1 of 1
[2025-05-21T14:04:13.473+0000] {taskinstance.py:2889} INFO - Executing <Task(PythonOperator): run_dbt> on 2025-05-21 14:04:11.511661+00:00
[2025-05-21T14:04:13.477+0000] {standard_task_runner.py:72} INFO - Started process 1139 to run task
[2025-05-21T14:04:13.480+0000] {standard_task_runner.py:104} INFO - Running: ['***', 'tasks', 'run', '04_transform_data', 'run_dbt', 'manual__2025-05-21T14:04:11.511661+00:00', '--job-id', '86', '--raw', '--subdir', 'DAGS_FOLDER/04_transform_data.py', '--cfg-path', '/tmp/tmpnxbm6eoz']
[2025-05-21T14:04:13.482+0000] {standard_task_runner.py:105} INFO - Job 86: Subtask run_dbt
[2025-05-21T14:04:13.534+0000] {task_command.py:467} INFO - Running <TaskInstance: 04_transform_data.run_dbt manual__2025-05-21T14:04:11.511661+00:00 [running]> on host e27e96d1841a
[2025-05-21T14:04:13.616+0000] {taskinstance.py:3132} INFO - Exporting env vars: AIRFLOW_CTX_DAG_OWNER='***' AIRFLOW_CTX_DAG_ID='04_transform_data' AIRFLOW_CTX_TASK_ID='run_dbt' AIRFLOW_CTX_EXECUTION_DATE='2025-05-21T14:04:11.511661+00:00' AIRFLOW_CTX_TRY_NUMBER='1' AIRFLOW_CTX_DAG_RUN_ID='manual__2025-05-21T14:04:11.511661+00:00'
[2025-05-21T14:04:13.618+0000] {taskinstance.py:731} INFO - ::endgroup::
[2025-05-21T14:04:15.315+0000] {logging_mixin.py:190} INFO - 14:04:15  Running with dbt=1.9.4
[2025-05-21T14:04:15.640+0000] {logging_mixin.py:190} INFO - 14:04:15  Registered adapter: postgres=1.9.0
[2025-05-21T14:04:16.725+0000] {logging_mixin.py:190} INFO - 14:04:16  [WARNING]: Configuration paths exist in your dbt_project.yml file which do not apply to any resources.
There are 1 unused configuration paths:
- models.e_commerce_sales.example
[2025-05-21T14:04:16.897+0000] {logging_mixin.py:190} INFO - 14:04:16  Found 8 models, 12 sources, 433 macros
[2025-05-21T14:04:16.901+0000] {logging_mixin.py:190} INFO - 14:04:16
[2025-05-21T14:04:16.903+0000] {logging_mixin.py:190} INFO - 14:04:16  Concurrency: 4 threads (target='dev')
[2025-05-21T14:04:16.904+0000] {logging_mixin.py:190} INFO - 14:04:16
[2025-05-21T14:04:17.028+0000] {logging_mixin.py:190} INFO - 14:04:17  1 of 8 START sql incremental model sales.mercadolivre_orders_results ........... [RUN]
[2025-05-21T14:04:17.030+0000] {logging_mixin.py:190} INFO - 14:04:17  2 of 8 START sql incremental model sales.shopee_new_id ......................... [RUN]
[2025-05-21T14:04:17.367+0000] {logging_mixin.py:190} INFO - 14:04:17  2 of 8 OK created sql incremental model sales.shopee_new_id .................... [MERGE 0 in 0.33s]
[2025-05-21T14:04:17.371+0000] {logging_mixin.py:190} INFO - 14:04:17  1 of 8 OK created sql incremental model sales.mercadolivre_orders_results ...... [MERGE 255 in 0.34s]
[2025-05-21T14:04:17.378+0000] {logging_mixin.py:190} INFO - 14:04:17  3 of 8 START sql incremental model sales.shopee_orders_results ................. [RUN]
[2025-05-21T14:04:17.379+0000] {logging_mixin.py:190} INFO - 14:04:17  4 of 8 START sql incremental model sales.mercadolivre_profits .................. [RUN]
[2025-05-21T14:04:17.539+0000] {logging_mixin.py:190} INFO - 14:04:17  3 of 8 OK created sql incremental model sales.shopee_orders_results ............ [MERGE 0 in 0.16s]
[2025-05-21T14:04:17.541+0000] {logging_mixin.py:190} INFO - 14:04:17  4 of 8 OK created sql incremental model sales.mercadolivre_profits ............. [MERGE 250 in 0.16s]
[2025-05-21T14:04:17.547+0000] {logging_mixin.py:190} INFO - 14:04:17  5 of 8 START sql incremental model sales.dim_shopee_buyer_id ................... [RUN]
[2025-05-21T14:04:17.549+0000] {logging_mixin.py:190} INFO - 14:04:17  6 of 8 START sql incremental model sales.dim_shopee_orders ..................... [RUN]
[2025-05-21T14:04:17.550+0000] {logging_mixin.py:190} INFO - 14:04:17  7 of 8 START sql incremental model sales.dim_shopee_orders_status .............. [RUN]
[2025-05-21T14:04:17.555+0000] {logging_mixin.py:190} INFO - 14:04:17  8 of 8 START sql incremental model sales.dim_shopee_product .................... [RUN]
[2025-05-21T14:04:17.701+0000] {logging_mixin.py:190} INFO - 14:04:17  5 of 8 ERROR creating sql incremental model sales.dim_shopee_buyer_id .......... [ERROR in 0.14s]
[2025-05-21T14:04:17.703+0000] {logging_mixin.py:190} INFO - 14:04:17  7 of 8 ERROR creating sql incremental model sales.dim_shopee_orders_status ..... [ERROR in 0.14s]
[2025-05-21T14:04:17.758+0000] {logging_mixin.py:190} INFO - 14:04:17  6 of 8 OK created sql incremental model sales.dim_shopee_orders ................ [MERGE 0 in 0.20s]
[2025-05-21T14:04:17.762+0000] {logging_mixin.py:190} INFO - 14:04:17  8 of 8 OK created sql incremental model sales.dim_shopee_product ............... [MERGE 0 in 0.20s]
[2025-05-21T14:04:17.786+0000] {logging_mixin.py:190} INFO - 14:04:17
[2025-05-21T14:04:17.787+0000] {logging_mixin.py:190} INFO - 14:04:17  Finished running 8 incremental models in 0 hours 0 minutes and 0.88 seconds (0.88s).
[2025-05-21T14:04:17.850+0000] {logging_mixin.py:190} INFO - 14:04:17
[2025-05-21T14:04:17.852+0000] {logging_mixin.py:190} INFO - 14:04:17  Completed with 2 errors, 0 partial successes, and 0 warnings:
[2025-05-21T14:04:17.853+0000] {logging_mixin.py:190} INFO - 14:04:17
[2025-05-21T14:04:17.855+0000] {logging_mixin.py:190} INFO - 14:04:17    Database Error in model dim_shopee_buyer_id (models/core/dim_shopee_buyer_id.sql)
  missing FROM-clause entry for table "update_data"
  LINE 74:         update_data.ld_timestamp
                   ^
  compiled code at target/run/e_commerce_sales/models/core/dim_shopee_buyer_id.sql
[2025-05-21T14:04:17.857+0000] {logging_mixin.py:190} INFO - 14:04:17
[2025-05-21T14:04:17.859+0000] {logging_mixin.py:190} INFO - 14:04:17    Database Error in model dim_shopee_orders_status (models/core/dim_shopee_orders_status.sql)
  syntax error at or near "AS"
  LINE 35:     LEFT JOIN AS delivery_data
                         ^
  compiled code at target/run/e_commerce_sales/models/core/dim_shopee_orders_status.sql
[2025-05-21T14:04:17.860+0000] {logging_mixin.py:190} INFO - 14:04:17
[2025-05-21T14:04:17.862+0000] {logging_mixin.py:190} INFO - 14:04:17  Done. PASS=6 WARN=0 ERROR=2 SKIP=0 TOTAL=8
[2025-05-21T14:04:18.771+0000] {logging_mixin.py:190} INFO - dbt run failed!
[2025-05-21T14:04:18.775+0000] {logging_mixin.py:190} INFO - None
[2025-05-21T14:04:18.777+0000] {taskinstance.py:3311} ERROR - Task failed with exception
Traceback (most recent call last):
  File "/home/airflow/.local/lib/python3.9/site-packages/airflow/models/taskinstance.py", line 767, in _execute_task
    result = _execute_callable(context=context, **execute_callable_kwargs)
  File "/home/airflow/.local/lib/python3.9/site-packages/airflow/models/taskinstance.py", line 733, in _execute_callable
    return ExecutionCallableRunner(
  File "/home/airflow/.local/lib/python3.9/site-packages/airflow/utils/operator_helpers.py", line 252, in run
    return self.func(*args, **kwargs)
  File "/home/airflow/.local/lib/python3.9/site-packages/airflow/models/baseoperator.py", line 422, in wrapper
    return func(self, *args, **kwargs)
  File "/home/airflow/.local/lib/python3.9/site-packages/airflow/operators/python.py", line 238, in execute
    return_value = self.execute_callable()
  File "/home/airflow/.local/lib/python3.9/site-packages/airflow/operators/python.py", line 256, in execute_callable
    return runner.run(*self.op_args, **self.op_kwargs)
  File "/home/airflow/.local/lib/python3.9/site-packages/airflow/utils/operator_helpers.py", line 252, in run
    return self.func(*args, **kwargs)
  File "/opt/airflow/dbt/run_dbt.py", line 22, in transform_data
    raise RuntimeError("dbt run failed")
RuntimeError: dbt run failed
[2025-05-21T14:04:18.787+0000] {taskinstance.py:1225} INFO - Marking task as FAILED. dag_id=04_transform_data, task_id=run_dbt, run_id=manual__2025-05-21T14:04:11.511661+00:00, execution_date=20250521T140411, start_date=20250521T140413, end_date=20250521T140418
[2025-05-21T14:04:18.798+0000] {taskinstance.py:340} INFO - ::group::Post task execution logs
[2025-05-21T14:04:18.800+0000] {standard_task_runner.py:124} ERROR - Failed to execute job 86 for task run_dbt (dbt run failed; 1139)
Traceback (most recent call last):
  File "/home/airflow/.local/lib/python3.9/site-packages/airflow/task/task_runner/standard_task_runner.py", line 117, in _start_by_fork
    ret = args.func(args, dag=self.dag)
  File "/home/airflow/.local/lib/python3.9/site-packages/airflow/cli/cli_config.py", line 49, in command
    return func(*args, **kwargs)
  File "/home/airflow/.local/lib/python3.9/site-packages/airflow/utils/cli.py", line 116, in wrapper
    return f(*args, **kwargs)
  File "/home/airflow/.local/lib/python3.9/site-packages/airflow/cli/commands/task_command.py", line 483, in task_run
    task_return_code = _run_task_by_selected_method(args, _dag, ti)
  File "/home/airflow/.local/lib/python3.9/site-packages/airflow/cli/commands/task_command.py", line 256, in _run_task_by_selected_method
    return _run_raw_task(args, ti)
  File "/home/airflow/.local/lib/python3.9/site-packages/airflow/cli/commands/task_command.py", line 341, in _run_raw_task
    return ti._run_raw_task(
  File "/home/airflow/.local/lib/python3.9/site-packages/airflow/utils/session.py", line 97, in wrapper
    return func(*args, session=session, **kwargs)
  File "/home/airflow/.local/lib/python3.9/site-packages/airflow/models/taskinstance.py", line 3005, in _run_raw_task
    return _run_raw_task(
  File "/home/airflow/.local/lib/python3.9/site-packages/airflow/models/taskinstance.py", line 273, in _run_raw_task
    TaskInstance._execute_task_with_callbacks(
  File "/home/airflow/.local/lib/python3.9/site-packages/airflow/models/taskinstance.py", line 3159, in _execute_task_with_callbacks
    result = self._execute_task(context, task_orig)
  File "/home/airflow/.local/lib/python3.9/site-packages/airflow/models/taskinstance.py", line 3183, in _execute_task
    return _execute_task(self, context, task_orig)
  File "/home/airflow/.local/lib/python3.9/site-packages/airflow/models/taskinstance.py", line 767, in _execute_task
    result = _execute_callable(context=context, **execute_callable_kwargs)
  File "/home/airflow/.local/lib/python3.9/site-packages/airflow/models/taskinstance.py", line 733, in _execute_callable
    return ExecutionCallableRunner(
  File "/home/airflow/.local/lib/python3.9/site-packages/airflow/utils/operator_helpers.py", line 252, in run
    return self.func(*args, **kwargs)
  File "/home/airflow/.local/lib/python3.9/site-packages/airflow/models/baseoperator.py", line 422, in wrapper
    return func(self, *args, **kwargs)
  File "/home/airflow/.local/lib/python3.9/site-packages/airflow/operators/python.py", line 238, in execute
    return_value = self.execute_callable()
  File "/home/airflow/.local/lib/python3.9/site-packages/airflow/operators/python.py", line 256, in execute_callable
    return runner.run(*self.op_args, **self.op_kwargs)
  File "/home/airflow/.local/lib/python3.9/site-packages/airflow/utils/operator_helpers.py", line 252, in run
    return self.func(*args, **kwargs)
  File "/opt/airflow/dbt/run_dbt.py", line 22, in transform_data
    raise RuntimeError("dbt run failed")
RuntimeError: dbt run failed
[2025-05-21T14:04:18.836+0000] {local_task_job_runner.py:266} INFO - Task exited with return code 1
[2025-05-21T14:04:18.851+0000] {taskinstance.py:3895} INFO - 0 downstream tasks scheduled from follow-on schedule check
[2025-05-21T14:04:18.854+0000] {local_task_job_runner.py:245} INFO - ::endgroup::
