[2025-06-12T00:15:55.939+0000] {local_task_job_runner.py:123} INFO - ::group::Pre task execution logs
[2025-06-12T00:15:55.956+0000] {taskinstance.py:2613} INFO - Dependencies all met for dep_context=non-requeueable deps ti=<TaskInstance: 05_transform_data_prod.run_dbt manual__2025-06-12T00:15:46.644414+00:00 [queued]>
[2025-06-12T00:15:55.964+0000] {taskinstance.py:2613} INFO - Dependencies all met for dep_context=requeueable deps ti=<TaskInstance: 05_transform_data_prod.run_dbt manual__2025-06-12T00:15:46.644414+00:00 [queued]>
[2025-06-12T00:15:55.965+0000] {taskinstance.py:2866} INFO - Starting attempt 1 of 1
[2025-06-12T00:15:55.976+0000] {taskinstance.py:2889} INFO - Executing <Task(PythonOperator): run_dbt> on 2025-06-12 00:15:46.644414+00:00
[2025-06-12T00:15:55.981+0000] {standard_task_runner.py:72} INFO - Started process 8954 to run task
[2025-06-12T00:15:55.984+0000] {standard_task_runner.py:104} INFO - Running: ['***', 'tasks', 'run', '05_transform_data_prod', 'run_dbt', 'manual__2025-06-12T00:15:46.644414+00:00', '--job-id', '998', '--raw', '--subdir', 'DAGS_FOLDER/05_transform_data_prod.py', '--cfg-path', '/tmp/tmp0xtjl2ij']
[2025-06-12T00:15:55.985+0000] {standard_task_runner.py:105} INFO - Job 998: Subtask run_dbt
[2025-06-12T00:15:56.041+0000] {task_command.py:467} INFO - Running <TaskInstance: 05_transform_data_prod.run_dbt manual__2025-06-12T00:15:46.644414+00:00 [running]> on host 28e6a58e4107
[2025-06-12T00:15:56.119+0000] {taskinstance.py:3132} INFO - Exporting env vars: AIRFLOW_CTX_DAG_OWNER='***' AIRFLOW_CTX_DAG_ID='05_transform_data_prod' AIRFLOW_CTX_TASK_ID='run_dbt' AIRFLOW_CTX_EXECUTION_DATE='2025-06-12T00:15:46.644414+00:00' AIRFLOW_CTX_TRY_NUMBER='1' AIRFLOW_CTX_DAG_RUN_ID='manual__2025-06-12T00:15:46.644414+00:00'
[2025-06-12T00:15:56.121+0000] {taskinstance.py:731} INFO - ::endgroup::
[2025-06-12T00:15:57.615+0000] {logging_mixin.py:190} INFO - 00:15:57  Running with dbt=1.9.5
[2025-06-12T00:15:57.998+0000] {logging_mixin.py:190} INFO - 00:15:57  Registered adapter: postgres=1.9.0
[2025-06-12T00:15:59.417+0000] {logging_mixin.py:190} INFO - 00:15:59  [WARNING]: Configuration paths exist in your dbt_project.yml file which do not apply to any resources.
There are 1 unused configuration paths:
- models.e_commerce_sales.example
[2025-06-12T00:15:59.859+0000] {logging_mixin.py:190} INFO - 00:15:59  Found 21 models, 12 sources, 549 macros, 1 unit test
[2025-06-12T00:15:59.864+0000] {logging_mixin.py:190} INFO - 00:15:59
[2025-06-12T00:15:59.867+0000] {logging_mixin.py:190} INFO - 00:15:59  Concurrency: 4 threads (target='prod')
[2025-06-12T00:15:59.868+0000] {logging_mixin.py:190} INFO - 00:15:59
[2025-06-12T00:16:00.042+0000] {logging_mixin.py:190} INFO - 00:16:00  1 of 21 START sql incremental model sales_stg.stg_mercadolivre ................. [RUN]
[2025-06-12T00:16:00.044+0000] {logging_mixin.py:190} INFO - 00:16:00  2 of 21 START sql incremental model sales_stg.stg_mercadolivre__order_items .... [RUN]
[2025-06-12T00:16:00.046+0000] {logging_mixin.py:190} INFO - 00:16:00  3 of 21 START sql incremental model sales_stg.stg_mercadolivre__payments ....... [RUN]
[2025-06-12T00:16:00.048+0000] {logging_mixin.py:190} INFO - 00:16:00  4 of 21 START sql incremental model sales_stg.stg_mercadolivre_sh .............. [RUN]
[2025-06-12T00:16:00.272+0000] {logging_mixin.py:190} INFO - 00:16:00  1 of 21 ERROR creating sql incremental model sales_stg.stg_mercadolivre ........ [ERROR in 0.22s]
[2025-06-12T00:16:00.274+0000] {logging_mixin.py:190} INFO - 00:16:00  3 of 21 ERROR creating sql incremental model sales_stg.stg_mercadolivre__payments  [ERROR in 0.22s]
[2025-06-12T00:16:00.275+0000] {logging_mixin.py:190} INFO - 00:16:00  4 of 21 ERROR creating sql incremental model sales_stg.stg_mercadolivre_sh ..... [ERROR in 0.22s]
[2025-06-12T00:16:00.277+0000] {logging_mixin.py:190} INFO - 00:16:00  2 of 21 ERROR creating sql incremental model sales_stg.stg_mercadolivre__order_items  [ERROR in 0.22s]
[2025-06-12T00:16:00.285+0000] {logging_mixin.py:190} INFO - 00:16:00  5 of 21 START sql incremental model sales_stg.stg_shopee ....................... [RUN]
[2025-06-12T00:16:00.302+0000] {logging_mixin.py:190} INFO - 00:16:00  6 of 21 SKIP relation sales.mercadolivre_orders_results ........................ [SKIP]
[2025-06-12T00:16:00.310+0000] {logging_mixin.py:190} INFO - 00:16:00  7 of 21 SKIP relation sales.dim_mercadolivre_buyer ............................. [SKIP]
[2025-06-12T00:16:00.311+0000] {logging_mixin.py:190} INFO - 00:16:00  8 of 21 SKIP relation sales.dim_mercadolivre_date .............................. [SKIP]
[2025-06-12T00:16:00.313+0000] {logging_mixin.py:190} INFO - 00:16:00  9 of 21 SKIP relation sales.dim_mercadolivre_orders_status ..................... [SKIP]
[2025-06-12T00:16:00.331+0000] {logging_mixin.py:190} INFO - 00:16:00  10 of 21 SKIP relation sales.dim_mercadolivre_product .......................... [SKIP]
[2025-06-12T00:16:00.333+0000] {logging_mixin.py:190} INFO - 00:16:00  11 of 21 SKIP relation sales.sum_mercadolivre_monthly_profit ................... [SKIP]
[2025-06-12T00:16:00.335+0000] {logging_mixin.py:190} INFO - 00:16:00  12 of 21 SKIP relation sales.sum_mercadolivre_monthly_revenue .................. [SKIP]
[2025-06-12T00:16:00.342+0000] {logging_mixin.py:190} INFO - 00:16:00  13 of 21 SKIP relation sales.sum_mercadolivre_monthly_sold ..................... [SKIP]
[2025-06-12T00:16:00.350+0000] {logging_mixin.py:190} INFO - 00:16:00  5 of 21 ERROR creating sql incremental model sales_stg.stg_shopee .............. [ERROR in 0.06s]
[2025-06-12T00:16:00.356+0000] {logging_mixin.py:190} INFO - 00:16:00  14 of 21 SKIP relation sales.shopee_orders_results ............................. [SKIP]
[2025-06-12T00:16:00.362+0000] {logging_mixin.py:190} INFO - 00:16:00  15 of 21 SKIP relation sales.dim_shopee_buyer .................................. [SKIP]
[2025-06-12T00:16:00.363+0000] {logging_mixin.py:190} INFO - 00:16:00  16 of 21 SKIP relation sales.dim_shopee_date ................................... [SKIP]
[2025-06-12T00:16:00.365+0000] {logging_mixin.py:190} INFO - 00:16:00  17 of 21 SKIP relation sales.dim_shopee_orders_status .......................... [SKIP]
[2025-06-12T00:16:00.366+0000] {logging_mixin.py:190} INFO - 00:16:00  18 of 21 SKIP relation sales.dim_shopee_product ................................ [SKIP]
[2025-06-12T00:16:00.376+0000] {logging_mixin.py:190} INFO - 00:16:00  19 of 21 SKIP relation sales.sum_shopee_monthly_profit ......................... [SKIP]
[2025-06-12T00:16:00.378+0000] {logging_mixin.py:190} INFO - 00:16:00  20 of 21 SKIP relation sales.sum_shopee_monthly_revenue ........................ [SKIP]
[2025-06-12T00:16:00.379+0000] {logging_mixin.py:190} INFO - 00:16:00  21 of 21 SKIP relation sales.sum_shopee_products_sold .......................... [SKIP]
[2025-06-12T00:16:00.406+0000] {logging_mixin.py:190} INFO - 00:16:00
[2025-06-12T00:16:00.407+0000] {logging_mixin.py:190} INFO - 00:16:00  Finished running 15 incremental models, 6 view models in 0 hours 0 minutes and 0.54 seconds (0.54s).
[2025-06-12T00:16:00.484+0000] {logging_mixin.py:190} INFO - 00:16:00
[2025-06-12T00:16:00.486+0000] {logging_mixin.py:190} INFO - 00:16:00  Completed with 5 errors, 0 partial successes, and 0 warnings:
[2025-06-12T00:16:00.487+0000] {logging_mixin.py:190} INFO - 00:16:00
[2025-06-12T00:16:00.489+0000] {logging_mixin.py:190} INFO - 00:16:00    Database Error in model stg_mercadolivre (models/staging/stg_mercadolivre.sql)
  relation "entry.entry_mercadolivre" does not exist
  LINE 53:         FROM "sales_db"."entry"."entry_mercadolivre", max_ti...
                        ^
[2025-06-12T00:16:00.491+0000] {logging_mixin.py:190} INFO - 00:16:00
[2025-06-12T00:16:00.492+0000] {logging_mixin.py:190} INFO - 00:16:00    Database Error in model stg_mercadolivre__payments (models/staging/stg_mercadolivre__payments.sql)
  relation "entry.entry_mercadolivre__payments" does not exist
  LINE 54:         FROM "sales_db"."entry"."entry_mercadolivre__payment...
                        ^
[2025-06-12T00:16:00.494+0000] {logging_mixin.py:190} INFO - 00:16:00
[2025-06-12T00:16:00.496+0000] {logging_mixin.py:190} INFO - 00:16:00    Database Error in model stg_mercadolivre_sh (models/staging/stg_mercadolivre_sh.sql)
  relation "entry.entry_mercadolivre_sh" does not exist
  LINE 117:         FROM "sales_db"."entry"."entry_mercadolivre_sh", max...
                         ^
[2025-06-12T00:16:00.497+0000] {logging_mixin.py:190} INFO - 00:16:00
[2025-06-12T00:16:00.499+0000] {logging_mixin.py:190} INFO - 00:16:00    Database Error in model stg_mercadolivre__order_items (models/staging/stg_mercadolivre__order_items.sql)
  relation "entry.entry_mercadolivre__order_items" does not exist
  LINE 39:         FROM "sales_db"."entry"."entry_mercadolivre__order_i...
                        ^
[2025-06-12T00:16:00.500+0000] {logging_mixin.py:190} INFO - 00:16:00
[2025-06-12T00:16:00.502+0000] {logging_mixin.py:190} INFO - 00:16:00    Database Error in model stg_shopee (models/staging/stg_shopee.sql)
  relation "entry.entry_shopee" does not exist
  LINE 76:     FROM "sales_db"."entry"."entry_shopee"
                    ^
[2025-06-12T00:16:00.504+0000] {logging_mixin.py:190} INFO - 00:16:00
[2025-06-12T00:16:00.505+0000] {logging_mixin.py:190} INFO - 00:16:00  Done. PASS=0 WARN=0 ERROR=5 SKIP=16 TOTAL=21
[2025-06-12T00:16:01.356+0000] {logging_mixin.py:190} INFO - dbt run failed!
[2025-06-12T00:16:01.357+0000] {logging_mixin.py:190} INFO - None
[2025-06-12T00:16:01.358+0000] {taskinstance.py:3311} ERROR - Task failed with exception
Traceback (most recent call last):
  File "/home/airflow/.local/lib/python3.9/site-packages/airflow/models/taskinstance.py", line 767, in _execute_task
    result = _execute_callable(context=context, **execute_callable_kwargs)
  File "/home/airflow/.local/lib/python3.9/site-packages/airflow/models/taskinstance.py", line 733, in _execute_callable
    return ExecutionCallableRunner(
  File "/home/airflow/.local/lib/python3.9/site-packages/airflow/utils/operator_helpers.py", line 252, in run
    return self.func(*args, **kwargs)
  File "/home/airflow/.local/lib/python3.9/site-packages/airflow/models/baseoperator.py", line 422, in wrapper
    return func(self, *args, **kwargs)
  File "/home/airflow/.local/lib/python3.9/site-packages/airflow/operators/python.py", line 238, in execute
    return_value = self.execute_callable()
  File "/home/airflow/.local/lib/python3.9/site-packages/airflow/operators/python.py", line 256, in execute_callable
    return runner.run(*self.op_args, **self.op_kwargs)
  File "/home/airflow/.local/lib/python3.9/site-packages/airflow/utils/operator_helpers.py", line 252, in run
    return self.func(*args, **kwargs)
  File "/opt/airflow/dbt_files/run_dbt.py", line 24, in transform_data
    raise RuntimeError("dbt run failed")
RuntimeError: dbt run failed
[2025-06-12T00:16:01.370+0000] {taskinstance.py:1225} INFO - Marking task as FAILED. dag_id=05_transform_data_prod, task_id=run_dbt, run_id=manual__2025-06-12T00:15:46.644414+00:00, execution_date=20250612T001546, start_date=20250612T001555, end_date=20250612T001601
[2025-06-12T00:16:01.386+0000] {taskinstance.py:340} INFO - ::group::Post task execution logs
[2025-06-12T00:16:01.387+0000] {standard_task_runner.py:124} ERROR - Failed to execute job 998 for task run_dbt (dbt run failed; 8954)
Traceback (most recent call last):
  File "/home/airflow/.local/lib/python3.9/site-packages/airflow/task/task_runner/standard_task_runner.py", line 117, in _start_by_fork
    ret = args.func(args, dag=self.dag)
  File "/home/airflow/.local/lib/python3.9/site-packages/airflow/cli/cli_config.py", line 49, in command
    return func(*args, **kwargs)
  File "/home/airflow/.local/lib/python3.9/site-packages/airflow/utils/cli.py", line 116, in wrapper
    return f(*args, **kwargs)
  File "/home/airflow/.local/lib/python3.9/site-packages/airflow/cli/commands/task_command.py", line 483, in task_run
    task_return_code = _run_task_by_selected_method(args, _dag, ti)
  File "/home/airflow/.local/lib/python3.9/site-packages/airflow/cli/commands/task_command.py", line 256, in _run_task_by_selected_method
    return _run_raw_task(args, ti)
  File "/home/airflow/.local/lib/python3.9/site-packages/airflow/cli/commands/task_command.py", line 341, in _run_raw_task
    return ti._run_raw_task(
  File "/home/airflow/.local/lib/python3.9/site-packages/airflow/utils/session.py", line 97, in wrapper
    return func(*args, session=session, **kwargs)
  File "/home/airflow/.local/lib/python3.9/site-packages/airflow/models/taskinstance.py", line 3005, in _run_raw_task
    return _run_raw_task(
  File "/home/airflow/.local/lib/python3.9/site-packages/airflow/models/taskinstance.py", line 273, in _run_raw_task
    TaskInstance._execute_task_with_callbacks(
  File "/home/airflow/.local/lib/python3.9/site-packages/airflow/models/taskinstance.py", line 3159, in _execute_task_with_callbacks
    result = self._execute_task(context, task_orig)
  File "/home/airflow/.local/lib/python3.9/site-packages/airflow/models/taskinstance.py", line 3183, in _execute_task
    return _execute_task(self, context, task_orig)
  File "/home/airflow/.local/lib/python3.9/site-packages/airflow/models/taskinstance.py", line 767, in _execute_task
    result = _execute_callable(context=context, **execute_callable_kwargs)
  File "/home/airflow/.local/lib/python3.9/site-packages/airflow/models/taskinstance.py", line 733, in _execute_callable
    return ExecutionCallableRunner(
  File "/home/airflow/.local/lib/python3.9/site-packages/airflow/utils/operator_helpers.py", line 252, in run
    return self.func(*args, **kwargs)
  File "/home/airflow/.local/lib/python3.9/site-packages/airflow/models/baseoperator.py", line 422, in wrapper
    return func(self, *args, **kwargs)
  File "/home/airflow/.local/lib/python3.9/site-packages/airflow/operators/python.py", line 238, in execute
    return_value = self.execute_callable()
  File "/home/airflow/.local/lib/python3.9/site-packages/airflow/operators/python.py", line 256, in execute_callable
    return runner.run(*self.op_args, **self.op_kwargs)
  File "/home/airflow/.local/lib/python3.9/site-packages/airflow/utils/operator_helpers.py", line 252, in run
    return self.func(*args, **kwargs)
  File "/opt/airflow/dbt_files/run_dbt.py", line 24, in transform_data
    raise RuntimeError("dbt run failed")
RuntimeError: dbt run failed
[2025-06-12T00:16:01.423+0000] {local_task_job_runner.py:266} INFO - Task exited with return code 1
[2025-06-12T00:16:01.442+0000] {taskinstance.py:3895} INFO - 0 downstream tasks scheduled from follow-on schedule check
[2025-06-12T00:16:01.445+0000] {local_task_job_runner.py:245} INFO - ::endgroup::
