[2025-05-22T19:15:52.453+0000] {local_task_job_runner.py:123} INFO - ::group::Pre task execution logs
[2025-05-22T19:15:52.471+0000] {taskinstance.py:2613} INFO - Dependencies all met for dep_context=non-requeueable deps ti=<TaskInstance: 04_transform_data.run_dbt manual__2025-05-22T19:15:43.081981+00:00 [queued]>
[2025-05-22T19:15:52.480+0000] {taskinstance.py:2613} INFO - Dependencies all met for dep_context=requeueable deps ti=<TaskInstance: 04_transform_data.run_dbt manual__2025-05-22T19:15:43.081981+00:00 [queued]>
[2025-05-22T19:15:52.482+0000] {taskinstance.py:2866} INFO - Starting attempt 1 of 1
[2025-05-22T19:15:52.496+0000] {taskinstance.py:2889} INFO - Executing <Task(PythonOperator): run_dbt> on 2025-05-22 19:15:43.081981+00:00
[2025-05-22T19:15:52.501+0000] {standard_task_runner.py:72} INFO - Started process 3964 to run task
[2025-05-22T19:15:52.504+0000] {standard_task_runner.py:104} INFO - Running: ['***', 'tasks', 'run', '04_transform_data', 'run_dbt', 'manual__2025-05-22T19:15:43.081981+00:00', '--job-id', '216', '--raw', '--subdir', 'DAGS_FOLDER/04_transform_data.py', '--cfg-path', '/tmp/tmpvcu1b3il']
[2025-05-22T19:15:52.507+0000] {standard_task_runner.py:105} INFO - Job 216: Subtask run_dbt
[2025-05-22T19:15:52.566+0000] {task_command.py:467} INFO - Running <TaskInstance: 04_transform_data.run_dbt manual__2025-05-22T19:15:43.081981+00:00 [running]> on host e27e96d1841a
[2025-05-22T19:15:52.653+0000] {taskinstance.py:3132} INFO - Exporting env vars: AIRFLOW_CTX_DAG_OWNER='***' AIRFLOW_CTX_DAG_ID='04_transform_data' AIRFLOW_CTX_TASK_ID='run_dbt' AIRFLOW_CTX_EXECUTION_DATE='2025-05-22T19:15:43.081981+00:00' AIRFLOW_CTX_TRY_NUMBER='1' AIRFLOW_CTX_DAG_RUN_ID='manual__2025-05-22T19:15:43.081981+00:00'
[2025-05-22T19:15:52.655+0000] {taskinstance.py:731} INFO - ::endgroup::
[2025-05-22T19:15:54.210+0000] {logging_mixin.py:190} INFO - 19:15:54  Running with dbt=1.9.4
[2025-05-22T19:15:54.573+0000] {logging_mixin.py:190} INFO - 19:15:54  Registered adapter: postgres=1.9.0
[2025-05-22T19:15:56.392+0000] {logging_mixin.py:190} INFO - 19:15:56  [WARNING]: Configuration paths exist in your dbt_project.yml file which do not apply to any resources.
There are 1 unused configuration paths:
- models.e_commerce_sales.example
[2025-05-22T19:15:56.569+0000] {logging_mixin.py:190} INFO - 19:15:56  Found 11 models, 12 sources, 549 macros
[2025-05-22T19:15:56.574+0000] {logging_mixin.py:190} INFO - 19:15:56
[2025-05-22T19:15:56.575+0000] {logging_mixin.py:190} INFO - 19:15:56  Concurrency: 4 threads (target='dev')
[2025-05-22T19:15:56.577+0000] {logging_mixin.py:190} INFO - 19:15:56
[2025-05-22T19:15:56.709+0000] {logging_mixin.py:190} INFO - 19:15:56  1 of 11 START sql incremental model sales.mercadolivre_orders_results .......... [RUN]
[2025-05-22T19:15:56.710+0000] {logging_mixin.py:190} INFO - 19:15:56  2 of 11 START sql incremental model sales.shopee_new_id ........................ [RUN]
[2025-05-22T19:15:57.068+0000] {logging_mixin.py:190} INFO - 19:15:57  2 of 11 OK created sql incremental model sales.shopee_new_id ................... [MERGE 0 in 0.35s]
[2025-05-22T19:15:57.072+0000] {logging_mixin.py:190} INFO - 19:15:57  1 of 11 OK created sql incremental model sales.mercadolivre_orders_results ..... [MERGE 190 in 0.36s]
[2025-05-22T19:15:57.077+0000] {logging_mixin.py:190} INFO - 19:15:57  3 of 11 START sql incremental model sales.shopee_orders_results ................ [RUN]
[2025-05-22T19:15:57.083+0000] {logging_mixin.py:190} INFO - 19:15:57  4 of 11 START sql incremental model sales.dim_mercadolivre_buyer ............... [RUN]
[2025-05-22T19:15:57.084+0000] {logging_mixin.py:190} INFO - 19:15:57  5 of 11 START sql incremental model sales.dim_mercadolivre_date ................ [RUN]
[2025-05-22T19:15:57.086+0000] {logging_mixin.py:190} INFO - 19:15:57  6 of 11 START sql incremental model sales.dim_mercadolivre_orders_status ....... [RUN]
[2025-05-22T19:15:57.242+0000] {logging_mixin.py:190} INFO - 19:15:57  3 of 11 ERROR creating sql incremental model sales.shopee_orders_results ....... [ERROR in 0.16s]
[2025-05-22T19:15:57.249+0000] {logging_mixin.py:190} INFO - 19:15:57  7 of 11 START sql incremental model sales.dim_mercadolivre_product ............. [RUN]
[2025-05-22T19:15:57.383+0000] {logging_mixin.py:190} INFO - 19:15:57  4 of 11 OK created sql incremental model sales.dim_mercadolivre_buyer .......... [MERGE 188 in 0.29s]
[2025-05-22T19:15:57.396+0000] {logging_mixin.py:190} INFO - 19:15:57  6 of 11 OK created sql incremental model sales.dim_mercadolivre_orders_status .. [MERGE 190 in 0.28s]
[2025-05-22T19:15:57.399+0000] {logging_mixin.py:190} INFO - 19:15:57  5 of 11 OK created sql incremental model sales.dim_mercadolivre_date ........... [MERGE 190 in 0.30s]
[2025-05-22T19:15:57.401+0000] {logging_mixin.py:190} INFO - 19:15:57  8 of 11 SKIP relation sales.dim_shopee_buyer ................................... [SKIP]
[2025-05-22T19:15:57.415+0000] {logging_mixin.py:190} INFO - 19:15:57  9 of 11 SKIP relation sales.dim_shopee_date .................................... [SKIP]
[2025-05-22T19:15:57.418+0000] {logging_mixin.py:190} INFO - 19:15:57  10 of 11 SKIP relation sales.dim_shopee_orders_status .......................... [SKIP]
[2025-05-22T19:15:57.419+0000] {logging_mixin.py:190} INFO - 19:15:57  11 of 11 SKIP relation sales.dim_shopee_product ................................ [SKIP]
[2025-05-22T19:15:57.462+0000] {logging_mixin.py:190} INFO - 19:15:57  7 of 11 OK created sql incremental model sales.dim_mercadolivre_product ........ [MERGE 186 in 0.19s]
[2025-05-22T19:15:57.487+0000] {logging_mixin.py:190} INFO - 19:15:57
[2025-05-22T19:15:57.489+0000] {logging_mixin.py:190} INFO - 19:15:57  Finished running 11 incremental models in 0 hours 0 minutes and 0.91 seconds (0.91s).
[2025-05-22T19:15:57.574+0000] {logging_mixin.py:190} INFO - 19:15:57
[2025-05-22T19:15:57.576+0000] {logging_mixin.py:190} INFO - 19:15:57  Completed with 1 error, 0 partial successes, and 0 warnings:
[2025-05-22T19:15:57.577+0000] {logging_mixin.py:190} INFO - 19:15:57
[2025-05-22T19:15:57.579+0000] {logging_mixin.py:190} INFO - 19:15:57    Database Error in model shopee_orders_results (models/core/shopee_orders_results.sql)
  syntax error at or near "AS"
  LINE 87: ...EXT), '_dbt_utils_surrogate_key_null_') as TEXT)) AS product...
                                                                ^
  compiled code at target/run/e_commerce_sales/models/core/shopee_orders_results.sql
[2025-05-22T19:15:57.581+0000] {logging_mixin.py:190} INFO - 19:15:57
[2025-05-22T19:15:57.582+0000] {logging_mixin.py:190} INFO - 19:15:57  Done. PASS=6 WARN=0 ERROR=1 SKIP=4 TOTAL=11
[2025-05-22T19:15:58.456+0000] {logging_mixin.py:190} INFO - dbt run failed!
[2025-05-22T19:15:58.460+0000] {logging_mixin.py:190} INFO - None
[2025-05-22T19:15:58.463+0000] {taskinstance.py:3311} ERROR - Task failed with exception
Traceback (most recent call last):
  File "/home/airflow/.local/lib/python3.9/site-packages/airflow/models/taskinstance.py", line 767, in _execute_task
    result = _execute_callable(context=context, **execute_callable_kwargs)
  File "/home/airflow/.local/lib/python3.9/site-packages/airflow/models/taskinstance.py", line 733, in _execute_callable
    return ExecutionCallableRunner(
  File "/home/airflow/.local/lib/python3.9/site-packages/airflow/utils/operator_helpers.py", line 252, in run
    return self.func(*args, **kwargs)
  File "/home/airflow/.local/lib/python3.9/site-packages/airflow/models/baseoperator.py", line 422, in wrapper
    return func(self, *args, **kwargs)
  File "/home/airflow/.local/lib/python3.9/site-packages/airflow/operators/python.py", line 238, in execute
    return_value = self.execute_callable()
  File "/home/airflow/.local/lib/python3.9/site-packages/airflow/operators/python.py", line 256, in execute_callable
    return runner.run(*self.op_args, **self.op_kwargs)
  File "/home/airflow/.local/lib/python3.9/site-packages/airflow/utils/operator_helpers.py", line 252, in run
    return self.func(*args, **kwargs)
  File "/opt/airflow/dbt/run_dbt.py", line 22, in transform_data
    raise RuntimeError("dbt run failed")
RuntimeError: dbt run failed
[2025-05-22T19:15:58.477+0000] {taskinstance.py:1225} INFO - Marking task as FAILED. dag_id=04_transform_data, task_id=run_dbt, run_id=manual__2025-05-22T19:15:43.081981+00:00, execution_date=20250522T191543, start_date=20250522T191552, end_date=20250522T191558
[2025-05-22T19:15:58.490+0000] {taskinstance.py:340} INFO - ::group::Post task execution logs
[2025-05-22T19:15:58.491+0000] {standard_task_runner.py:124} ERROR - Failed to execute job 216 for task run_dbt (dbt run failed; 3964)
Traceback (most recent call last):
  File "/home/airflow/.local/lib/python3.9/site-packages/airflow/task/task_runner/standard_task_runner.py", line 117, in _start_by_fork
    ret = args.func(args, dag=self.dag)
  File "/home/airflow/.local/lib/python3.9/site-packages/airflow/cli/cli_config.py", line 49, in command
    return func(*args, **kwargs)
  File "/home/airflow/.local/lib/python3.9/site-packages/airflow/utils/cli.py", line 116, in wrapper
    return f(*args, **kwargs)
  File "/home/airflow/.local/lib/python3.9/site-packages/airflow/cli/commands/task_command.py", line 483, in task_run
    task_return_code = _run_task_by_selected_method(args, _dag, ti)
  File "/home/airflow/.local/lib/python3.9/site-packages/airflow/cli/commands/task_command.py", line 256, in _run_task_by_selected_method
    return _run_raw_task(args, ti)
  File "/home/airflow/.local/lib/python3.9/site-packages/airflow/cli/commands/task_command.py", line 341, in _run_raw_task
    return ti._run_raw_task(
  File "/home/airflow/.local/lib/python3.9/site-packages/airflow/utils/session.py", line 97, in wrapper
    return func(*args, session=session, **kwargs)
  File "/home/airflow/.local/lib/python3.9/site-packages/airflow/models/taskinstance.py", line 3005, in _run_raw_task
    return _run_raw_task(
  File "/home/airflow/.local/lib/python3.9/site-packages/airflow/models/taskinstance.py", line 273, in _run_raw_task
    TaskInstance._execute_task_with_callbacks(
  File "/home/airflow/.local/lib/python3.9/site-packages/airflow/models/taskinstance.py", line 3159, in _execute_task_with_callbacks
    result = self._execute_task(context, task_orig)
  File "/home/airflow/.local/lib/python3.9/site-packages/airflow/models/taskinstance.py", line 3183, in _execute_task
    return _execute_task(self, context, task_orig)
  File "/home/airflow/.local/lib/python3.9/site-packages/airflow/models/taskinstance.py", line 767, in _execute_task
    result = _execute_callable(context=context, **execute_callable_kwargs)
  File "/home/airflow/.local/lib/python3.9/site-packages/airflow/models/taskinstance.py", line 733, in _execute_callable
    return ExecutionCallableRunner(
  File "/home/airflow/.local/lib/python3.9/site-packages/airflow/utils/operator_helpers.py", line 252, in run
    return self.func(*args, **kwargs)
  File "/home/airflow/.local/lib/python3.9/site-packages/airflow/models/baseoperator.py", line 422, in wrapper
    return func(self, *args, **kwargs)
  File "/home/airflow/.local/lib/python3.9/site-packages/airflow/operators/python.py", line 238, in execute
    return_value = self.execute_callable()
  File "/home/airflow/.local/lib/python3.9/site-packages/airflow/operators/python.py", line 256, in execute_callable
    return runner.run(*self.op_args, **self.op_kwargs)
  File "/home/airflow/.local/lib/python3.9/site-packages/airflow/utils/operator_helpers.py", line 252, in run
    return self.func(*args, **kwargs)
  File "/opt/airflow/dbt/run_dbt.py", line 22, in transform_data
    raise RuntimeError("dbt run failed")
RuntimeError: dbt run failed
[2025-05-22T19:15:58.541+0000] {local_task_job_runner.py:266} INFO - Task exited with return code 1
[2025-05-22T19:15:58.558+0000] {taskinstance.py:3895} INFO - 0 downstream tasks scheduled from follow-on schedule check
[2025-05-22T19:15:58.561+0000] {local_task_job_runner.py:245} INFO - ::endgroup::
