[2025-05-20T18:42:07.276+0000] {local_task_job_runner.py:123} INFO - ::group::Pre task execution logs
[2025-05-20T18:42:07.293+0000] {taskinstance.py:2613} INFO - Dependencies all met for dep_context=non-requeueable deps ti=<TaskInstance: 04_transform_data.run_dbt manual__2025-05-20T18:42:05.443691+00:00 [queued]>
[2025-05-20T18:42:07.300+0000] {taskinstance.py:2613} INFO - Dependencies all met for dep_context=requeueable deps ti=<TaskInstance: 04_transform_data.run_dbt manual__2025-05-20T18:42:05.443691+00:00 [queued]>
[2025-05-20T18:42:07.302+0000] {taskinstance.py:2866} INFO - Starting attempt 1 of 1
[2025-05-20T18:42:07.313+0000] {taskinstance.py:2889} INFO - Executing <Task(PythonOperator): run_dbt> on 2025-05-20 18:42:05.443691+00:00
[2025-05-20T18:42:07.319+0000] {standard_task_runner.py:72} INFO - Started process 3083 to run task
[2025-05-20T18:42:07.324+0000] {standard_task_runner.py:104} INFO - Running: ['***', 'tasks', 'run', '04_transform_data', 'run_dbt', 'manual__2025-05-20T18:42:05.443691+00:00', '--job-id', '34', '--raw', '--subdir', 'DAGS_FOLDER/04_transform_data.py', '--cfg-path', '/tmp/tmpmwpq5it8']
[2025-05-20T18:42:07.326+0000] {standard_task_runner.py:105} INFO - Job 34: Subtask run_dbt
[2025-05-20T18:42:07.384+0000] {task_command.py:467} INFO - Running <TaskInstance: 04_transform_data.run_dbt manual__2025-05-20T18:42:05.443691+00:00 [running]> on host e27e96d1841a
[2025-05-20T18:42:07.469+0000] {taskinstance.py:3132} INFO - Exporting env vars: AIRFLOW_CTX_DAG_OWNER='***' AIRFLOW_CTX_DAG_ID='04_transform_data' AIRFLOW_CTX_TASK_ID='run_dbt' AIRFLOW_CTX_EXECUTION_DATE='2025-05-20T18:42:05.443691+00:00' AIRFLOW_CTX_TRY_NUMBER='1' AIRFLOW_CTX_DAG_RUN_ID='manual__2025-05-20T18:42:05.443691+00:00'
[2025-05-20T18:42:07.471+0000] {taskinstance.py:731} INFO - ::endgroup::
[2025-05-20T18:42:09.048+0000] {logging_mixin.py:190} INFO - 18:42:09  Running with dbt=1.9.4
[2025-05-20T18:42:09.392+0000] {logging_mixin.py:190} INFO - 18:42:09  Registered adapter: postgres=1.9.0
[2025-05-20T18:42:10.502+0000] {logging_mixin.py:190} INFO - 18:42:10  [WARNING]: Configuration paths exist in your dbt_project.yml file which do not apply to any resources.
There are 1 unused configuration paths:
- models.e_commerce_sales.example
[2025-05-20T18:42:10.656+0000] {logging_mixin.py:190} INFO - 18:42:10  Found 6 models, 12 sources, 433 macros
[2025-05-20T18:42:10.660+0000] {logging_mixin.py:190} INFO - 18:42:10
[2025-05-20T18:42:10.662+0000] {logging_mixin.py:190} INFO - 18:42:10  Concurrency: 4 threads (target='dev')
[2025-05-20T18:42:10.663+0000] {logging_mixin.py:190} INFO - 18:42:10
[2025-05-20T18:42:10.779+0000] {logging_mixin.py:190} INFO - 18:42:10  1 of 6 START sql incremental model sales.mercadolivre_orders_results ........... [RUN]
[2025-05-20T18:42:10.781+0000] {logging_mixin.py:190} INFO - 18:42:10  2 of 6 START sql incremental model sales.shopee_new_id ......................... [RUN]
[2025-05-20T18:42:11.112+0000] {logging_mixin.py:190} INFO - 18:42:11  2 of 6 OK created sql incremental model sales.shopee_new_id .................... [MERGE 0 in 0.32s]
[2025-05-20T18:42:11.116+0000] {logging_mixin.py:190} INFO - 18:42:11  1 of 6 OK created sql incremental model sales.mercadolivre_orders_results ...... [MERGE 255 in 0.33s]
[2025-05-20T18:42:11.121+0000] {logging_mixin.py:190} INFO - 18:42:11  3 of 6 START sql incremental model sales.shopee_orders_results ................. [RUN]
[2025-05-20T18:42:11.125+0000] {logging_mixin.py:190} INFO - 18:42:11  4 of 6 START sql incremental model sales.mercadolivre_profits .................. [RUN]
[2025-05-20T18:42:11.209+0000] {logging_mixin.py:190} INFO - 18:42:11  3 of 6 ERROR creating sql incremental model sales.shopee_orders_results ........ [ERROR in 0.08s]
[2025-05-20T18:42:11.220+0000] {logging_mixin.py:190} INFO - 18:42:11  5 of 6 SKIP relation sales.dim_shopee_orders ................................... [SKIP]
[2025-05-20T18:42:11.222+0000] {logging_mixin.py:190} INFO - 18:42:11  6 of 6 SKIP relation sales.dim_shopee_product .................................. [SKIP]
[2025-05-20T18:42:11.257+0000] {logging_mixin.py:190} INFO - 18:42:11  4 of 6 OK created sql incremental model sales.mercadolivre_profits ............. [MERGE 250 in 0.13s]
[2025-05-20T18:42:11.280+0000] {logging_mixin.py:190} INFO - 18:42:11
[2025-05-20T18:42:11.282+0000] {logging_mixin.py:190} INFO - 18:42:11  Finished running 6 incremental models in 0 hours 0 minutes and 0.62 seconds (0.62s).
[2025-05-20T18:42:11.339+0000] {logging_mixin.py:190} INFO - 18:42:11
[2025-05-20T18:42:11.340+0000] {logging_mixin.py:190} INFO - 18:42:11  Completed with 1 error, 0 partial successes, and 0 warnings:
[2025-05-20T18:42:11.342+0000] {logging_mixin.py:190} INFO - 18:42:11
[2025-05-20T18:42:11.343+0000] {logging_mixin.py:190} INFO - 18:42:11    Database Error in model shopee_orders_results (models/core/shopee_orders_results.sql)
  missing FROM-clause entry for table "id_buyer_sku"
  LINE 61:         GROUP BY id_buyer_sku.id,
                            ^
  compiled code at target/run/e_commerce_sales/models/core/shopee_orders_results.sql
[2025-05-20T18:42:11.345+0000] {logging_mixin.py:190} INFO - 18:42:11
[2025-05-20T18:42:11.346+0000] {logging_mixin.py:190} INFO - 18:42:11  Done. PASS=3 WARN=0 ERROR=1 SKIP=2 TOTAL=6
[2025-05-20T18:42:12.070+0000] {logging_mixin.py:190} INFO - dbt run failed!
[2025-05-20T18:42:12.071+0000] {logging_mixin.py:190} INFO - None
[2025-05-20T18:42:12.072+0000] {taskinstance.py:3311} ERROR - Task failed with exception
Traceback (most recent call last):
  File "/home/airflow/.local/lib/python3.9/site-packages/airflow/models/taskinstance.py", line 767, in _execute_task
    result = _execute_callable(context=context, **execute_callable_kwargs)
  File "/home/airflow/.local/lib/python3.9/site-packages/airflow/models/taskinstance.py", line 733, in _execute_callable
    return ExecutionCallableRunner(
  File "/home/airflow/.local/lib/python3.9/site-packages/airflow/utils/operator_helpers.py", line 252, in run
    return self.func(*args, **kwargs)
  File "/home/airflow/.local/lib/python3.9/site-packages/airflow/models/baseoperator.py", line 422, in wrapper
    return func(self, *args, **kwargs)
  File "/home/airflow/.local/lib/python3.9/site-packages/airflow/operators/python.py", line 238, in execute
    return_value = self.execute_callable()
  File "/home/airflow/.local/lib/python3.9/site-packages/airflow/operators/python.py", line 256, in execute_callable
    return runner.run(*self.op_args, **self.op_kwargs)
  File "/home/airflow/.local/lib/python3.9/site-packages/airflow/utils/operator_helpers.py", line 252, in run
    return self.func(*args, **kwargs)
  File "/opt/airflow/dbt/run_dbt.py", line 22, in transform_data
    raise RuntimeError("dbt run failed")
RuntimeError: dbt run failed
[2025-05-20T18:42:12.082+0000] {taskinstance.py:1225} INFO - Marking task as FAILED. dag_id=04_transform_data, task_id=run_dbt, run_id=manual__2025-05-20T18:42:05.443691+00:00, execution_date=20250520T184205, start_date=20250520T184207, end_date=20250520T184212
[2025-05-20T18:42:12.094+0000] {taskinstance.py:340} INFO - ::group::Post task execution logs
[2025-05-20T18:42:12.095+0000] {standard_task_runner.py:124} ERROR - Failed to execute job 34 for task run_dbt (dbt run failed; 3083)
Traceback (most recent call last):
  File "/home/airflow/.local/lib/python3.9/site-packages/airflow/task/task_runner/standard_task_runner.py", line 117, in _start_by_fork
    ret = args.func(args, dag=self.dag)
  File "/home/airflow/.local/lib/python3.9/site-packages/airflow/cli/cli_config.py", line 49, in command
    return func(*args, **kwargs)
  File "/home/airflow/.local/lib/python3.9/site-packages/airflow/utils/cli.py", line 116, in wrapper
    return f(*args, **kwargs)
  File "/home/airflow/.local/lib/python3.9/site-packages/airflow/cli/commands/task_command.py", line 483, in task_run
    task_return_code = _run_task_by_selected_method(args, _dag, ti)
  File "/home/airflow/.local/lib/python3.9/site-packages/airflow/cli/commands/task_command.py", line 256, in _run_task_by_selected_method
    return _run_raw_task(args, ti)
  File "/home/airflow/.local/lib/python3.9/site-packages/airflow/cli/commands/task_command.py", line 341, in _run_raw_task
    return ti._run_raw_task(
  File "/home/airflow/.local/lib/python3.9/site-packages/airflow/utils/session.py", line 97, in wrapper
    return func(*args, session=session, **kwargs)
  File "/home/airflow/.local/lib/python3.9/site-packages/airflow/models/taskinstance.py", line 3005, in _run_raw_task
    return _run_raw_task(
  File "/home/airflow/.local/lib/python3.9/site-packages/airflow/models/taskinstance.py", line 273, in _run_raw_task
    TaskInstance._execute_task_with_callbacks(
  File "/home/airflow/.local/lib/python3.9/site-packages/airflow/models/taskinstance.py", line 3159, in _execute_task_with_callbacks
    result = self._execute_task(context, task_orig)
  File "/home/airflow/.local/lib/python3.9/site-packages/airflow/models/taskinstance.py", line 3183, in _execute_task
    return _execute_task(self, context, task_orig)
  File "/home/airflow/.local/lib/python3.9/site-packages/airflow/models/taskinstance.py", line 767, in _execute_task
    result = _execute_callable(context=context, **execute_callable_kwargs)
  File "/home/airflow/.local/lib/python3.9/site-packages/airflow/models/taskinstance.py", line 733, in _execute_callable
    return ExecutionCallableRunner(
  File "/home/airflow/.local/lib/python3.9/site-packages/airflow/utils/operator_helpers.py", line 252, in run
    return self.func(*args, **kwargs)
  File "/home/airflow/.local/lib/python3.9/site-packages/airflow/models/baseoperator.py", line 422, in wrapper
    return func(self, *args, **kwargs)
  File "/home/airflow/.local/lib/python3.9/site-packages/airflow/operators/python.py", line 238, in execute
    return_value = self.execute_callable()
  File "/home/airflow/.local/lib/python3.9/site-packages/airflow/operators/python.py", line 256, in execute_callable
    return runner.run(*self.op_args, **self.op_kwargs)
  File "/home/airflow/.local/lib/python3.9/site-packages/airflow/utils/operator_helpers.py", line 252, in run
    return self.func(*args, **kwargs)
  File "/opt/airflow/dbt/run_dbt.py", line 22, in transform_data
    raise RuntimeError("dbt run failed")
RuntimeError: dbt run failed
[2025-05-20T18:42:12.116+0000] {local_task_job_runner.py:266} INFO - Task exited with return code 1
[2025-05-20T18:42:12.134+0000] {taskinstance.py:3895} INFO - 0 downstream tasks scheduled from follow-on schedule check
[2025-05-20T18:42:12.137+0000] {local_task_job_runner.py:245} INFO - ::endgroup::
