[2025-06-09T22:26:52.333+0000] {local_task_job_runner.py:123} INFO - ::group::Pre task execution logs
[2025-06-09T22:26:52.351+0000] {taskinstance.py:2613} INFO - Dependencies all met for dep_context=non-requeueable deps ti=<TaskInstance: 05_transform_data.run_dbt manual__2025-06-09T22:26:43.070133+00:00 [queued]>
[2025-06-09T22:26:52.359+0000] {taskinstance.py:2613} INFO - Dependencies all met for dep_context=requeueable deps ti=<TaskInstance: 05_transform_data.run_dbt manual__2025-06-09T22:26:43.070133+00:00 [queued]>
[2025-06-09T22:26:52.361+0000] {taskinstance.py:2866} INFO - Starting attempt 1 of 1
[2025-06-09T22:26:52.373+0000] {taskinstance.py:2889} INFO - Executing <Task(PythonOperator): run_dbt> on 2025-06-09 22:26:43.070133+00:00
[2025-06-09T22:26:52.377+0000] {standard_task_runner.py:72} INFO - Started process 5973 to run task
[2025-06-09T22:26:52.380+0000] {standard_task_runner.py:104} INFO - Running: ['***', 'tasks', 'run', '05_transform_data', 'run_dbt', 'manual__2025-06-09T22:26:43.070133+00:00', '--job-id', '635', '--raw', '--subdir', 'DAGS_FOLDER/05_transform_data.py', '--cfg-path', '/tmp/tmp98pmy55v']
[2025-06-09T22:26:52.382+0000] {standard_task_runner.py:105} INFO - Job 635: Subtask run_dbt
[2025-06-09T22:26:52.432+0000] {task_command.py:467} INFO - Running <TaskInstance: 05_transform_data.run_dbt manual__2025-06-09T22:26:43.070133+00:00 [running]> on host 28e6a58e4107
[2025-06-09T22:26:52.529+0000] {taskinstance.py:3132} INFO - Exporting env vars: AIRFLOW_CTX_DAG_OWNER='***' AIRFLOW_CTX_DAG_ID='05_transform_data' AIRFLOW_CTX_TASK_ID='run_dbt' AIRFLOW_CTX_EXECUTION_DATE='2025-06-09T22:26:43.070133+00:00' AIRFLOW_CTX_TRY_NUMBER='1' AIRFLOW_CTX_DAG_RUN_ID='manual__2025-06-09T22:26:43.070133+00:00'
[2025-06-09T22:26:52.530+0000] {taskinstance.py:731} INFO - ::endgroup::
[2025-06-09T22:26:54.145+0000] {logging_mixin.py:190} INFO - 22:26:54  Running with dbt=1.9.5
[2025-06-09T22:26:54.546+0000] {logging_mixin.py:190} INFO - 22:26:54  Registered adapter: postgres=1.9.0
[2025-06-09T22:26:56.427+0000] {logging_mixin.py:190} INFO - 22:26:56  [WARNING]: Configuration paths exist in your dbt_project.yml file which do not apply to any resources.
There are 1 unused configuration paths:
- models.e_commerce_sales.example
[2025-06-09T22:26:56.639+0000] {logging_mixin.py:190} INFO - 22:26:56  Found 18 models, 12 sources, 549 macros, 1 unit test
[2025-06-09T22:26:56.644+0000] {logging_mixin.py:190} INFO - 22:26:56
[2025-06-09T22:26:56.645+0000] {logging_mixin.py:190} INFO - 22:26:56  Concurrency: 4 threads (target='dev')
[2025-06-09T22:26:56.646+0000] {logging_mixin.py:190} INFO - 22:26:56
[2025-06-09T22:26:56.820+0000] {logging_mixin.py:190} INFO - 22:26:56  1 of 18 START sql incremental model sales_stg.stg_mercadolivre ................. [RUN]
[2025-06-09T22:26:56.822+0000] {logging_mixin.py:190} INFO - 22:26:56  2 of 18 START sql incremental model sales_stg.stg_mercadolivre__order_items .... [RUN]
[2025-06-09T22:26:56.824+0000] {logging_mixin.py:190} INFO - 22:26:56  3 of 18 START sql incremental model sales_stg.stg_mercadolivre__payments ....... [RUN]
[2025-06-09T22:26:56.826+0000] {logging_mixin.py:190} INFO - 22:26:56  4 of 18 START sql incremental model sales_stg.stg_mercadolivre_sh .............. [RUN]
[2025-06-09T22:26:57.154+0000] {logging_mixin.py:190} INFO - 22:26:57  2 of 18 OK created sql incremental model sales_stg.stg_mercadolivre__order_items  [SELECT 415 in 0.32s]
[2025-06-09T22:26:57.158+0000] {logging_mixin.py:190} INFO - 22:26:57  3 of 18 OK created sql incremental model sales_stg.stg_mercadolivre__payments .. [SELECT 437 in 0.32s]
[2025-06-09T22:26:57.160+0000] {logging_mixin.py:190} INFO - 22:26:57  1 of 18 OK created sql incremental model sales_stg.stg_mercadolivre ............ [SELECT 415 in 0.33s]
[2025-06-09T22:26:57.207+0000] {logging_mixin.py:190} INFO - 22:26:57  5 of 18 START sql incremental model sales_stg.stg_shopee ....................... [RUN]
[2025-06-09T22:26:57.247+0000] {logging_mixin.py:190} INFO - 22:26:57  4 of 18 ERROR creating sql incremental model sales_stg.stg_mercadolivre_sh ..... [ERROR in 0.41s]
[2025-06-09T22:26:57.253+0000] {logging_mixin.py:190} INFO - 22:26:57  6 of 18 SKIP relation sales.mercadolivre_orders_results ........................ [SKIP]
[2025-06-09T22:26:57.259+0000] {logging_mixin.py:190} INFO - 22:26:57  7 of 18 SKIP relation sales.dim_mercadolivre_buyer ............................. [SKIP]
[2025-06-09T22:26:57.261+0000] {logging_mixin.py:190} INFO - 22:26:57  8 of 18 SKIP relation sales.dim_mercadolivre_date .............................. [SKIP]
[2025-06-09T22:26:57.262+0000] {logging_mixin.py:190} INFO - 22:26:57  9 of 18 SKIP relation sales.dim_mercadolivre_orders_status ..................... [SKIP]
[2025-06-09T22:26:57.268+0000] {logging_mixin.py:190} INFO - 22:26:57  10 of 18 SKIP relation sales.dim_mercadolivre_product .......................... [SKIP]
[2025-06-09T22:26:57.359+0000] {logging_mixin.py:190} INFO - 22:26:57  5 of 18 OK created sql incremental model sales_stg.stg_shopee .................. [MERGE 0 in 0.15s]
[2025-06-09T22:26:57.364+0000] {logging_mixin.py:190} INFO - 22:26:57  11 of 18 START sql incremental model sales.shopee_orders_results ............... [RUN]
[2025-06-09T22:26:57.490+0000] {logging_mixin.py:190} INFO - 22:26:57  11 of 18 OK created sql incremental model sales.shopee_orders_results .......... [MERGE 0 in 0.12s]
[2025-06-09T22:26:57.497+0000] {logging_mixin.py:190} INFO - 22:26:57  12 of 18 START sql incremental model sales.dim_shopee_buyer .................... [RUN]
[2025-06-09T22:26:57.498+0000] {logging_mixin.py:190} INFO - 22:26:57  13 of 18 START sql incremental model sales.dim_shopee_date ..................... [RUN]
[2025-06-09T22:26:57.500+0000] {logging_mixin.py:190} INFO - 22:26:57  14 of 18 START sql incremental model sales.dim_shopee_orders_status ............ [RUN]
[2025-06-09T22:26:57.502+0000] {logging_mixin.py:190} INFO - 22:26:57  15 of 18 START sql incremental model sales.dim_shopee_product .................. [RUN]
[2025-06-09T22:26:57.643+0000] {logging_mixin.py:190} INFO - 22:26:57  12 of 18 ERROR creating sql incremental model sales.dim_shopee_buyer ........... [ERROR in 0.14s]
[2025-06-09T22:26:57.750+0000] {logging_mixin.py:190} INFO - 22:26:57  15 of 18 OK created sql incremental model sales.dim_shopee_product ............. [MERGE 0 in 0.24s]
[2025-06-09T22:26:57.757+0000] {logging_mixin.py:190} INFO - 22:26:57  14 of 18 OK created sql incremental model sales.dim_shopee_orders_status ....... [MERGE 0 in 0.25s]
[2025-06-09T22:26:57.759+0000] {logging_mixin.py:190} INFO - 22:26:57  13 of 18 OK created sql incremental model sales.dim_shopee_date ................ [MERGE 0 in 0.25s]
[2025-06-09T22:26:57.767+0000] {logging_mixin.py:190} INFO - 22:26:57  16 of 18 START sql view model sales.sum_shopee_monthly_profit .................. [RUN]
[2025-06-09T22:26:57.768+0000] {logging_mixin.py:190} INFO - 22:26:57  17 of 18 START sql view model sales.sum_shopee_monthly_revenue ................. [RUN]
[2025-06-09T22:26:57.770+0000] {logging_mixin.py:190} INFO - 22:26:57  18 of 18 START sql view model sales.sum_shopee_products_sold ................... [RUN]
[2025-06-09T22:26:57.991+0000] {logging_mixin.py:190} INFO - 22:26:57  16 of 18 OK created sql view model sales.sum_shopee_monthly_profit ............. [CREATE VIEW in 0.22s]
[2025-06-09T22:26:57.993+0000] {logging_mixin.py:190} INFO - 22:26:57  17 of 18 OK created sql view model sales.sum_shopee_monthly_revenue ............ [CREATE VIEW in 0.22s]
[2025-06-09T22:26:57.995+0000] {logging_mixin.py:190} INFO - 22:26:57  18 of 18 OK created sql view model sales.sum_shopee_products_sold .............. [CREATE VIEW in 0.22s]
[2025-06-09T22:26:58.022+0000] {logging_mixin.py:190} INFO - 22:26:58
[2025-06-09T22:26:58.023+0000] {logging_mixin.py:190} INFO - 22:26:58  Finished running 15 incremental models, 3 view models in 0 hours 0 minutes and 1.37 seconds (1.37s).
[2025-06-09T22:26:58.100+0000] {logging_mixin.py:190} INFO - 22:26:58
[2025-06-09T22:26:58.101+0000] {logging_mixin.py:190} INFO - 22:26:58  Completed with 2 errors, 0 partial successes, and 0 warnings:
[2025-06-09T22:26:58.103+0000] {logging_mixin.py:190} INFO - 22:26:58
[2025-06-09T22:26:58.105+0000] {logging_mixin.py:190} INFO - 22:26:58    Database Error in model stg_mercadolivre_sh (models/staging/stg_mercadolivre_sh.sql)
  MERGE command cannot affect row a second time
  HINT:  Ensure that not more than one source row matches any one target row.
  compiled code at target/run/e_commerce_sales/models/staging/stg_mercadolivre_sh.sql
[2025-06-09T22:26:58.106+0000] {logging_mixin.py:190} INFO - 22:26:58
[2025-06-09T22:26:58.108+0000] {logging_mixin.py:190} INFO - 22:26:58    Database Error in model dim_shopee_buyer (models/core/dim_shopee_buyer.sql)
  relation "sales.stg_shopee" does not exist
  LINE 18:             FROM sales.stg_shopee                           ...
                            ^
  compiled code at target/run/e_commerce_sales/models/core/dim_shopee_buyer.sql
[2025-06-09T22:26:58.110+0000] {logging_mixin.py:190} INFO - 22:26:58
[2025-06-09T22:26:58.111+0000] {logging_mixin.py:190} INFO - 22:26:58  Done. PASS=11 WARN=0 ERROR=2 SKIP=5 TOTAL=18
[2025-06-09T22:26:58.971+0000] {logging_mixin.py:190} INFO - dbt run failed!
[2025-06-09T22:26:58.974+0000] {logging_mixin.py:190} INFO - None
[2025-06-09T22:26:58.977+0000] {taskinstance.py:3311} ERROR - Task failed with exception
Traceback (most recent call last):
  File "/home/airflow/.local/lib/python3.9/site-packages/airflow/models/taskinstance.py", line 767, in _execute_task
    result = _execute_callable(context=context, **execute_callable_kwargs)
  File "/home/airflow/.local/lib/python3.9/site-packages/airflow/models/taskinstance.py", line 733, in _execute_callable
    return ExecutionCallableRunner(
  File "/home/airflow/.local/lib/python3.9/site-packages/airflow/utils/operator_helpers.py", line 252, in run
    return self.func(*args, **kwargs)
  File "/home/airflow/.local/lib/python3.9/site-packages/airflow/models/baseoperator.py", line 422, in wrapper
    return func(self, *args, **kwargs)
  File "/home/airflow/.local/lib/python3.9/site-packages/airflow/operators/python.py", line 238, in execute
    return_value = self.execute_callable()
  File "/home/airflow/.local/lib/python3.9/site-packages/airflow/operators/python.py", line 256, in execute_callable
    return runner.run(*self.op_args, **self.op_kwargs)
  File "/home/airflow/.local/lib/python3.9/site-packages/airflow/utils/operator_helpers.py", line 252, in run
    return self.func(*args, **kwargs)
  File "/opt/airflow/dbt_files/run_dbt.py", line 22, in transform_data
    raise RuntimeError("dbt run failed")
RuntimeError: dbt run failed
[2025-06-09T22:26:58.991+0000] {taskinstance.py:1225} INFO - Marking task as FAILED. dag_id=05_transform_data, task_id=run_dbt, run_id=manual__2025-06-09T22:26:43.070133+00:00, execution_date=20250609T222643, start_date=20250609T222652, end_date=20250609T222658
[2025-06-09T22:26:59.003+0000] {taskinstance.py:340} INFO - ::group::Post task execution logs
[2025-06-09T22:26:59.005+0000] {standard_task_runner.py:124} ERROR - Failed to execute job 635 for task run_dbt (dbt run failed; 5973)
Traceback (most recent call last):
  File "/home/airflow/.local/lib/python3.9/site-packages/airflow/task/task_runner/standard_task_runner.py", line 117, in _start_by_fork
    ret = args.func(args, dag=self.dag)
  File "/home/airflow/.local/lib/python3.9/site-packages/airflow/cli/cli_config.py", line 49, in command
    return func(*args, **kwargs)
  File "/home/airflow/.local/lib/python3.9/site-packages/airflow/utils/cli.py", line 116, in wrapper
    return f(*args, **kwargs)
  File "/home/airflow/.local/lib/python3.9/site-packages/airflow/cli/commands/task_command.py", line 483, in task_run
    task_return_code = _run_task_by_selected_method(args, _dag, ti)
  File "/home/airflow/.local/lib/python3.9/site-packages/airflow/cli/commands/task_command.py", line 256, in _run_task_by_selected_method
    return _run_raw_task(args, ti)
  File "/home/airflow/.local/lib/python3.9/site-packages/airflow/cli/commands/task_command.py", line 341, in _run_raw_task
    return ti._run_raw_task(
  File "/home/airflow/.local/lib/python3.9/site-packages/airflow/utils/session.py", line 97, in wrapper
    return func(*args, session=session, **kwargs)
  File "/home/airflow/.local/lib/python3.9/site-packages/airflow/models/taskinstance.py", line 3005, in _run_raw_task
    return _run_raw_task(
  File "/home/airflow/.local/lib/python3.9/site-packages/airflow/models/taskinstance.py", line 273, in _run_raw_task
    TaskInstance._execute_task_with_callbacks(
  File "/home/airflow/.local/lib/python3.9/site-packages/airflow/models/taskinstance.py", line 3159, in _execute_task_with_callbacks
    result = self._execute_task(context, task_orig)
  File "/home/airflow/.local/lib/python3.9/site-packages/airflow/models/taskinstance.py", line 3183, in _execute_task
    return _execute_task(self, context, task_orig)
  File "/home/airflow/.local/lib/python3.9/site-packages/airflow/models/taskinstance.py", line 767, in _execute_task
    result = _execute_callable(context=context, **execute_callable_kwargs)
  File "/home/airflow/.local/lib/python3.9/site-packages/airflow/models/taskinstance.py", line 733, in _execute_callable
    return ExecutionCallableRunner(
  File "/home/airflow/.local/lib/python3.9/site-packages/airflow/utils/operator_helpers.py", line 252, in run
    return self.func(*args, **kwargs)
  File "/home/airflow/.local/lib/python3.9/site-packages/airflow/models/baseoperator.py", line 422, in wrapper
    return func(self, *args, **kwargs)
  File "/home/airflow/.local/lib/python3.9/site-packages/airflow/operators/python.py", line 238, in execute
    return_value = self.execute_callable()
  File "/home/airflow/.local/lib/python3.9/site-packages/airflow/operators/python.py", line 256, in execute_callable
    return runner.run(*self.op_args, **self.op_kwargs)
  File "/home/airflow/.local/lib/python3.9/site-packages/airflow/utils/operator_helpers.py", line 252, in run
    return self.func(*args, **kwargs)
  File "/opt/airflow/dbt_files/run_dbt.py", line 22, in transform_data
    raise RuntimeError("dbt run failed")
RuntimeError: dbt run failed
[2025-06-09T22:26:59.058+0000] {local_task_job_runner.py:266} INFO - Task exited with return code 1
[2025-06-09T22:26:59.103+0000] {taskinstance.py:3895} INFO - 0 downstream tasks scheduled from follow-on schedule check
[2025-06-09T22:26:59.106+0000] {local_task_job_runner.py:245} INFO - ::endgroup::
