[2025-05-22T14:21:49.524+0000] {local_task_job_runner.py:123} INFO - ::group::Pre task execution logs
[2025-05-22T14:21:49.542+0000] {taskinstance.py:2613} INFO - Dependencies all met for dep_context=non-requeueable deps ti=<TaskInstance: 04_transform_data.run_dbt manual__2025-05-22T14:21:48.594988+00:00 [queued]>
[2025-05-22T14:21:49.550+0000] {taskinstance.py:2613} INFO - Dependencies all met for dep_context=requeueable deps ti=<TaskInstance: 04_transform_data.run_dbt manual__2025-05-22T14:21:48.594988+00:00 [queued]>
[2025-05-22T14:21:49.553+0000] {taskinstance.py:2866} INFO - Starting attempt 1 of 1
[2025-05-22T14:21:49.566+0000] {taskinstance.py:2889} INFO - Executing <Task(PythonOperator): run_dbt> on 2025-05-22 14:21:48.594988+00:00
[2025-05-22T14:21:49.570+0000] {standard_task_runner.py:72} INFO - Started process 961 to run task
[2025-05-22T14:21:49.573+0000] {standard_task_runner.py:104} INFO - Running: ['***', 'tasks', 'run', '04_transform_data', 'run_dbt', 'manual__2025-05-22T14:21:48.594988+00:00', '--job-id', '179', '--raw', '--subdir', 'DAGS_FOLDER/04_transform_data.py', '--cfg-path', '/tmp/tmpp9ki070f']
[2025-05-22T14:21:49.575+0000] {standard_task_runner.py:105} INFO - Job 179: Subtask run_dbt
[2025-05-22T14:21:49.627+0000] {task_command.py:467} INFO - Running <TaskInstance: 04_transform_data.run_dbt manual__2025-05-22T14:21:48.594988+00:00 [running]> on host e27e96d1841a
[2025-05-22T14:21:49.711+0000] {taskinstance.py:3132} INFO - Exporting env vars: AIRFLOW_CTX_DAG_OWNER='***' AIRFLOW_CTX_DAG_ID='04_transform_data' AIRFLOW_CTX_TASK_ID='run_dbt' AIRFLOW_CTX_EXECUTION_DATE='2025-05-22T14:21:48.594988+00:00' AIRFLOW_CTX_TRY_NUMBER='1' AIRFLOW_CTX_DAG_RUN_ID='manual__2025-05-22T14:21:48.594988+00:00'
[2025-05-22T14:21:49.712+0000] {taskinstance.py:731} INFO - ::endgroup::
[2025-05-22T14:21:51.420+0000] {logging_mixin.py:190} INFO - 14:21:51  Running with dbt=1.9.4
[2025-05-22T14:21:51.874+0000] {logging_mixin.py:190} INFO - 14:21:51  Registered adapter: postgres=1.9.0
[2025-05-22T14:21:53.256+0000] {logging_mixin.py:190} INFO - 14:21:53  [WARNING]: Configuration paths exist in your dbt_project.yml file which do not apply to any resources.
There are 1 unused configuration paths:
- models.e_commerce_sales.example
[2025-05-22T14:21:53.429+0000] {logging_mixin.py:190} INFO - 14:21:53  Found 12 models, 12 sources, 433 macros
[2025-05-22T14:21:53.434+0000] {logging_mixin.py:190} INFO - 14:21:53
[2025-05-22T14:21:53.435+0000] {logging_mixin.py:190} INFO - 14:21:53  Concurrency: 4 threads (target='dev')
[2025-05-22T14:21:53.437+0000] {logging_mixin.py:190} INFO - 14:21:53
[2025-05-22T14:21:53.574+0000] {logging_mixin.py:190} INFO - 14:21:53  1 of 12 START sql incremental model sales.mercadolivre_orders_results .......... [RUN]
[2025-05-22T14:21:53.576+0000] {logging_mixin.py:190} INFO - 14:21:53  2 of 12 START sql incremental model sales.shopee_new_id ........................ [RUN]
[2025-05-22T14:21:53.819+0000] {logging_mixin.py:190} INFO - 14:21:53  1 of 12 ERROR creating sql incremental model sales.mercadolivre_orders_results . [ERROR in 0.23s]
[2025-05-22T14:21:53.841+0000] {logging_mixin.py:190} INFO - 14:21:53  3 of 12 SKIP relation sales.dim_mercadolivre_buyer ............................. [SKIP]
[2025-05-22T14:21:53.843+0000] {logging_mixin.py:190} INFO - 14:21:53  4 of 12 SKIP relation sales.dim_mercadolivre_date .............................. [SKIP]
[2025-05-22T14:21:53.845+0000] {logging_mixin.py:190} INFO - 14:21:53  5 of 12 SKIP relation sales.dim_mercadolivre_orders_status ..................... [SKIP]
[2025-05-22T14:21:53.856+0000] {logging_mixin.py:190} INFO - 14:21:53  6 of 12 SKIP relation sales.dim_mercadolivre_product ........................... [SKIP]
[2025-05-22T14:21:53.880+0000] {logging_mixin.py:190} INFO - 14:21:53  7 of 12 SKIP relation sales.mercadolivre_profits ............................... [SKIP]
[2025-05-22T14:21:53.951+0000] {logging_mixin.py:190} INFO - 14:21:53  2 of 12 OK created sql incremental model sales.shopee_new_id ................... [MERGE 0 in 0.37s]
[2025-05-22T14:21:53.958+0000] {logging_mixin.py:190} INFO - 14:21:53  8 of 12 START sql incremental model sales.shopee_orders_results ................ [RUN]
[2025-05-22T14:21:54.090+0000] {logging_mixin.py:190} INFO - 14:21:54  8 of 12 OK created sql incremental model sales.shopee_orders_results ........... [MERGE 0 in 0.13s]
[2025-05-22T14:21:54.099+0000] {logging_mixin.py:190} INFO - 14:21:54  9 of 12 START sql incremental model sales.dim_shopee_buyer_id .................. [RUN]
[2025-05-22T14:21:54.101+0000] {logging_mixin.py:190} INFO - 14:21:54  10 of 12 START sql incremental model sales.dim_shopee_date ..................... [RUN]
[2025-05-22T14:21:54.102+0000] {logging_mixin.py:190} INFO - 14:21:54  11 of 12 START sql incremental model sales.dim_shopee_orders_status ............ [RUN]
[2025-05-22T14:21:54.104+0000] {logging_mixin.py:190} INFO - 14:21:54  12 of 12 START sql incremental model sales.dim_shopee_product .................. [RUN]
[2025-05-22T14:21:54.397+0000] {logging_mixin.py:190} INFO - 14:21:54  9 of 12 OK created sql incremental model sales.dim_shopee_buyer_id ............. [MERGE 0 in 0.29s]
[2025-05-22T14:21:54.409+0000] {logging_mixin.py:190} INFO - 14:21:54  10 of 12 OK created sql incremental model sales.dim_shopee_date ................ [MERGE 0 in 0.30s]
[2025-05-22T14:21:54.414+0000] {logging_mixin.py:190} INFO - 14:21:54  12 of 12 OK created sql incremental model sales.dim_shopee_product ............. [MERGE 0 in 0.30s]
[2025-05-22T14:21:54.416+0000] {logging_mixin.py:190} INFO - 14:21:54  11 of 12 OK created sql incremental model sales.dim_shopee_orders_status ....... [MERGE 0 in 0.30s]
[2025-05-22T14:21:54.441+0000] {logging_mixin.py:190} INFO - 14:21:54
[2025-05-22T14:21:54.442+0000] {logging_mixin.py:190} INFO - 14:21:54  Finished running 12 incremental models in 0 hours 0 minutes and 1.00 seconds (1.00s).
[2025-05-22T14:21:54.508+0000] {logging_mixin.py:190} INFO - 14:21:54
[2025-05-22T14:21:54.509+0000] {logging_mixin.py:190} INFO - 14:21:54  Completed with 1 error, 0 partial successes, and 0 warnings:
[2025-05-22T14:21:54.511+0000] {logging_mixin.py:190} INFO - 14:21:54
[2025-05-22T14:21:54.512+0000] {logging_mixin.py:190} INFO - 14:21:54    Database Error in model mercadolivre_orders_results (models/core/mercadolivre_orders_results.sql)
  column orders.sku does not exist
  LINE 59:         orders.sku,
                   ^
  compiled code at target/run/e_commerce_sales/models/core/mercadolivre_orders_results.sql
[2025-05-22T14:21:54.514+0000] {logging_mixin.py:190} INFO - 14:21:54
[2025-05-22T14:21:54.515+0000] {logging_mixin.py:190} INFO - 14:21:54  Done. PASS=6 WARN=0 ERROR=1 SKIP=5 TOTAL=12
[2025-05-22T14:21:55.431+0000] {logging_mixin.py:190} INFO - dbt run failed!
[2025-05-22T14:21:55.432+0000] {logging_mixin.py:190} INFO - None
[2025-05-22T14:21:55.433+0000] {taskinstance.py:3311} ERROR - Task failed with exception
Traceback (most recent call last):
  File "/home/airflow/.local/lib/python3.9/site-packages/airflow/models/taskinstance.py", line 767, in _execute_task
    result = _execute_callable(context=context, **execute_callable_kwargs)
  File "/home/airflow/.local/lib/python3.9/site-packages/airflow/models/taskinstance.py", line 733, in _execute_callable
    return ExecutionCallableRunner(
  File "/home/airflow/.local/lib/python3.9/site-packages/airflow/utils/operator_helpers.py", line 252, in run
    return self.func(*args, **kwargs)
  File "/home/airflow/.local/lib/python3.9/site-packages/airflow/models/baseoperator.py", line 422, in wrapper
    return func(self, *args, **kwargs)
  File "/home/airflow/.local/lib/python3.9/site-packages/airflow/operators/python.py", line 238, in execute
    return_value = self.execute_callable()
  File "/home/airflow/.local/lib/python3.9/site-packages/airflow/operators/python.py", line 256, in execute_callable
    return runner.run(*self.op_args, **self.op_kwargs)
  File "/home/airflow/.local/lib/python3.9/site-packages/airflow/utils/operator_helpers.py", line 252, in run
    return self.func(*args, **kwargs)
  File "/opt/airflow/dbt/run_dbt.py", line 22, in transform_data
    raise RuntimeError("dbt run failed")
RuntimeError: dbt run failed
[2025-05-22T14:21:55.443+0000] {taskinstance.py:1225} INFO - Marking task as FAILED. dag_id=04_transform_data, task_id=run_dbt, run_id=manual__2025-05-22T14:21:48.594988+00:00, execution_date=20250522T142148, start_date=20250522T142149, end_date=20250522T142155
[2025-05-22T14:21:55.455+0000] {taskinstance.py:340} INFO - ::group::Post task execution logs
[2025-05-22T14:21:55.457+0000] {standard_task_runner.py:124} ERROR - Failed to execute job 179 for task run_dbt (dbt run failed; 961)
Traceback (most recent call last):
  File "/home/airflow/.local/lib/python3.9/site-packages/airflow/task/task_runner/standard_task_runner.py", line 117, in _start_by_fork
    ret = args.func(args, dag=self.dag)
  File "/home/airflow/.local/lib/python3.9/site-packages/airflow/cli/cli_config.py", line 49, in command
    return func(*args, **kwargs)
  File "/home/airflow/.local/lib/python3.9/site-packages/airflow/utils/cli.py", line 116, in wrapper
    return f(*args, **kwargs)
  File "/home/airflow/.local/lib/python3.9/site-packages/airflow/cli/commands/task_command.py", line 483, in task_run
    task_return_code = _run_task_by_selected_method(args, _dag, ti)
  File "/home/airflow/.local/lib/python3.9/site-packages/airflow/cli/commands/task_command.py", line 256, in _run_task_by_selected_method
    return _run_raw_task(args, ti)
  File "/home/airflow/.local/lib/python3.9/site-packages/airflow/cli/commands/task_command.py", line 341, in _run_raw_task
    return ti._run_raw_task(
  File "/home/airflow/.local/lib/python3.9/site-packages/airflow/utils/session.py", line 97, in wrapper
    return func(*args, session=session, **kwargs)
  File "/home/airflow/.local/lib/python3.9/site-packages/airflow/models/taskinstance.py", line 3005, in _run_raw_task
    return _run_raw_task(
  File "/home/airflow/.local/lib/python3.9/site-packages/airflow/models/taskinstance.py", line 273, in _run_raw_task
    TaskInstance._execute_task_with_callbacks(
  File "/home/airflow/.local/lib/python3.9/site-packages/airflow/models/taskinstance.py", line 3159, in _execute_task_with_callbacks
    result = self._execute_task(context, task_orig)
  File "/home/airflow/.local/lib/python3.9/site-packages/airflow/models/taskinstance.py", line 3183, in _execute_task
    return _execute_task(self, context, task_orig)
  File "/home/airflow/.local/lib/python3.9/site-packages/airflow/models/taskinstance.py", line 767, in _execute_task
    result = _execute_callable(context=context, **execute_callable_kwargs)
  File "/home/airflow/.local/lib/python3.9/site-packages/airflow/models/taskinstance.py", line 733, in _execute_callable
    return ExecutionCallableRunner(
  File "/home/airflow/.local/lib/python3.9/site-packages/airflow/utils/operator_helpers.py", line 252, in run
    return self.func(*args, **kwargs)
  File "/home/airflow/.local/lib/python3.9/site-packages/airflow/models/baseoperator.py", line 422, in wrapper
    return func(self, *args, **kwargs)
  File "/home/airflow/.local/lib/python3.9/site-packages/airflow/operators/python.py", line 238, in execute
    return_value = self.execute_callable()
  File "/home/airflow/.local/lib/python3.9/site-packages/airflow/operators/python.py", line 256, in execute_callable
    return runner.run(*self.op_args, **self.op_kwargs)
  File "/home/airflow/.local/lib/python3.9/site-packages/airflow/utils/operator_helpers.py", line 252, in run
    return self.func(*args, **kwargs)
  File "/opt/airflow/dbt/run_dbt.py", line 22, in transform_data
    raise RuntimeError("dbt run failed")
RuntimeError: dbt run failed
[2025-05-22T14:21:55.492+0000] {local_task_job_runner.py:266} INFO - Task exited with return code 1
[2025-05-22T14:21:55.509+0000] {taskinstance.py:3895} INFO - 0 downstream tasks scheduled from follow-on schedule check
[2025-05-22T14:21:55.512+0000] {local_task_job_runner.py:245} INFO - ::endgroup::
