[2025-05-21T17:27:05.580+0000] {local_task_job_runner.py:123} INFO - ::group::Pre task execution logs
[2025-05-21T17:27:05.600+0000] {taskinstance.py:2613} INFO - Dependencies all met for dep_context=non-requeueable deps ti=<TaskInstance: 04_transform_data.run_dbt manual__2025-05-21T17:27:03.155390+00:00 [queued]>
[2025-05-21T17:27:05.609+0000] {taskinstance.py:2613} INFO - Dependencies all met for dep_context=requeueable deps ti=<TaskInstance: 04_transform_data.run_dbt manual__2025-05-21T17:27:03.155390+00:00 [queued]>
[2025-05-21T17:27:05.611+0000] {taskinstance.py:2866} INFO - Starting attempt 1 of 1
[2025-05-21T17:27:05.623+0000] {taskinstance.py:2889} INFO - Executing <Task(PythonOperator): run_dbt> on 2025-05-21 17:27:03.155390+00:00
[2025-05-21T17:27:05.628+0000] {standard_task_runner.py:72} INFO - Started process 2318 to run task
[2025-05-21T17:27:05.631+0000] {standard_task_runner.py:104} INFO - Running: ['***', 'tasks', 'run', '04_transform_data', 'run_dbt', 'manual__2025-05-21T17:27:03.155390+00:00', '--job-id', '94', '--raw', '--subdir', 'DAGS_FOLDER/04_transform_data.py', '--cfg-path', '/tmp/tmp75cm9jpe']
[2025-05-21T17:27:05.633+0000] {standard_task_runner.py:105} INFO - Job 94: Subtask run_dbt
[2025-05-21T17:27:05.686+0000] {task_command.py:467} INFO - Running <TaskInstance: 04_transform_data.run_dbt manual__2025-05-21T17:27:03.155390+00:00 [running]> on host e27e96d1841a
[2025-05-21T17:27:05.773+0000] {taskinstance.py:3132} INFO - Exporting env vars: AIRFLOW_CTX_DAG_OWNER='***' AIRFLOW_CTX_DAG_ID='04_transform_data' AIRFLOW_CTX_TASK_ID='run_dbt' AIRFLOW_CTX_EXECUTION_DATE='2025-05-21T17:27:03.155390+00:00' AIRFLOW_CTX_TRY_NUMBER='1' AIRFLOW_CTX_DAG_RUN_ID='manual__2025-05-21T17:27:03.155390+00:00'
[2025-05-21T17:27:05.774+0000] {taskinstance.py:731} INFO - ::endgroup::
[2025-05-21T17:27:07.567+0000] {logging_mixin.py:190} INFO - 17:27:07  Running with dbt=1.9.4
[2025-05-21T17:27:07.933+0000] {logging_mixin.py:190} INFO - 17:27:07  Registered adapter: postgres=1.9.0
[2025-05-21T17:27:09.146+0000] {logging_mixin.py:190} INFO - 17:27:09  [WARNING]: Configuration paths exist in your dbt_project.yml file which do not apply to any resources.
There are 1 unused configuration paths:
- models.e_commerce_sales.example
[2025-05-21T17:27:09.327+0000] {logging_mixin.py:190} INFO - 17:27:09  Found 9 models, 12 sources, 433 macros
[2025-05-21T17:27:09.332+0000] {logging_mixin.py:190} INFO - 17:27:09
[2025-05-21T17:27:09.333+0000] {logging_mixin.py:190} INFO - 17:27:09  Concurrency: 4 threads (target='dev')
[2025-05-21T17:27:09.334+0000] {logging_mixin.py:190} INFO - 17:27:09
[2025-05-21T17:27:09.479+0000] {logging_mixin.py:190} INFO - 17:27:09  1 of 9 START sql incremental model sales.mercadolivre_orders_results ........... [RUN]
[2025-05-21T17:27:09.481+0000] {logging_mixin.py:190} INFO - 17:27:09  2 of 9 START sql incremental model sales.shopee_new_id ......................... [RUN]
[2025-05-21T17:27:09.771+0000] {logging_mixin.py:190} INFO - 17:27:09  1 of 9 OK created sql incremental model sales.mercadolivre_orders_results ...... [SELECT 255 in 0.28s]
[2025-05-21T17:27:09.780+0000] {logging_mixin.py:190} INFO - 17:27:09  3 of 9 START sql incremental model sales.dim_mercadolivre_product .............. [RUN]
[2025-05-21T17:27:09.782+0000] {logging_mixin.py:190} INFO - 17:27:09  4 of 9 START sql incremental model sales.mercadolivre_profits .................. [RUN]
[2025-05-21T17:27:09.902+0000] {logging_mixin.py:190} INFO - 17:27:09  2 of 9 OK created sql incremental model sales.shopee_new_id .................... [MERGE 0 in 0.41s]
[2025-05-21T17:27:09.910+0000] {logging_mixin.py:190} INFO - 17:27:09  5 of 9 START sql incremental model sales.shopee_orders_results ................. [RUN]
[2025-05-21T17:27:09.948+0000] {logging_mixin.py:190} INFO - 17:27:09  3 of 9 ERROR creating sql incremental model sales.dim_mercadolivre_product ..... [ERROR in 0.15s]
[2025-05-21T17:27:10.038+0000] {logging_mixin.py:190} INFO - 17:27:10  4 of 9 OK created sql incremental model sales.mercadolivre_profits ............. [MERGE 250 in 0.24s]
[2025-05-21T17:27:10.076+0000] {logging_mixin.py:190} INFO - 17:27:10  5 of 9 OK created sql incremental model sales.shopee_orders_results ............ [MERGE 0 in 0.16s]
[2025-05-21T17:27:10.083+0000] {logging_mixin.py:190} INFO - 17:27:10  6 of 9 START sql incremental model sales.dim_shopee_buyer_id ................... [RUN]
[2025-05-21T17:27:10.085+0000] {logging_mixin.py:190} INFO - 17:27:10  7 of 9 START sql incremental model sales.dim_shopee_orders ..................... [RUN]
[2025-05-21T17:27:10.087+0000] {logging_mixin.py:190} INFO - 17:27:10  8 of 9 START sql incremental model sales.dim_shopee_orders_status .............. [RUN]
[2025-05-21T17:27:10.089+0000] {logging_mixin.py:190} INFO - 17:27:10  9 of 9 START sql incremental model sales.dim_shopee_product .................... [RUN]
[2025-05-21T17:27:10.372+0000] {logging_mixin.py:190} INFO - 17:27:10  6 of 9 OK created sql incremental model sales.dim_shopee_buyer_id .............. [MERGE 0 in 0.28s]
[2025-05-21T17:27:10.386+0000] {logging_mixin.py:190} INFO - 17:27:10  9 of 9 OK created sql incremental model sales.dim_shopee_product ............... [MERGE 0 in 0.28s]
[2025-05-21T17:27:10.390+0000] {logging_mixin.py:190} INFO - 17:27:10  8 of 9 OK created sql incremental model sales.dim_shopee_orders_status ......... [MERGE 0 in 0.29s]
[2025-05-21T17:27:10.392+0000] {logging_mixin.py:190} INFO - 17:27:10  7 of 9 OK created sql incremental model sales.dim_shopee_orders ................ [MERGE 0 in 0.30s]
[2025-05-21T17:27:10.417+0000] {logging_mixin.py:190} INFO - 17:27:10
[2025-05-21T17:27:10.419+0000] {logging_mixin.py:190} INFO - 17:27:10  Finished running 9 incremental models in 0 hours 0 minutes and 1.08 seconds (1.08s).
[2025-05-21T17:27:10.485+0000] {logging_mixin.py:190} INFO - 17:27:10
[2025-05-21T17:27:10.487+0000] {logging_mixin.py:190} INFO - 17:27:10  Completed with 1 error, 0 partial successes, and 0 warnings:
[2025-05-21T17:27:10.488+0000] {logging_mixin.py:190} INFO - 17:27:10
[2025-05-21T17:27:10.490+0000] {logging_mixin.py:190} INFO - 17:27:10    Database Error in model dim_mercadolivre_product (models/core/dim_mercadolivre_product.sql)
  missing FROM-clause entry for table "orders_results"
  LINE 22:             ON orders_results.order_id = stg_mercadolivre__p...
                          ^
  compiled code at target/run/e_commerce_sales/models/core/dim_mercadolivre_product.sql
[2025-05-21T17:27:10.491+0000] {logging_mixin.py:190} INFO - 17:27:10
[2025-05-21T17:27:10.493+0000] {logging_mixin.py:190} INFO - 17:27:10  Done. PASS=8 WARN=0 ERROR=1 SKIP=0 TOTAL=9
[2025-05-21T17:27:11.388+0000] {logging_mixin.py:190} INFO - dbt run failed!
[2025-05-21T17:27:11.389+0000] {logging_mixin.py:190} INFO - None
[2025-05-21T17:27:11.389+0000] {taskinstance.py:3311} ERROR - Task failed with exception
Traceback (most recent call last):
  File "/home/airflow/.local/lib/python3.9/site-packages/airflow/models/taskinstance.py", line 767, in _execute_task
    result = _execute_callable(context=context, **execute_callable_kwargs)
  File "/home/airflow/.local/lib/python3.9/site-packages/airflow/models/taskinstance.py", line 733, in _execute_callable
    return ExecutionCallableRunner(
  File "/home/airflow/.local/lib/python3.9/site-packages/airflow/utils/operator_helpers.py", line 252, in run
    return self.func(*args, **kwargs)
  File "/home/airflow/.local/lib/python3.9/site-packages/airflow/models/baseoperator.py", line 422, in wrapper
    return func(self, *args, **kwargs)
  File "/home/airflow/.local/lib/python3.9/site-packages/airflow/operators/python.py", line 238, in execute
    return_value = self.execute_callable()
  File "/home/airflow/.local/lib/python3.9/site-packages/airflow/operators/python.py", line 256, in execute_callable
    return runner.run(*self.op_args, **self.op_kwargs)
  File "/home/airflow/.local/lib/python3.9/site-packages/airflow/utils/operator_helpers.py", line 252, in run
    return self.func(*args, **kwargs)
  File "/opt/airflow/dbt/run_dbt.py", line 22, in transform_data
    raise RuntimeError("dbt run failed")
RuntimeError: dbt run failed
[2025-05-21T17:27:11.401+0000] {taskinstance.py:1225} INFO - Marking task as FAILED. dag_id=04_transform_data, task_id=run_dbt, run_id=manual__2025-05-21T17:27:03.155390+00:00, execution_date=20250521T172703, start_date=20250521T172705, end_date=20250521T172711
[2025-05-21T17:27:11.412+0000] {taskinstance.py:340} INFO - ::group::Post task execution logs
[2025-05-21T17:27:11.414+0000] {standard_task_runner.py:124} ERROR - Failed to execute job 94 for task run_dbt (dbt run failed; 2318)
Traceback (most recent call last):
  File "/home/airflow/.local/lib/python3.9/site-packages/airflow/task/task_runner/standard_task_runner.py", line 117, in _start_by_fork
    ret = args.func(args, dag=self.dag)
  File "/home/airflow/.local/lib/python3.9/site-packages/airflow/cli/cli_config.py", line 49, in command
    return func(*args, **kwargs)
  File "/home/airflow/.local/lib/python3.9/site-packages/airflow/utils/cli.py", line 116, in wrapper
    return f(*args, **kwargs)
  File "/home/airflow/.local/lib/python3.9/site-packages/airflow/cli/commands/task_command.py", line 483, in task_run
    task_return_code = _run_task_by_selected_method(args, _dag, ti)
  File "/home/airflow/.local/lib/python3.9/site-packages/airflow/cli/commands/task_command.py", line 256, in _run_task_by_selected_method
    return _run_raw_task(args, ti)
  File "/home/airflow/.local/lib/python3.9/site-packages/airflow/cli/commands/task_command.py", line 341, in _run_raw_task
    return ti._run_raw_task(
  File "/home/airflow/.local/lib/python3.9/site-packages/airflow/utils/session.py", line 97, in wrapper
    return func(*args, session=session, **kwargs)
  File "/home/airflow/.local/lib/python3.9/site-packages/airflow/models/taskinstance.py", line 3005, in _run_raw_task
    return _run_raw_task(
  File "/home/airflow/.local/lib/python3.9/site-packages/airflow/models/taskinstance.py", line 273, in _run_raw_task
    TaskInstance._execute_task_with_callbacks(
  File "/home/airflow/.local/lib/python3.9/site-packages/airflow/models/taskinstance.py", line 3159, in _execute_task_with_callbacks
    result = self._execute_task(context, task_orig)
  File "/home/airflow/.local/lib/python3.9/site-packages/airflow/models/taskinstance.py", line 3183, in _execute_task
    return _execute_task(self, context, task_orig)
  File "/home/airflow/.local/lib/python3.9/site-packages/airflow/models/taskinstance.py", line 767, in _execute_task
    result = _execute_callable(context=context, **execute_callable_kwargs)
  File "/home/airflow/.local/lib/python3.9/site-packages/airflow/models/taskinstance.py", line 733, in _execute_callable
    return ExecutionCallableRunner(
  File "/home/airflow/.local/lib/python3.9/site-packages/airflow/utils/operator_helpers.py", line 252, in run
    return self.func(*args, **kwargs)
  File "/home/airflow/.local/lib/python3.9/site-packages/airflow/models/baseoperator.py", line 422, in wrapper
    return func(self, *args, **kwargs)
  File "/home/airflow/.local/lib/python3.9/site-packages/airflow/operators/python.py", line 238, in execute
    return_value = self.execute_callable()
  File "/home/airflow/.local/lib/python3.9/site-packages/airflow/operators/python.py", line 256, in execute_callable
    return runner.run(*self.op_args, **self.op_kwargs)
  File "/home/airflow/.local/lib/python3.9/site-packages/airflow/utils/operator_helpers.py", line 252, in run
    return self.func(*args, **kwargs)
  File "/opt/airflow/dbt/run_dbt.py", line 22, in transform_data
    raise RuntimeError("dbt run failed")
RuntimeError: dbt run failed
[2025-05-21T17:27:11.430+0000] {local_task_job_runner.py:266} INFO - Task exited with return code 1
[2025-05-21T17:27:11.447+0000] {taskinstance.py:3895} INFO - 0 downstream tasks scheduled from follow-on schedule check
[2025-05-21T17:27:11.450+0000] {local_task_job_runner.py:245} INFO - ::endgroup::
