[2025-06-11T23:31:15.039+0000] {local_task_job_runner.py:123} INFO - ::group::Pre task execution logs
[2025-06-11T23:31:15.062+0000] {taskinstance.py:2613} INFO - Dependencies all met for dep_context=non-requeueable deps ti=<TaskInstance: 05_transform_data_dev.run_dbt manual__2025-06-11T23:31:05.386075+00:00 [queued]>
[2025-06-11T23:31:15.075+0000] {taskinstance.py:2613} INFO - Dependencies all met for dep_context=requeueable deps ti=<TaskInstance: 05_transform_data_dev.run_dbt manual__2025-06-11T23:31:05.386075+00:00 [queued]>
[2025-06-11T23:31:15.076+0000] {taskinstance.py:2866} INFO - Starting attempt 1 of 1
[2025-06-11T23:31:15.092+0000] {taskinstance.py:2889} INFO - Executing <Task(PythonOperator): run_dbt> on 2025-06-11 23:31:05.386075+00:00
[2025-06-11T23:31:15.099+0000] {standard_task_runner.py:72} INFO - Started process 5354 to run task
[2025-06-11T23:31:15.103+0000] {standard_task_runner.py:104} INFO - Running: ['***', 'tasks', 'run', '05_transform_data_dev', 'run_dbt', 'manual__2025-06-11T23:31:05.386075+00:00', '--job-id', '942', '--raw', '--subdir', 'DAGS_FOLDER/05_transform_data_dev.py', '--cfg-path', '/tmp/tmpqg29d3k9']
[2025-06-11T23:31:15.105+0000] {standard_task_runner.py:105} INFO - Job 942: Subtask run_dbt
[2025-06-11T23:31:15.163+0000] {task_command.py:467} INFO - Running <TaskInstance: 05_transform_data_dev.run_dbt manual__2025-06-11T23:31:05.386075+00:00 [running]> on host 28e6a58e4107
[2025-06-11T23:31:15.242+0000] {taskinstance.py:3132} INFO - Exporting env vars: AIRFLOW_CTX_DAG_OWNER='***' AIRFLOW_CTX_DAG_ID='05_transform_data_dev' AIRFLOW_CTX_TASK_ID='run_dbt' AIRFLOW_CTX_EXECUTION_DATE='2025-06-11T23:31:05.386075+00:00' AIRFLOW_CTX_TRY_NUMBER='1' AIRFLOW_CTX_DAG_RUN_ID='manual__2025-06-11T23:31:05.386075+00:00'
[2025-06-11T23:31:15.244+0000] {taskinstance.py:731} INFO - ::endgroup::
[2025-06-11T23:31:16.823+0000] {logging_mixin.py:190} INFO - 23:31:16  Running with dbt=1.9.5
[2025-06-11T23:31:17.201+0000] {logging_mixin.py:190} INFO - 23:31:17  Registered adapter: postgres=1.9.0
[2025-06-11T23:31:19.568+0000] {logging_mixin.py:190} INFO - 23:31:19  [WARNING]: Configuration paths exist in your dbt_project.yml file which do not apply to any resources.
There are 1 unused configuration paths:
- models.e_commerce_sales.example
[2025-06-11T23:31:19.771+0000] {logging_mixin.py:190} INFO - 23:31:19  Found 21 models, 12 sources, 549 macros, 1 unit test
[2025-06-11T23:31:19.777+0000] {logging_mixin.py:190} INFO - 23:31:19
[2025-06-11T23:31:19.778+0000] {logging_mixin.py:190} INFO - 23:31:19  Concurrency: 4 threads (target='dev')
[2025-06-11T23:31:19.780+0000] {logging_mixin.py:190} INFO - 23:31:19
[2025-06-11T23:31:19.939+0000] {logging_mixin.py:190} INFO - 23:31:19  1 of 21 START sql incremental model sales_stg.stg_mercadolivre ................. [RUN]
[2025-06-11T23:31:19.940+0000] {logging_mixin.py:190} INFO - 23:31:19  2 of 21 START sql incremental model sales_stg.stg_mercadolivre__order_items .... [RUN]
[2025-06-11T23:31:19.942+0000] {logging_mixin.py:190} INFO - 23:31:19  3 of 21 START sql incremental model sales_stg.stg_mercadolivre__payments ....... [RUN]
[2025-06-11T23:31:19.943+0000] {logging_mixin.py:190} INFO - 23:31:19  4 of 21 START sql incremental model sales_stg.stg_mercadolivre_sh .............. [RUN]
[2025-06-11T23:31:20.256+0000] {logging_mixin.py:190} INFO - 23:31:20  1 of 21 OK created sql incremental model sales_stg.stg_mercadolivre ............ [SELECT 80 in 0.30s]
[2025-06-11T23:31:20.258+0000] {logging_mixin.py:190} INFO - 23:31:20  4 of 21 OK created sql incremental model sales_stg.stg_mercadolivre_sh ......... [SELECT 77 in 0.30s]
[2025-06-11T23:31:20.260+0000] {logging_mixin.py:190} INFO - 23:31:20  2 of 21 OK created sql incremental model sales_stg.stg_mercadolivre__order_items  [SELECT 80 in 0.31s]
[2025-06-11T23:31:20.262+0000] {logging_mixin.py:190} INFO - 23:31:20  3 of 21 OK created sql incremental model sales_stg.stg_mercadolivre__payments .. [SELECT 84 in 0.31s]
[2025-06-11T23:31:20.270+0000] {logging_mixin.py:190} INFO - 23:31:20  5 of 21 START sql incremental model sales_stg.stg_shopee ....................... [RUN]
[2025-06-11T23:31:20.273+0000] {logging_mixin.py:190} INFO - 23:31:20  6 of 21 START sql incremental model sales.mercadolivre_orders_results .......... [RUN]
[2025-06-11T23:31:20.354+0000] {logging_mixin.py:190} INFO - 23:31:20  6 of 21 ERROR creating sql incremental model sales.mercadolivre_orders_results . [ERROR in 0.08s]
[2025-06-11T23:31:20.358+0000] {logging_mixin.py:190} INFO - 23:31:20  5 of 21 OK created sql incremental model sales_stg.stg_shopee .................. [SELECT 248 in 0.08s]
[2025-06-11T23:31:20.364+0000] {logging_mixin.py:190} INFO - 23:31:20  7 of 21 SKIP relation sales.dim_mercadolivre_buyer ............................. [SKIP]
[2025-06-11T23:31:20.366+0000] {logging_mixin.py:190} INFO - 23:31:20  8 of 21 SKIP relation sales.dim_mercadolivre_date .............................. [SKIP]
[2025-06-11T23:31:20.367+0000] {logging_mixin.py:190} INFO - 23:31:20  9 of 21 SKIP relation sales.dim_mercadolivre_orders_status ..................... [SKIP]
[2025-06-11T23:31:20.372+0000] {logging_mixin.py:190} INFO - 23:31:20  10 of 21 SKIP relation sales.dim_mercadolivre_product .......................... [SKIP]
[2025-06-11T23:31:20.379+0000] {logging_mixin.py:190} INFO - 23:31:20  11 of 21 START sql incremental model sales.shopee_orders_results ............... [RUN]
[2025-06-11T23:31:20.381+0000] {logging_mixin.py:190} INFO - 23:31:20  12 of 21 SKIP relation sales.sum_mercadolivre_monthly_profit ................... [SKIP]
[2025-06-11T23:31:20.384+0000] {logging_mixin.py:190} INFO - 23:31:20  13 of 21 SKIP relation sales.sum_mercadolivre_monthly_revenue .................. [SKIP]
[2025-06-11T23:31:20.388+0000] {logging_mixin.py:190} INFO - 23:31:20  14 of 21 SKIP relation sales.sum_mercadolivre_monthly_sold ..................... [SKIP]
[2025-06-11T23:31:20.458+0000] {logging_mixin.py:190} INFO - 23:31:20  11 of 21 ERROR creating sql incremental model sales.shopee_orders_results ...... [ERROR in 0.07s]
[2025-06-11T23:31:20.467+0000] {logging_mixin.py:190} INFO - 23:31:20  15 of 21 SKIP relation sales.dim_shopee_buyer .................................. [SKIP]
[2025-06-11T23:31:20.468+0000] {logging_mixin.py:190} INFO - 23:31:20  16 of 21 SKIP relation sales.dim_shopee_date ................................... [SKIP]
[2025-06-11T23:31:20.470+0000] {logging_mixin.py:190} INFO - 23:31:20  17 of 21 SKIP relation sales.dim_shopee_orders_status .......................... [SKIP]
[2025-06-11T23:31:20.471+0000] {logging_mixin.py:190} INFO - 23:31:20  18 of 21 SKIP relation sales.dim_shopee_product ................................ [SKIP]
[2025-06-11T23:31:20.480+0000] {logging_mixin.py:190} INFO - 23:31:20  19 of 21 SKIP relation sales.sum_shopee_monthly_profit ......................... [SKIP]
[2025-06-11T23:31:20.482+0000] {logging_mixin.py:190} INFO - 23:31:20  20 of 21 SKIP relation sales.sum_shopee_monthly_revenue ........................ [SKIP]
[2025-06-11T23:31:20.484+0000] {logging_mixin.py:190} INFO - 23:31:20  21 of 21 SKIP relation sales.sum_shopee_products_sold .......................... [SKIP]
[2025-06-11T23:31:20.509+0000] {logging_mixin.py:190} INFO - 23:31:20
[2025-06-11T23:31:20.511+0000] {logging_mixin.py:190} INFO - 23:31:20  Finished running 15 incremental models, 6 view models in 0 hours 0 minutes and 0.73 seconds (0.73s).
[2025-06-11T23:31:20.588+0000] {logging_mixin.py:190} INFO - 23:31:20
[2025-06-11T23:31:20.591+0000] {logging_mixin.py:190} INFO - 23:31:20  Completed with 2 errors, 0 partial successes, and 0 warnings:
[2025-06-11T23:31:20.594+0000] {logging_mixin.py:190} INFO - 23:31:20
[2025-06-11T23:31:20.597+0000] {logging_mixin.py:190} INFO - 23:31:20    Database Error in model mercadolivre_orders_results (models/core/mercadolivre_orders_results.sql)
  relation "supplies.kit_components" does not exist
  LINE 78:  FROM "dev_sales_db"."supplies"."kit_components" AS kit, 
                 ^
  compiled code at target/run/e_commerce_sales/models/core/mercadolivre_orders_results.sql
[2025-06-11T23:31:20.600+0000] {logging_mixin.py:190} INFO - 23:31:20
[2025-06-11T23:31:20.602+0000] {logging_mixin.py:190} INFO - 23:31:20    Database Error in model shopee_orders_results (models/core/shopee_orders_results.sql)
  relation "supplies.kit_components" does not exist
  LINE 40:         LEFT JOIN "dev_sales_db"."supplies"."kit_components"...
                             ^
  compiled code at target/run/e_commerce_sales/models/core/shopee_orders_results.sql
[2025-06-11T23:31:20.604+0000] {logging_mixin.py:190} INFO - 23:31:20
[2025-06-11T23:31:20.606+0000] {logging_mixin.py:190} INFO - 23:31:20  Done. PASS=5 WARN=0 ERROR=2 SKIP=14 TOTAL=21
[2025-06-11T23:31:21.442+0000] {logging_mixin.py:190} INFO - dbt run failed!
[2025-06-11T23:31:21.443+0000] {logging_mixin.py:190} INFO - None
[2025-06-11T23:31:21.444+0000] {taskinstance.py:3311} ERROR - Task failed with exception
Traceback (most recent call last):
  File "/home/airflow/.local/lib/python3.9/site-packages/airflow/models/taskinstance.py", line 767, in _execute_task
    result = _execute_callable(context=context, **execute_callable_kwargs)
  File "/home/airflow/.local/lib/python3.9/site-packages/airflow/models/taskinstance.py", line 733, in _execute_callable
    return ExecutionCallableRunner(
  File "/home/airflow/.local/lib/python3.9/site-packages/airflow/utils/operator_helpers.py", line 252, in run
    return self.func(*args, **kwargs)
  File "/home/airflow/.local/lib/python3.9/site-packages/airflow/models/baseoperator.py", line 422, in wrapper
    return func(self, *args, **kwargs)
  File "/home/airflow/.local/lib/python3.9/site-packages/airflow/operators/python.py", line 238, in execute
    return_value = self.execute_callable()
  File "/home/airflow/.local/lib/python3.9/site-packages/airflow/operators/python.py", line 256, in execute_callable
    return runner.run(*self.op_args, **self.op_kwargs)
  File "/home/airflow/.local/lib/python3.9/site-packages/airflow/utils/operator_helpers.py", line 252, in run
    return self.func(*args, **kwargs)
  File "/opt/airflow/dbt_files/run_dbt.py", line 24, in transform_data
    raise RuntimeError("dbt run failed")
RuntimeError: dbt run failed
[2025-06-11T23:31:21.456+0000] {taskinstance.py:1225} INFO - Marking task as FAILED. dag_id=05_transform_data_dev, task_id=run_dbt, run_id=manual__2025-06-11T23:31:05.386075+00:00, execution_date=20250611T233105, start_date=20250611T233115, end_date=20250611T233121
[2025-06-11T23:31:21.468+0000] {taskinstance.py:340} INFO - ::group::Post task execution logs
[2025-06-11T23:31:21.469+0000] {standard_task_runner.py:124} ERROR - Failed to execute job 942 for task run_dbt (dbt run failed; 5354)
Traceback (most recent call last):
  File "/home/airflow/.local/lib/python3.9/site-packages/airflow/task/task_runner/standard_task_runner.py", line 117, in _start_by_fork
    ret = args.func(args, dag=self.dag)
  File "/home/airflow/.local/lib/python3.9/site-packages/airflow/cli/cli_config.py", line 49, in command
    return func(*args, **kwargs)
  File "/home/airflow/.local/lib/python3.9/site-packages/airflow/utils/cli.py", line 116, in wrapper
    return f(*args, **kwargs)
  File "/home/airflow/.local/lib/python3.9/site-packages/airflow/cli/commands/task_command.py", line 483, in task_run
    task_return_code = _run_task_by_selected_method(args, _dag, ti)
  File "/home/airflow/.local/lib/python3.9/site-packages/airflow/cli/commands/task_command.py", line 256, in _run_task_by_selected_method
    return _run_raw_task(args, ti)
  File "/home/airflow/.local/lib/python3.9/site-packages/airflow/cli/commands/task_command.py", line 341, in _run_raw_task
    return ti._run_raw_task(
  File "/home/airflow/.local/lib/python3.9/site-packages/airflow/utils/session.py", line 97, in wrapper
    return func(*args, session=session, **kwargs)
  File "/home/airflow/.local/lib/python3.9/site-packages/airflow/models/taskinstance.py", line 3005, in _run_raw_task
    return _run_raw_task(
  File "/home/airflow/.local/lib/python3.9/site-packages/airflow/models/taskinstance.py", line 273, in _run_raw_task
    TaskInstance._execute_task_with_callbacks(
  File "/home/airflow/.local/lib/python3.9/site-packages/airflow/models/taskinstance.py", line 3159, in _execute_task_with_callbacks
    result = self._execute_task(context, task_orig)
  File "/home/airflow/.local/lib/python3.9/site-packages/airflow/models/taskinstance.py", line 3183, in _execute_task
    return _execute_task(self, context, task_orig)
  File "/home/airflow/.local/lib/python3.9/site-packages/airflow/models/taskinstance.py", line 767, in _execute_task
    result = _execute_callable(context=context, **execute_callable_kwargs)
  File "/home/airflow/.local/lib/python3.9/site-packages/airflow/models/taskinstance.py", line 733, in _execute_callable
    return ExecutionCallableRunner(
  File "/home/airflow/.local/lib/python3.9/site-packages/airflow/utils/operator_helpers.py", line 252, in run
    return self.func(*args, **kwargs)
  File "/home/airflow/.local/lib/python3.9/site-packages/airflow/models/baseoperator.py", line 422, in wrapper
    return func(self, *args, **kwargs)
  File "/home/airflow/.local/lib/python3.9/site-packages/airflow/operators/python.py", line 238, in execute
    return_value = self.execute_callable()
  File "/home/airflow/.local/lib/python3.9/site-packages/airflow/operators/python.py", line 256, in execute_callable
    return runner.run(*self.op_args, **self.op_kwargs)
  File "/home/airflow/.local/lib/python3.9/site-packages/airflow/utils/operator_helpers.py", line 252, in run
    return self.func(*args, **kwargs)
  File "/opt/airflow/dbt_files/run_dbt.py", line 24, in transform_data
    raise RuntimeError("dbt run failed")
RuntimeError: dbt run failed
[2025-06-11T23:31:21.501+0000] {local_task_job_runner.py:266} INFO - Task exited with return code 1
[2025-06-11T23:31:21.520+0000] {taskinstance.py:3895} INFO - 0 downstream tasks scheduled from follow-on schedule check
[2025-06-11T23:31:21.523+0000] {local_task_job_runner.py:245} INFO - ::endgroup::
