[2025-05-22T19:14:05.282+0000] {local_task_job_runner.py:123} INFO - ::group::Pre task execution logs
[2025-05-22T19:14:05.302+0000] {taskinstance.py:2613} INFO - Dependencies all met for dep_context=non-requeueable deps ti=<TaskInstance: 04_transform_data.run_dbt manual__2025-05-22T19:13:55.444797+00:00 [queued]>
[2025-05-22T19:14:05.311+0000] {taskinstance.py:2613} INFO - Dependencies all met for dep_context=requeueable deps ti=<TaskInstance: 04_transform_data.run_dbt manual__2025-05-22T19:13:55.444797+00:00 [queued]>
[2025-05-22T19:14:05.312+0000] {taskinstance.py:2866} INFO - Starting attempt 1 of 1
[2025-05-22T19:14:05.325+0000] {taskinstance.py:2889} INFO - Executing <Task(PythonOperator): run_dbt> on 2025-05-22 19:13:55.444797+00:00
[2025-05-22T19:14:05.330+0000] {standard_task_runner.py:72} INFO - Started process 3927 to run task
[2025-05-22T19:14:05.334+0000] {standard_task_runner.py:104} INFO - Running: ['***', 'tasks', 'run', '04_transform_data', 'run_dbt', 'manual__2025-05-22T19:13:55.444797+00:00', '--job-id', '214', '--raw', '--subdir', 'DAGS_FOLDER/04_transform_data.py', '--cfg-path', '/tmp/tmp7rs9u7mt']
[2025-05-22T19:14:05.335+0000] {standard_task_runner.py:105} INFO - Job 214: Subtask run_dbt
[2025-05-22T19:14:05.388+0000] {task_command.py:467} INFO - Running <TaskInstance: 04_transform_data.run_dbt manual__2025-05-22T19:13:55.444797+00:00 [running]> on host e27e96d1841a
[2025-05-22T19:14:05.481+0000] {taskinstance.py:3132} INFO - Exporting env vars: AIRFLOW_CTX_DAG_OWNER='***' AIRFLOW_CTX_DAG_ID='04_transform_data' AIRFLOW_CTX_TASK_ID='run_dbt' AIRFLOW_CTX_EXECUTION_DATE='2025-05-22T19:13:55.444797+00:00' AIRFLOW_CTX_TRY_NUMBER='1' AIRFLOW_CTX_DAG_RUN_ID='manual__2025-05-22T19:13:55.444797+00:00'
[2025-05-22T19:14:05.482+0000] {taskinstance.py:731} INFO - ::endgroup::
[2025-05-22T19:14:07.180+0000] {logging_mixin.py:190} INFO - 19:14:07  Running with dbt=1.9.4
[2025-05-22T19:14:07.535+0000] {logging_mixin.py:190} INFO - 19:14:07  Registered adapter: postgres=1.9.0
[2025-05-22T19:14:09.399+0000] {logging_mixin.py:190} INFO - 19:14:09  [WARNING]: Configuration paths exist in your dbt_project.yml file which do not apply to any resources.
There are 1 unused configuration paths:
- models.e_commerce_sales.example
[2025-05-22T19:14:09.578+0000] {logging_mixin.py:190} INFO - 19:14:09  Found 11 models, 12 sources, 549 macros
[2025-05-22T19:14:09.583+0000] {logging_mixin.py:190} INFO - 19:14:09
[2025-05-22T19:14:09.584+0000] {logging_mixin.py:190} INFO - 19:14:09  Concurrency: 4 threads (target='dev')
[2025-05-22T19:14:09.586+0000] {logging_mixin.py:190} INFO - 19:14:09
[2025-05-22T19:14:09.708+0000] {logging_mixin.py:190} INFO - 19:14:09  1 of 11 START sql incremental model sales.mercadolivre_orders_results .......... [RUN]
[2025-05-22T19:14:09.710+0000] {logging_mixin.py:190} INFO - 19:14:09  2 of 11 START sql incremental model sales.shopee_new_id ........................ [RUN]
[2025-05-22T19:14:10.017+0000] {logging_mixin.py:190} INFO - 19:14:10  1 of 11 OK created sql incremental model sales.mercadolivre_orders_results ..... [SELECT 190 in 0.30s]
[2025-05-22T19:14:10.026+0000] {logging_mixin.py:190} INFO - 19:14:10  3 of 11 START sql incremental model sales.dim_mercadolivre_buyer ............... [RUN]
[2025-05-22T19:14:10.028+0000] {logging_mixin.py:190} INFO - 19:14:10  4 of 11 START sql incremental model sales.dim_mercadolivre_date ................ [RUN]
[2025-05-22T19:14:10.030+0000] {logging_mixin.py:190} INFO - 19:14:10  5 of 11 START sql incremental model sales.dim_mercadolivre_orders_status ....... [RUN]
[2025-05-22T19:14:10.107+0000] {logging_mixin.py:190} INFO - 19:14:10  2 of 11 OK created sql incremental model sales.shopee_new_id ................... [MERGE 0 in 0.37s]
[2025-05-22T19:14:10.117+0000] {logging_mixin.py:190} INFO - 19:14:10  6 of 11 START sql incremental model sales.dim_mercadolivre_product ............. [RUN]
[2025-05-22T19:14:10.191+0000] {logging_mixin.py:190} INFO - 19:14:10  5 of 11 OK created sql incremental model sales.dim_mercadolivre_orders_status .. [SELECT 190 in 0.15s]
[2025-05-22T19:14:10.195+0000] {logging_mixin.py:190} INFO - 19:14:10  3 of 11 OK created sql incremental model sales.dim_mercadolivre_buyer .......... [SELECT 188 in 0.16s]
[2025-05-22T19:14:10.199+0000] {logging_mixin.py:190} INFO - 19:14:10  4 of 11 OK created sql incremental model sales.dim_mercadolivre_date ........... [SELECT 190 in 0.16s]
[2025-05-22T19:14:10.205+0000] {logging_mixin.py:190} INFO - 19:14:10  7 of 11 START sql incremental model sales.shopee_orders_results ................ [RUN]
[2025-05-22T19:14:10.247+0000] {logging_mixin.py:190} INFO - 19:14:10  6 of 11 OK created sql incremental model sales.dim_mercadolivre_product ........ [SELECT 186 in 0.12s]
[2025-05-22T19:14:10.275+0000] {logging_mixin.py:190} INFO - 19:14:10  7 of 11 ERROR creating sql incremental model sales.shopee_orders_results ....... [ERROR in 0.07s]
[2025-05-22T19:14:10.283+0000] {logging_mixin.py:190} INFO - 19:14:10  8 of 11 SKIP relation sales.dim_shopee_buyer ................................... [SKIP]
[2025-05-22T19:14:10.285+0000] {logging_mixin.py:190} INFO - 19:14:10  9 of 11 SKIP relation sales.dim_shopee_date .................................... [SKIP]
[2025-05-22T19:14:10.287+0000] {logging_mixin.py:190} INFO - 19:14:10  10 of 11 SKIP relation sales.dim_shopee_orders_status .......................... [SKIP]
[2025-05-22T19:14:10.288+0000] {logging_mixin.py:190} INFO - 19:14:10  11 of 11 SKIP relation sales.dim_shopee_product ................................ [SKIP]
[2025-05-22T19:14:10.316+0000] {logging_mixin.py:190} INFO - 19:14:10
[2025-05-22T19:14:10.318+0000] {logging_mixin.py:190} INFO - 19:14:10  Finished running 11 incremental models in 0 hours 0 minutes and 0.73 seconds (0.73s).
[2025-05-22T19:14:10.399+0000] {logging_mixin.py:190} INFO - 19:14:10
[2025-05-22T19:14:10.401+0000] {logging_mixin.py:190} INFO - 19:14:10  Completed with 1 error, 0 partial successes, and 0 warnings:
[2025-05-22T19:14:10.402+0000] {logging_mixin.py:190} INFO - 19:14:10
[2025-05-22T19:14:10.404+0000] {logging_mixin.py:190} INFO - 19:14:10    Database Error in model shopee_orders_results (models/core/shopee_orders_results.sql)
  syntax error at or near "AS"
  LINE 87: ...EXT), '_dbt_utils_surrogate_key_null_') as TEXT)) AS product...
                                                                ^
  compiled code at target/run/e_commerce_sales/models/core/shopee_orders_results.sql
[2025-05-22T19:14:10.405+0000] {logging_mixin.py:190} INFO - 19:14:10
[2025-05-22T19:14:10.407+0000] {logging_mixin.py:190} INFO - 19:14:10  Done. PASS=6 WARN=0 ERROR=1 SKIP=4 TOTAL=11
[2025-05-22T19:14:11.277+0000] {logging_mixin.py:190} INFO - dbt run failed!
[2025-05-22T19:14:11.278+0000] {logging_mixin.py:190} INFO - None
[2025-05-22T19:14:11.280+0000] {taskinstance.py:3311} ERROR - Task failed with exception
Traceback (most recent call last):
  File "/home/airflow/.local/lib/python3.9/site-packages/airflow/models/taskinstance.py", line 767, in _execute_task
    result = _execute_callable(context=context, **execute_callable_kwargs)
  File "/home/airflow/.local/lib/python3.9/site-packages/airflow/models/taskinstance.py", line 733, in _execute_callable
    return ExecutionCallableRunner(
  File "/home/airflow/.local/lib/python3.9/site-packages/airflow/utils/operator_helpers.py", line 252, in run
    return self.func(*args, **kwargs)
  File "/home/airflow/.local/lib/python3.9/site-packages/airflow/models/baseoperator.py", line 422, in wrapper
    return func(self, *args, **kwargs)
  File "/home/airflow/.local/lib/python3.9/site-packages/airflow/operators/python.py", line 238, in execute
    return_value = self.execute_callable()
  File "/home/airflow/.local/lib/python3.9/site-packages/airflow/operators/python.py", line 256, in execute_callable
    return runner.run(*self.op_args, **self.op_kwargs)
  File "/home/airflow/.local/lib/python3.9/site-packages/airflow/utils/operator_helpers.py", line 252, in run
    return self.func(*args, **kwargs)
  File "/opt/airflow/dbt/run_dbt.py", line 22, in transform_data
    raise RuntimeError("dbt run failed")
RuntimeError: dbt run failed
[2025-05-22T19:14:11.294+0000] {taskinstance.py:1225} INFO - Marking task as FAILED. dag_id=04_transform_data, task_id=run_dbt, run_id=manual__2025-05-22T19:13:55.444797+00:00, execution_date=20250522T191355, start_date=20250522T191405, end_date=20250522T191411
[2025-05-22T19:14:11.308+0000] {taskinstance.py:340} INFO - ::group::Post task execution logs
[2025-05-22T19:14:11.310+0000] {standard_task_runner.py:124} ERROR - Failed to execute job 214 for task run_dbt (dbt run failed; 3927)
Traceback (most recent call last):
  File "/home/airflow/.local/lib/python3.9/site-packages/airflow/task/task_runner/standard_task_runner.py", line 117, in _start_by_fork
    ret = args.func(args, dag=self.dag)
  File "/home/airflow/.local/lib/python3.9/site-packages/airflow/cli/cli_config.py", line 49, in command
    return func(*args, **kwargs)
  File "/home/airflow/.local/lib/python3.9/site-packages/airflow/utils/cli.py", line 116, in wrapper
    return f(*args, **kwargs)
  File "/home/airflow/.local/lib/python3.9/site-packages/airflow/cli/commands/task_command.py", line 483, in task_run
    task_return_code = _run_task_by_selected_method(args, _dag, ti)
  File "/home/airflow/.local/lib/python3.9/site-packages/airflow/cli/commands/task_command.py", line 256, in _run_task_by_selected_method
    return _run_raw_task(args, ti)
  File "/home/airflow/.local/lib/python3.9/site-packages/airflow/cli/commands/task_command.py", line 341, in _run_raw_task
    return ti._run_raw_task(
  File "/home/airflow/.local/lib/python3.9/site-packages/airflow/utils/session.py", line 97, in wrapper
    return func(*args, session=session, **kwargs)
  File "/home/airflow/.local/lib/python3.9/site-packages/airflow/models/taskinstance.py", line 3005, in _run_raw_task
    return _run_raw_task(
  File "/home/airflow/.local/lib/python3.9/site-packages/airflow/models/taskinstance.py", line 273, in _run_raw_task
    TaskInstance._execute_task_with_callbacks(
  File "/home/airflow/.local/lib/python3.9/site-packages/airflow/models/taskinstance.py", line 3159, in _execute_task_with_callbacks
    result = self._execute_task(context, task_orig)
  File "/home/airflow/.local/lib/python3.9/site-packages/airflow/models/taskinstance.py", line 3183, in _execute_task
    return _execute_task(self, context, task_orig)
  File "/home/airflow/.local/lib/python3.9/site-packages/airflow/models/taskinstance.py", line 767, in _execute_task
    result = _execute_callable(context=context, **execute_callable_kwargs)
  File "/home/airflow/.local/lib/python3.9/site-packages/airflow/models/taskinstance.py", line 733, in _execute_callable
    return ExecutionCallableRunner(
  File "/home/airflow/.local/lib/python3.9/site-packages/airflow/utils/operator_helpers.py", line 252, in run
    return self.func(*args, **kwargs)
  File "/home/airflow/.local/lib/python3.9/site-packages/airflow/models/baseoperator.py", line 422, in wrapper
    return func(self, *args, **kwargs)
  File "/home/airflow/.local/lib/python3.9/site-packages/airflow/operators/python.py", line 238, in execute
    return_value = self.execute_callable()
  File "/home/airflow/.local/lib/python3.9/site-packages/airflow/operators/python.py", line 256, in execute_callable
    return runner.run(*self.op_args, **self.op_kwargs)
  File "/home/airflow/.local/lib/python3.9/site-packages/airflow/utils/operator_helpers.py", line 252, in run
    return self.func(*args, **kwargs)
  File "/opt/airflow/dbt/run_dbt.py", line 22, in transform_data
    raise RuntimeError("dbt run failed")
RuntimeError: dbt run failed
[2025-05-22T19:14:11.333+0000] {local_task_job_runner.py:266} INFO - Task exited with return code 1
[2025-05-22T19:14:11.352+0000] {taskinstance.py:3895} INFO - 0 downstream tasks scheduled from follow-on schedule check
[2025-05-22T19:14:11.355+0000] {local_task_job_runner.py:245} INFO - ::endgroup::
