[2025-05-22T14:49:31.936+0000] {local_task_job_runner.py:123} INFO - ::group::Pre task execution logs
[2025-05-22T14:49:31.956+0000] {taskinstance.py:2613} INFO - Dependencies all met for dep_context=non-requeueable deps ti=<TaskInstance: 04_transform_data.run_dbt manual__2025-05-22T14:49:29.756216+00:00 [queued]>
[2025-05-22T14:49:31.966+0000] {taskinstance.py:2613} INFO - Dependencies all met for dep_context=requeueable deps ti=<TaskInstance: 04_transform_data.run_dbt manual__2025-05-22T14:49:29.756216+00:00 [queued]>
[2025-05-22T14:49:31.967+0000] {taskinstance.py:2866} INFO - Starting attempt 1 of 1
[2025-05-22T14:49:31.982+0000] {taskinstance.py:2889} INFO - Executing <Task(PythonOperator): run_dbt> on 2025-05-22 14:49:29.756216+00:00
[2025-05-22T14:49:31.986+0000] {standard_task_runner.py:72} INFO - Started process 1286 to run task
[2025-05-22T14:49:31.989+0000] {standard_task_runner.py:104} INFO - Running: ['***', 'tasks', 'run', '04_transform_data', 'run_dbt', 'manual__2025-05-22T14:49:29.756216+00:00', '--job-id', '184', '--raw', '--subdir', 'DAGS_FOLDER/04_transform_data.py', '--cfg-path', '/tmp/tmpmlx5gx8g']
[2025-05-22T14:49:31.991+0000] {standard_task_runner.py:105} INFO - Job 184: Subtask run_dbt
[2025-05-22T14:49:32.052+0000] {task_command.py:467} INFO - Running <TaskInstance: 04_transform_data.run_dbt manual__2025-05-22T14:49:29.756216+00:00 [running]> on host e27e96d1841a
[2025-05-22T14:49:32.147+0000] {taskinstance.py:3132} INFO - Exporting env vars: AIRFLOW_CTX_DAG_OWNER='***' AIRFLOW_CTX_DAG_ID='04_transform_data' AIRFLOW_CTX_TASK_ID='run_dbt' AIRFLOW_CTX_EXECUTION_DATE='2025-05-22T14:49:29.756216+00:00' AIRFLOW_CTX_TRY_NUMBER='1' AIRFLOW_CTX_DAG_RUN_ID='manual__2025-05-22T14:49:29.756216+00:00'
[2025-05-22T14:49:32.149+0000] {taskinstance.py:731} INFO - ::endgroup::
[2025-05-22T14:49:34.088+0000] {logging_mixin.py:190} INFO - 14:49:34  Running with dbt=1.9.4
[2025-05-22T14:49:34.497+0000] {logging_mixin.py:190} INFO - 14:49:34  Registered adapter: postgres=1.9.0
[2025-05-22T14:49:35.848+0000] {logging_mixin.py:190} INFO - 14:49:35  [WARNING]: Configuration paths exist in your dbt_project.yml file which do not apply to any resources.
There are 1 unused configuration paths:
- models.e_commerce_sales.example
[2025-05-22T14:49:36.050+0000] {logging_mixin.py:190} INFO - 14:49:36  Found 12 models, 12 sources, 433 macros
[2025-05-22T14:49:36.055+0000] {logging_mixin.py:190} INFO - 14:49:36
[2025-05-22T14:49:36.057+0000] {logging_mixin.py:190} INFO - 14:49:36  Concurrency: 4 threads (target='dev')
[2025-05-22T14:49:36.059+0000] {logging_mixin.py:190} INFO - 14:49:36
[2025-05-22T14:49:36.221+0000] {logging_mixin.py:190} INFO - 14:49:36  1 of 12 START sql incremental model sales.mercadolivre_orders_results .......... [RUN]
[2025-05-22T14:49:36.223+0000] {logging_mixin.py:190} INFO - 14:49:36  2 of 12 START sql incremental model sales.shopee_new_id ........................ [RUN]
[2025-05-22T14:49:36.637+0000] {logging_mixin.py:190} INFO - 14:49:36  2 of 12 OK created sql incremental model sales.shopee_new_id ................... [MERGE 0 in 0.40s]
[2025-05-22T14:49:36.644+0000] {logging_mixin.py:190} INFO - 14:49:36  3 of 12 START sql incremental model sales.shopee_orders_results ................ [RUN]
[2025-05-22T14:49:36.673+0000] {logging_mixin.py:190} INFO - 14:49:36  1 of 12 ERROR creating sql incremental model sales.mercadolivre_orders_results . [ERROR in 0.44s]
[2025-05-22T14:49:36.682+0000] {logging_mixin.py:190} INFO - 14:49:36  4 of 12 SKIP relation sales.dim_mercadolivre_buyer ............................. [SKIP]
[2025-05-22T14:49:36.684+0000] {logging_mixin.py:190} INFO - 14:49:36  5 of 12 SKIP relation sales.dim_mercadolivre_date .............................. [SKIP]
[2025-05-22T14:49:36.694+0000] {logging_mixin.py:190} INFO - 14:49:36  6 of 12 SKIP relation sales.dim_mercadolivre_orders_status ..................... [SKIP]
[2025-05-22T14:49:36.708+0000] {logging_mixin.py:190} INFO - 14:49:36  7 of 12 SKIP relation sales.dim_mercadolivre_product ........................... [SKIP]
[2025-05-22T14:49:36.710+0000] {logging_mixin.py:190} INFO - 14:49:36  8 of 12 SKIP relation sales.mercadolivre_profits ............................... [SKIP]
[2025-05-22T14:49:36.798+0000] {logging_mixin.py:190} INFO - 14:49:36  3 of 12 OK created sql incremental model sales.shopee_orders_results ........... [MERGE 0 in 0.15s]
[2025-05-22T14:49:36.807+0000] {logging_mixin.py:190} INFO - 14:49:36  9 of 12 START sql incremental model sales.dim_shopee_buyer_id .................. [RUN]
[2025-05-22T14:49:36.809+0000] {logging_mixin.py:190} INFO - 14:49:36  10 of 12 START sql incremental model sales.dim_shopee_date ..................... [RUN]
[2025-05-22T14:49:36.811+0000] {logging_mixin.py:190} INFO - 14:49:36  11 of 12 START sql incremental model sales.dim_shopee_orders_status ............ [RUN]
[2025-05-22T14:49:36.813+0000] {logging_mixin.py:190} INFO - 14:49:36  12 of 12 START sql incremental model sales.dim_shopee_product .................. [RUN]
[2025-05-22T14:49:37.102+0000] {logging_mixin.py:190} INFO - 14:49:37  9 of 12 OK created sql incremental model sales.dim_shopee_buyer_id ............. [MERGE 0 in 0.28s]
[2025-05-22T14:49:37.140+0000] {logging_mixin.py:190} INFO - 14:49:37  10 of 12 OK created sql incremental model sales.dim_shopee_date ................ [MERGE 0 in 0.32s]
[2025-05-22T14:49:37.144+0000] {logging_mixin.py:190} INFO - 14:49:37  12 of 12 OK created sql incremental model sales.dim_shopee_product ............. [MERGE 0 in 0.32s]
[2025-05-22T14:49:37.148+0000] {logging_mixin.py:190} INFO - 14:49:37  11 of 12 OK created sql incremental model sales.dim_shopee_orders_status ....... [MERGE 0 in 0.33s]
[2025-05-22T14:49:37.180+0000] {logging_mixin.py:190} INFO - 14:49:37
[2025-05-22T14:49:37.182+0000] {logging_mixin.py:190} INFO - 14:49:37  Finished running 12 incremental models in 0 hours 0 minutes and 1.12 seconds (1.12s).
[2025-05-22T14:49:37.260+0000] {logging_mixin.py:190} INFO - 14:49:37
[2025-05-22T14:49:37.262+0000] {logging_mixin.py:190} INFO - 14:49:37  Completed with 1 error, 0 partial successes, and 0 warnings:
[2025-05-22T14:49:37.263+0000] {logging_mixin.py:190} INFO - 14:49:37
[2025-05-22T14:49:37.265+0000] {logging_mixin.py:190} INFO - 14:49:37    Database Error in model mercadolivre_orders_results (models/core/mercadolivre_orders_results.sql)
  MERGE command cannot affect row a second time
  HINT:  Ensure that not more than one source row matches any one target row.
  compiled code at target/run/e_commerce_sales/models/core/mercadolivre_orders_results.sql
[2025-05-22T14:49:37.267+0000] {logging_mixin.py:190} INFO - 14:49:37
[2025-05-22T14:49:37.269+0000] {logging_mixin.py:190} INFO - 14:49:37  Done. PASS=6 WARN=0 ERROR=1 SKIP=5 TOTAL=12
[2025-05-22T14:49:38.284+0000] {logging_mixin.py:190} INFO - dbt run failed!
[2025-05-22T14:49:38.285+0000] {logging_mixin.py:190} INFO - None
[2025-05-22T14:49:38.287+0000] {taskinstance.py:3311} ERROR - Task failed with exception
Traceback (most recent call last):
  File "/home/airflow/.local/lib/python3.9/site-packages/airflow/models/taskinstance.py", line 767, in _execute_task
    result = _execute_callable(context=context, **execute_callable_kwargs)
  File "/home/airflow/.local/lib/python3.9/site-packages/airflow/models/taskinstance.py", line 733, in _execute_callable
    return ExecutionCallableRunner(
  File "/home/airflow/.local/lib/python3.9/site-packages/airflow/utils/operator_helpers.py", line 252, in run
    return self.func(*args, **kwargs)
  File "/home/airflow/.local/lib/python3.9/site-packages/airflow/models/baseoperator.py", line 422, in wrapper
    return func(self, *args, **kwargs)
  File "/home/airflow/.local/lib/python3.9/site-packages/airflow/operators/python.py", line 238, in execute
    return_value = self.execute_callable()
  File "/home/airflow/.local/lib/python3.9/site-packages/airflow/operators/python.py", line 256, in execute_callable
    return runner.run(*self.op_args, **self.op_kwargs)
  File "/home/airflow/.local/lib/python3.9/site-packages/airflow/utils/operator_helpers.py", line 252, in run
    return self.func(*args, **kwargs)
  File "/opt/airflow/dbt/run_dbt.py", line 22, in transform_data
    raise RuntimeError("dbt run failed")
RuntimeError: dbt run failed
[2025-05-22T14:49:38.300+0000] {taskinstance.py:1225} INFO - Marking task as FAILED. dag_id=04_transform_data, task_id=run_dbt, run_id=manual__2025-05-22T14:49:29.756216+00:00, execution_date=20250522T144929, start_date=20250522T144931, end_date=20250522T144938
[2025-05-22T14:49:38.315+0000] {taskinstance.py:340} INFO - ::group::Post task execution logs
[2025-05-22T14:49:38.317+0000] {standard_task_runner.py:124} ERROR - Failed to execute job 184 for task run_dbt (dbt run failed; 1286)
Traceback (most recent call last):
  File "/home/airflow/.local/lib/python3.9/site-packages/airflow/task/task_runner/standard_task_runner.py", line 117, in _start_by_fork
    ret = args.func(args, dag=self.dag)
  File "/home/airflow/.local/lib/python3.9/site-packages/airflow/cli/cli_config.py", line 49, in command
    return func(*args, **kwargs)
  File "/home/airflow/.local/lib/python3.9/site-packages/airflow/utils/cli.py", line 116, in wrapper
    return f(*args, **kwargs)
  File "/home/airflow/.local/lib/python3.9/site-packages/airflow/cli/commands/task_command.py", line 483, in task_run
    task_return_code = _run_task_by_selected_method(args, _dag, ti)
  File "/home/airflow/.local/lib/python3.9/site-packages/airflow/cli/commands/task_command.py", line 256, in _run_task_by_selected_method
    return _run_raw_task(args, ti)
  File "/home/airflow/.local/lib/python3.9/site-packages/airflow/cli/commands/task_command.py", line 341, in _run_raw_task
    return ti._run_raw_task(
  File "/home/airflow/.local/lib/python3.9/site-packages/airflow/utils/session.py", line 97, in wrapper
    return func(*args, session=session, **kwargs)
  File "/home/airflow/.local/lib/python3.9/site-packages/airflow/models/taskinstance.py", line 3005, in _run_raw_task
    return _run_raw_task(
  File "/home/airflow/.local/lib/python3.9/site-packages/airflow/models/taskinstance.py", line 273, in _run_raw_task
    TaskInstance._execute_task_with_callbacks(
  File "/home/airflow/.local/lib/python3.9/site-packages/airflow/models/taskinstance.py", line 3159, in _execute_task_with_callbacks
    result = self._execute_task(context, task_orig)
  File "/home/airflow/.local/lib/python3.9/site-packages/airflow/models/taskinstance.py", line 3183, in _execute_task
    return _execute_task(self, context, task_orig)
  File "/home/airflow/.local/lib/python3.9/site-packages/airflow/models/taskinstance.py", line 767, in _execute_task
    result = _execute_callable(context=context, **execute_callable_kwargs)
  File "/home/airflow/.local/lib/python3.9/site-packages/airflow/models/taskinstance.py", line 733, in _execute_callable
    return ExecutionCallableRunner(
  File "/home/airflow/.local/lib/python3.9/site-packages/airflow/utils/operator_helpers.py", line 252, in run
    return self.func(*args, **kwargs)
  File "/home/airflow/.local/lib/python3.9/site-packages/airflow/models/baseoperator.py", line 422, in wrapper
    return func(self, *args, **kwargs)
  File "/home/airflow/.local/lib/python3.9/site-packages/airflow/operators/python.py", line 238, in execute
    return_value = self.execute_callable()
  File "/home/airflow/.local/lib/python3.9/site-packages/airflow/operators/python.py", line 256, in execute_callable
    return runner.run(*self.op_args, **self.op_kwargs)
  File "/home/airflow/.local/lib/python3.9/site-packages/airflow/utils/operator_helpers.py", line 252, in run
    return self.func(*args, **kwargs)
  File "/opt/airflow/dbt/run_dbt.py", line 22, in transform_data
    raise RuntimeError("dbt run failed")
RuntimeError: dbt run failed
[2025-05-22T14:49:38.356+0000] {local_task_job_runner.py:266} INFO - Task exited with return code 1
[2025-05-22T14:49:38.375+0000] {taskinstance.py:3895} INFO - 0 downstream tasks scheduled from follow-on schedule check
[2025-05-22T14:49:38.379+0000] {local_task_job_runner.py:245} INFO - ::endgroup::
