[2025-05-21T20:36:05.203+0000] {local_task_job_runner.py:123} INFO - ::group::Pre task execution logs
[2025-05-21T20:36:05.226+0000] {taskinstance.py:2613} INFO - Dependencies all met for dep_context=non-requeueable deps ti=<TaskInstance: 04_transform_data.run_dbt manual__2025-05-21T20:36:03.580661+00:00 [queued]>
[2025-05-21T20:36:05.236+0000] {taskinstance.py:2613} INFO - Dependencies all met for dep_context=requeueable deps ti=<TaskInstance: 04_transform_data.run_dbt manual__2025-05-21T20:36:03.580661+00:00 [queued]>
[2025-05-21T20:36:05.237+0000] {taskinstance.py:2866} INFO - Starting attempt 1 of 1
[2025-05-21T20:36:05.251+0000] {taskinstance.py:2889} INFO - Executing <Task(PythonOperator): run_dbt> on 2025-05-21 20:36:03.580661+00:00
[2025-05-21T20:36:05.256+0000] {standard_task_runner.py:72} INFO - Started process 5215 to run task
[2025-05-21T20:36:05.261+0000] {standard_task_runner.py:104} INFO - Running: ['***', 'tasks', 'run', '04_transform_data', 'run_dbt', 'manual__2025-05-21T20:36:03.580661+00:00', '--job-id', '129', '--raw', '--subdir', 'DAGS_FOLDER/04_transform_data.py', '--cfg-path', '/tmp/tmpdrzql5fh']
[2025-05-21T20:36:05.263+0000] {standard_task_runner.py:105} INFO - Job 129: Subtask run_dbt
[2025-05-21T20:36:05.338+0000] {task_command.py:467} INFO - Running <TaskInstance: 04_transform_data.run_dbt manual__2025-05-21T20:36:03.580661+00:00 [running]> on host e27e96d1841a
[2025-05-21T20:36:05.458+0000] {taskinstance.py:3132} INFO - Exporting env vars: AIRFLOW_CTX_DAG_OWNER='***' AIRFLOW_CTX_DAG_ID='04_transform_data' AIRFLOW_CTX_TASK_ID='run_dbt' AIRFLOW_CTX_EXECUTION_DATE='2025-05-21T20:36:03.580661+00:00' AIRFLOW_CTX_TRY_NUMBER='1' AIRFLOW_CTX_DAG_RUN_ID='manual__2025-05-21T20:36:03.580661+00:00'
[2025-05-21T20:36:05.459+0000] {taskinstance.py:731} INFO - ::endgroup::
[2025-05-21T20:36:07.255+0000] {logging_mixin.py:190} INFO - 20:36:07  Running with dbt=1.9.4
[2025-05-21T20:36:07.637+0000] {logging_mixin.py:190} INFO - 20:36:07  Registered adapter: postgres=1.9.0
[2025-05-21T20:36:08.980+0000] {logging_mixin.py:190} INFO - 20:36:08  [WARNING]: Configuration paths exist in your dbt_project.yml file which do not apply to any resources.
There are 1 unused configuration paths:
- models.e_commerce_sales.example
[2025-05-21T20:36:09.149+0000] {logging_mixin.py:190} INFO - 20:36:09  Found 11 models, 12 sources, 433 macros
[2025-05-21T20:36:09.153+0000] {logging_mixin.py:190} INFO - 20:36:09
[2025-05-21T20:36:09.155+0000] {logging_mixin.py:190} INFO - 20:36:09  Concurrency: 4 threads (target='dev')
[2025-05-21T20:36:09.157+0000] {logging_mixin.py:190} INFO - 20:36:09
[2025-05-21T20:36:09.291+0000] {logging_mixin.py:190} INFO - 20:36:09  1 of 11 START sql incremental model sales.mercadolivre_orders_results .......... [RUN]
[2025-05-21T20:36:09.294+0000] {logging_mixin.py:190} INFO - 20:36:09  2 of 11 START sql incremental model sales.shopee_new_id ........................ [RUN]
[2025-05-21T20:36:09.658+0000] {logging_mixin.py:190} INFO - 20:36:09  2 of 11 OK created sql incremental model sales.shopee_new_id ................... [MERGE 0 in 0.36s]
[2025-05-21T20:36:09.660+0000] {logging_mixin.py:190} INFO - 20:36:09  1 of 11 OK created sql incremental model sales.mercadolivre_orders_results ..... [MERGE 255 in 0.36s]
[2025-05-21T20:36:09.665+0000] {logging_mixin.py:190} INFO - 20:36:09  3 of 11 START sql incremental model sales.shopee_orders_results ................ [RUN]
[2025-05-21T20:36:09.670+0000] {logging_mixin.py:190} INFO - 20:36:09  4 of 11 START sql incremental model sales.dim_mercadolivre_buyer ............... [RUN]
[2025-05-21T20:36:09.672+0000] {logging_mixin.py:190} INFO - 20:36:09  5 of 11 START sql incremental model sales.dim_mercadolivre_date ................ [RUN]
[2025-05-21T20:36:09.673+0000] {logging_mixin.py:190} INFO - 20:36:09  6 of 11 START sql incremental model sales.dim_mercadolivre_product ............. [RUN]
[2025-05-21T20:36:09.928+0000] {logging_mixin.py:190} INFO - 20:36:09  3 of 11 OK created sql incremental model sales.shopee_orders_results ........... [MERGE 0 in 0.26s]
[2025-05-21T20:36:09.939+0000] {logging_mixin.py:190} INFO - 20:36:09  7 of 11 START sql incremental model sales.mercadolivre_profits ................. [RUN]
[2025-05-21T20:36:09.983+0000] {logging_mixin.py:190} INFO - 20:36:09  5 of 11 ERROR creating sql incremental model sales.dim_mercadolivre_date ....... [ERROR in 0.30s]
[2025-05-21T20:36:09.986+0000] {logging_mixin.py:190} INFO - 20:36:09  4 of 11 ERROR creating sql incremental model sales.dim_mercadolivre_buyer ...... [ERROR in 0.30s]
[2025-05-21T20:36:10.005+0000] {logging_mixin.py:190} INFO - 20:36:10  6 of 11 OK created sql incremental model sales.dim_mercadolivre_product ........ [MERGE 250 in 0.30s]
[2025-05-21T20:36:10.011+0000] {logging_mixin.py:190} INFO - 20:36:10  8 of 11 START sql incremental model sales.dim_shopee_buyer_id .................. [RUN]
[2025-05-21T20:36:10.015+0000] {logging_mixin.py:190} INFO - 20:36:10  9 of 11 START sql incremental model sales.dim_shopee_date ...................... [RUN]
[2025-05-21T20:36:10.028+0000] {logging_mixin.py:190} INFO - 20:36:10  10 of 11 START sql incremental model sales.dim_shopee_orders_status ............ [RUN]
[2025-05-21T20:36:10.223+0000] {logging_mixin.py:190} INFO - 20:36:10  7 of 11 OK created sql incremental model sales.mercadolivre_profits ............ [MERGE 250 in 0.27s]
[2025-05-21T20:36:10.244+0000] {logging_mixin.py:190} INFO - 20:36:10  11 of 11 START sql incremental model sales.dim_shopee_product .................. [RUN]
[2025-05-21T20:36:10.307+0000] {logging_mixin.py:190} INFO - 20:36:10  9 of 11 OK created sql incremental model sales.dim_shopee_date ................. [MERGE 0 in 0.28s]
[2025-05-21T20:36:10.309+0000] {logging_mixin.py:190} INFO - 20:36:10  8 of 11 OK created sql incremental model sales.dim_shopee_buyer_id ............. [MERGE 0 in 0.28s]
[2025-05-21T20:36:10.311+0000] {logging_mixin.py:190} INFO - 20:36:10  10 of 11 OK created sql incremental model sales.dim_shopee_orders_status ....... [MERGE 0 in 0.26s]
[2025-05-21T20:36:10.378+0000] {logging_mixin.py:190} INFO - 20:36:10  11 of 11 OK created sql incremental model sales.dim_shopee_product ............. [MERGE 0 in 0.13s]
[2025-05-21T20:36:10.402+0000] {logging_mixin.py:190} INFO - 20:36:10
[2025-05-21T20:36:10.404+0000] {logging_mixin.py:190} INFO - 20:36:10  Finished running 11 incremental models in 0 hours 0 minutes and 1.24 seconds (1.24s).
[2025-05-21T20:36:10.471+0000] {logging_mixin.py:190} INFO - 20:36:10
[2025-05-21T20:36:10.473+0000] {logging_mixin.py:190} INFO - 20:36:10  Completed with 2 errors, 0 partial successes, and 0 warnings:
[2025-05-21T20:36:10.475+0000] {logging_mixin.py:190} INFO - 20:36:10
[2025-05-21T20:36:10.476+0000] {logging_mixin.py:190} INFO - 20:36:10    Database Error in model dim_mercadolivre_date (models/core/dim_mercadolivre_date.sql)
  MERGE command cannot affect row a second time
  HINT:  Ensure that not more than one source row matches any one target row.
  compiled code at target/run/e_commerce_sales/models/core/dim_mercadolivre_date.sql
[2025-05-21T20:36:10.478+0000] {logging_mixin.py:190} INFO - 20:36:10
[2025-05-21T20:36:10.479+0000] {logging_mixin.py:190} INFO - 20:36:10    Database Error in model dim_mercadolivre_buyer (models/core/dim_mercadolivre_buyer.sql)
  MERGE command cannot affect row a second time
  HINT:  Ensure that not more than one source row matches any one target row.
  compiled code at target/run/e_commerce_sales/models/core/dim_mercadolivre_buyer.sql
[2025-05-21T20:36:10.480+0000] {logging_mixin.py:190} INFO - 20:36:10
[2025-05-21T20:36:10.482+0000] {logging_mixin.py:190} INFO - 20:36:10  Done. PASS=9 WARN=0 ERROR=2 SKIP=0 TOTAL=11
[2025-05-21T20:36:11.378+0000] {logging_mixin.py:190} INFO - dbt run failed!
[2025-05-21T20:36:11.379+0000] {logging_mixin.py:190} INFO - None
[2025-05-21T20:36:11.380+0000] {taskinstance.py:3311} ERROR - Task failed with exception
Traceback (most recent call last):
  File "/home/airflow/.local/lib/python3.9/site-packages/airflow/models/taskinstance.py", line 767, in _execute_task
    result = _execute_callable(context=context, **execute_callable_kwargs)
  File "/home/airflow/.local/lib/python3.9/site-packages/airflow/models/taskinstance.py", line 733, in _execute_callable
    return ExecutionCallableRunner(
  File "/home/airflow/.local/lib/python3.9/site-packages/airflow/utils/operator_helpers.py", line 252, in run
    return self.func(*args, **kwargs)
  File "/home/airflow/.local/lib/python3.9/site-packages/airflow/models/baseoperator.py", line 422, in wrapper
    return func(self, *args, **kwargs)
  File "/home/airflow/.local/lib/python3.9/site-packages/airflow/operators/python.py", line 238, in execute
    return_value = self.execute_callable()
  File "/home/airflow/.local/lib/python3.9/site-packages/airflow/operators/python.py", line 256, in execute_callable
    return runner.run(*self.op_args, **self.op_kwargs)
  File "/home/airflow/.local/lib/python3.9/site-packages/airflow/utils/operator_helpers.py", line 252, in run
    return self.func(*args, **kwargs)
  File "/opt/airflow/dbt/run_dbt.py", line 22, in transform_data
    raise RuntimeError("dbt run failed")
RuntimeError: dbt run failed
[2025-05-21T20:36:11.391+0000] {taskinstance.py:1225} INFO - Marking task as FAILED. dag_id=04_transform_data, task_id=run_dbt, run_id=manual__2025-05-21T20:36:03.580661+00:00, execution_date=20250521T203603, start_date=20250521T203605, end_date=20250521T203611
[2025-05-21T20:36:11.403+0000] {taskinstance.py:340} INFO - ::group::Post task execution logs
[2025-05-21T20:36:11.405+0000] {standard_task_runner.py:124} ERROR - Failed to execute job 129 for task run_dbt (dbt run failed; 5215)
Traceback (most recent call last):
  File "/home/airflow/.local/lib/python3.9/site-packages/airflow/task/task_runner/standard_task_runner.py", line 117, in _start_by_fork
    ret = args.func(args, dag=self.dag)
  File "/home/airflow/.local/lib/python3.9/site-packages/airflow/cli/cli_config.py", line 49, in command
    return func(*args, **kwargs)
  File "/home/airflow/.local/lib/python3.9/site-packages/airflow/utils/cli.py", line 116, in wrapper
    return f(*args, **kwargs)
  File "/home/airflow/.local/lib/python3.9/site-packages/airflow/cli/commands/task_command.py", line 483, in task_run
    task_return_code = _run_task_by_selected_method(args, _dag, ti)
  File "/home/airflow/.local/lib/python3.9/site-packages/airflow/cli/commands/task_command.py", line 256, in _run_task_by_selected_method
    return _run_raw_task(args, ti)
  File "/home/airflow/.local/lib/python3.9/site-packages/airflow/cli/commands/task_command.py", line 341, in _run_raw_task
    return ti._run_raw_task(
  File "/home/airflow/.local/lib/python3.9/site-packages/airflow/utils/session.py", line 97, in wrapper
    return func(*args, session=session, **kwargs)
  File "/home/airflow/.local/lib/python3.9/site-packages/airflow/models/taskinstance.py", line 3005, in _run_raw_task
    return _run_raw_task(
  File "/home/airflow/.local/lib/python3.9/site-packages/airflow/models/taskinstance.py", line 273, in _run_raw_task
    TaskInstance._execute_task_with_callbacks(
  File "/home/airflow/.local/lib/python3.9/site-packages/airflow/models/taskinstance.py", line 3159, in _execute_task_with_callbacks
    result = self._execute_task(context, task_orig)
  File "/home/airflow/.local/lib/python3.9/site-packages/airflow/models/taskinstance.py", line 3183, in _execute_task
    return _execute_task(self, context, task_orig)
  File "/home/airflow/.local/lib/python3.9/site-packages/airflow/models/taskinstance.py", line 767, in _execute_task
    result = _execute_callable(context=context, **execute_callable_kwargs)
  File "/home/airflow/.local/lib/python3.9/site-packages/airflow/models/taskinstance.py", line 733, in _execute_callable
    return ExecutionCallableRunner(
  File "/home/airflow/.local/lib/python3.9/site-packages/airflow/utils/operator_helpers.py", line 252, in run
    return self.func(*args, **kwargs)
  File "/home/airflow/.local/lib/python3.9/site-packages/airflow/models/baseoperator.py", line 422, in wrapper
    return func(self, *args, **kwargs)
  File "/home/airflow/.local/lib/python3.9/site-packages/airflow/operators/python.py", line 238, in execute
    return_value = self.execute_callable()
  File "/home/airflow/.local/lib/python3.9/site-packages/airflow/operators/python.py", line 256, in execute_callable
    return runner.run(*self.op_args, **self.op_kwargs)
  File "/home/airflow/.local/lib/python3.9/site-packages/airflow/utils/operator_helpers.py", line 252, in run
    return self.func(*args, **kwargs)
  File "/opt/airflow/dbt/run_dbt.py", line 22, in transform_data
    raise RuntimeError("dbt run failed")
RuntimeError: dbt run failed
[2025-05-21T20:36:11.460+0000] {local_task_job_runner.py:266} INFO - Task exited with return code 1
[2025-05-21T20:36:11.477+0000] {taskinstance.py:3895} INFO - 0 downstream tasks scheduled from follow-on schedule check
[2025-05-21T20:36:11.480+0000] {local_task_job_runner.py:245} INFO - ::endgroup::
