[2025-06-06T19:27:23.875+0000] {local_task_job_runner.py:123} INFO - ::group::Pre task execution logs
[2025-06-06T19:27:23.899+0000] {taskinstance.py:2613} INFO - Dependencies all met for dep_context=non-requeueable deps ti=<TaskInstance: 04_ELT_shipping_file.extract_from_API manual__2025-06-06T19:27:20.797738+00:00 [queued]>
[2025-06-06T19:27:23.909+0000] {taskinstance.py:2613} INFO - Dependencies all met for dep_context=requeueable deps ti=<TaskInstance: 04_ELT_shipping_file.extract_from_API manual__2025-06-06T19:27:20.797738+00:00 [queued]>
[2025-06-06T19:27:23.910+0000] {taskinstance.py:2866} INFO - Starting attempt 1 of 1
[2025-06-06T19:27:23.925+0000] {taskinstance.py:2889} INFO - Executing <Task(PythonOperator): extract_from_API> on 2025-06-06 19:27:20.797738+00:00
[2025-06-06T19:27:23.930+0000] {standard_task_runner.py:72} INFO - Started process 2347 to run task
[2025-06-06T19:27:23.934+0000] {standard_task_runner.py:104} INFO - Running: ['***', 'tasks', 'run', '04_ELT_shipping_file', 'extract_from_API', 'manual__2025-06-06T19:27:20.797738+00:00', '--job-id', '400', '--raw', '--subdir', 'DAGS_FOLDER/04_make_sh_id_file.py', '--cfg-path', '/tmp/tmpmedsji2e']
[2025-06-06T19:27:23.936+0000] {standard_task_runner.py:105} INFO - Job 400: Subtask extract_from_API
[2025-06-06T19:27:24.000+0000] {task_command.py:467} INFO - Running <TaskInstance: 04_ELT_shipping_file.extract_from_API manual__2025-06-06T19:27:20.797738+00:00 [running]> on host 28e6a58e4107
[2025-06-06T19:27:24.094+0000] {taskinstance.py:3132} INFO - Exporting env vars: AIRFLOW_CTX_DAG_OWNER='***' AIRFLOW_CTX_DAG_ID='04_ELT_shipping_file' AIRFLOW_CTX_TASK_ID='extract_from_API' AIRFLOW_CTX_EXECUTION_DATE='2025-06-06T19:27:20.797738+00:00' AIRFLOW_CTX_TRY_NUMBER='1' AIRFLOW_CTX_DAG_RUN_ID='manual__2025-06-06T19:27:20.797738+00:00'
[2025-06-06T19:27:24.096+0000] {taskinstance.py:731} INFO - ::endgroup::
[2025-06-06T19:27:24.600+0000] {taskinstance.py:3311} ERROR - Task failed with exception
Traceback (most recent call last):
  File "/home/airflow/.local/lib/python3.9/site-packages/pandas/core/indexes/base.py", line 3791, in get_loc
    return self._engine.get_loc(casted_key)
  File "index.pyx", line 152, in pandas._libs.index.IndexEngine.get_loc
  File "index.pyx", line 181, in pandas._libs.index.IndexEngine.get_loc
  File "pandas/_libs/hashtable_class_helper.pxi", line 7080, in pandas._libs.hashtable.PyObjectHashTable.get_item
  File "pandas/_libs/hashtable_class_helper.pxi", line 7088, in pandas._libs.hashtable.PyObjectHashTable.get_item
KeyError: 'shipping_id'

The above exception was the direct cause of the following exception:

Traceback (most recent call last):
  File "/home/airflow/.local/lib/python3.9/site-packages/airflow/models/taskinstance.py", line 767, in _execute_task
    result = _execute_callable(context=context, **execute_callable_kwargs)
  File "/home/airflow/.local/lib/python3.9/site-packages/airflow/models/taskinstance.py", line 733, in _execute_callable
    return ExecutionCallableRunner(
  File "/home/airflow/.local/lib/python3.9/site-packages/airflow/utils/operator_helpers.py", line 252, in run
    return self.func(*args, **kwargs)
  File "/home/airflow/.local/lib/python3.9/site-packages/airflow/models/baseoperator.py", line 422, in wrapper
    return func(self, *args, **kwargs)
  File "/home/airflow/.local/lib/python3.9/site-packages/airflow/operators/python.py", line 238, in execute
    return_value = self.execute_callable()
  File "/home/airflow/.local/lib/python3.9/site-packages/airflow/operators/python.py", line 256, in execute_callable
    return runner.run(*self.op_args, **self.op_kwargs)
  File "/home/airflow/.local/lib/python3.9/site-packages/airflow/utils/operator_helpers.py", line 252, in run
    return self.func(*args, **kwargs)
  File "/opt/airflow/extraction/mercadolivre/script/get_seller_shipping_cost.py", line 17, in get_shipping_id
    df["shipping_id"] = df["shipping_id"].astype(int)
  File "/home/airflow/.local/lib/python3.9/site-packages/pandas/core/frame.py", line 3893, in __getitem__
    indexer = self.columns.get_loc(key)
  File "/home/airflow/.local/lib/python3.9/site-packages/pandas/core/indexes/base.py", line 3798, in get_loc
    raise KeyError(key) from err
KeyError: 'shipping_id'
[2025-06-06T19:27:24.618+0000] {taskinstance.py:1225} INFO - Marking task as FAILED. dag_id=04_ELT_shipping_file, task_id=extract_from_API, run_id=manual__2025-06-06T19:27:20.797738+00:00, execution_date=20250606T192720, start_date=20250606T192723, end_date=20250606T192724
[2025-06-06T19:27:24.630+0000] {taskinstance.py:340} INFO - ::group::Post task execution logs
[2025-06-06T19:27:24.631+0000] {standard_task_runner.py:124} ERROR - Failed to execute job 400 for task extract_from_API ('shipping_id'; 2347)
Traceback (most recent call last):
  File "/home/airflow/.local/lib/python3.9/site-packages/pandas/core/indexes/base.py", line 3791, in get_loc
    return self._engine.get_loc(casted_key)
  File "index.pyx", line 152, in pandas._libs.index.IndexEngine.get_loc
  File "index.pyx", line 181, in pandas._libs.index.IndexEngine.get_loc
  File "pandas/_libs/hashtable_class_helper.pxi", line 7080, in pandas._libs.hashtable.PyObjectHashTable.get_item
  File "pandas/_libs/hashtable_class_helper.pxi", line 7088, in pandas._libs.hashtable.PyObjectHashTable.get_item
KeyError: 'shipping_id'

The above exception was the direct cause of the following exception:

Traceback (most recent call last):
  File "/home/airflow/.local/lib/python3.9/site-packages/airflow/task/task_runner/standard_task_runner.py", line 117, in _start_by_fork
    ret = args.func(args, dag=self.dag)
  File "/home/airflow/.local/lib/python3.9/site-packages/airflow/cli/cli_config.py", line 49, in command
    return func(*args, **kwargs)
  File "/home/airflow/.local/lib/python3.9/site-packages/airflow/utils/cli.py", line 116, in wrapper
    return f(*args, **kwargs)
  File "/home/airflow/.local/lib/python3.9/site-packages/airflow/cli/commands/task_command.py", line 483, in task_run
    task_return_code = _run_task_by_selected_method(args, _dag, ti)
  File "/home/airflow/.local/lib/python3.9/site-packages/airflow/cli/commands/task_command.py", line 256, in _run_task_by_selected_method
    return _run_raw_task(args, ti)
  File "/home/airflow/.local/lib/python3.9/site-packages/airflow/cli/commands/task_command.py", line 341, in _run_raw_task
    return ti._run_raw_task(
  File "/home/airflow/.local/lib/python3.9/site-packages/airflow/utils/session.py", line 97, in wrapper
    return func(*args, session=session, **kwargs)
  File "/home/airflow/.local/lib/python3.9/site-packages/airflow/models/taskinstance.py", line 3005, in _run_raw_task
    return _run_raw_task(
  File "/home/airflow/.local/lib/python3.9/site-packages/airflow/models/taskinstance.py", line 273, in _run_raw_task
    TaskInstance._execute_task_with_callbacks(
  File "/home/airflow/.local/lib/python3.9/site-packages/airflow/models/taskinstance.py", line 3159, in _execute_task_with_callbacks
    result = self._execute_task(context, task_orig)
  File "/home/airflow/.local/lib/python3.9/site-packages/airflow/models/taskinstance.py", line 3183, in _execute_task
    return _execute_task(self, context, task_orig)
  File "/home/airflow/.local/lib/python3.9/site-packages/airflow/models/taskinstance.py", line 767, in _execute_task
    result = _execute_callable(context=context, **execute_callable_kwargs)
  File "/home/airflow/.local/lib/python3.9/site-packages/airflow/models/taskinstance.py", line 733, in _execute_callable
    return ExecutionCallableRunner(
  File "/home/airflow/.local/lib/python3.9/site-packages/airflow/utils/operator_helpers.py", line 252, in run
    return self.func(*args, **kwargs)
  File "/home/airflow/.local/lib/python3.9/site-packages/airflow/models/baseoperator.py", line 422, in wrapper
    return func(self, *args, **kwargs)
  File "/home/airflow/.local/lib/python3.9/site-packages/airflow/operators/python.py", line 238, in execute
    return_value = self.execute_callable()
  File "/home/airflow/.local/lib/python3.9/site-packages/airflow/operators/python.py", line 256, in execute_callable
    return runner.run(*self.op_args, **self.op_kwargs)
  File "/home/airflow/.local/lib/python3.9/site-packages/airflow/utils/operator_helpers.py", line 252, in run
    return self.func(*args, **kwargs)
  File "/opt/airflow/extraction/mercadolivre/script/get_seller_shipping_cost.py", line 17, in get_shipping_id
    df["shipping_id"] = df["shipping_id"].astype(int)
  File "/home/airflow/.local/lib/python3.9/site-packages/pandas/core/frame.py", line 3893, in __getitem__
    indexer = self.columns.get_loc(key)
  File "/home/airflow/.local/lib/python3.9/site-packages/pandas/core/indexes/base.py", line 3798, in get_loc
    raise KeyError(key) from err
KeyError: 'shipping_id'
[2025-06-06T19:27:24.671+0000] {local_task_job_runner.py:266} INFO - Task exited with return code 1
[2025-06-06T19:27:24.693+0000] {taskinstance.py:3895} INFO - 0 downstream tasks scheduled from follow-on schedule check
[2025-06-06T19:27:24.698+0000] {local_task_job_runner.py:245} INFO - ::endgroup::
