[2025-05-22T19:20:53.076+0000] {local_task_job_runner.py:123} INFO - ::group::Pre task execution logs
[2025-05-22T19:20:53.094+0000] {taskinstance.py:2613} INFO - Dependencies all met for dep_context=non-requeueable deps ti=<TaskInstance: 04_transform_data.run_dbt manual__2025-05-22T19:20:44.447246+00:00 [queued]>
[2025-05-22T19:20:53.102+0000] {taskinstance.py:2613} INFO - Dependencies all met for dep_context=requeueable deps ti=<TaskInstance: 04_transform_data.run_dbt manual__2025-05-22T19:20:44.447246+00:00 [queued]>
[2025-05-22T19:20:53.103+0000] {taskinstance.py:2866} INFO - Starting attempt 1 of 1
[2025-05-22T19:20:53.115+0000] {taskinstance.py:2889} INFO - Executing <Task(PythonOperator): run_dbt> on 2025-05-22 19:20:44.447246+00:00
[2025-05-22T19:20:53.120+0000] {standard_task_runner.py:72} INFO - Started process 4060 to run task
[2025-05-22T19:20:53.122+0000] {standard_task_runner.py:104} INFO - Running: ['***', 'tasks', 'run', '04_transform_data', 'run_dbt', 'manual__2025-05-22T19:20:44.447246+00:00', '--job-id', '220', '--raw', '--subdir', 'DAGS_FOLDER/04_transform_data.py', '--cfg-path', '/tmp/tmpk2gjjc_y']
[2025-05-22T19:20:53.124+0000] {standard_task_runner.py:105} INFO - Job 220: Subtask run_dbt
[2025-05-22T19:20:53.176+0000] {task_command.py:467} INFO - Running <TaskInstance: 04_transform_data.run_dbt manual__2025-05-22T19:20:44.447246+00:00 [running]> on host e27e96d1841a
[2025-05-22T19:20:53.268+0000] {taskinstance.py:3132} INFO - Exporting env vars: AIRFLOW_CTX_DAG_OWNER='***' AIRFLOW_CTX_DAG_ID='04_transform_data' AIRFLOW_CTX_TASK_ID='run_dbt' AIRFLOW_CTX_EXECUTION_DATE='2025-05-22T19:20:44.447246+00:00' AIRFLOW_CTX_TRY_NUMBER='1' AIRFLOW_CTX_DAG_RUN_ID='manual__2025-05-22T19:20:44.447246+00:00'
[2025-05-22T19:20:53.270+0000] {taskinstance.py:731} INFO - ::endgroup::
[2025-05-22T19:20:54.883+0000] {logging_mixin.py:190} INFO - 19:20:54  Running with dbt=1.9.4
[2025-05-22T19:20:55.229+0000] {logging_mixin.py:190} INFO - 19:20:55  Registered adapter: postgres=1.9.0
[2025-05-22T19:20:56.927+0000] {logging_mixin.py:190} INFO - 19:20:56  [WARNING]: Configuration paths exist in your dbt_project.yml file which do not apply to any resources.
There are 1 unused configuration paths:
- models.e_commerce_sales.example
[2025-05-22T19:20:57.099+0000] {logging_mixin.py:190} INFO - 19:20:57  Found 11 models, 12 sources, 549 macros
[2025-05-22T19:20:57.104+0000] {logging_mixin.py:190} INFO - 19:20:57
[2025-05-22T19:20:57.105+0000] {logging_mixin.py:190} INFO - 19:20:57  Concurrency: 4 threads (target='dev')
[2025-05-22T19:20:57.107+0000] {logging_mixin.py:190} INFO - 19:20:57
[2025-05-22T19:20:57.226+0000] {logging_mixin.py:190} INFO - 19:20:57  1 of 11 START sql incremental model sales.mercadolivre_orders_results .......... [RUN]
[2025-05-22T19:20:57.228+0000] {logging_mixin.py:190} INFO - 19:20:57  2 of 11 START sql incremental model sales.shopee_new_id ........................ [RUN]
[2025-05-22T19:20:57.566+0000] {logging_mixin.py:190} INFO - 19:20:57  2 of 11 OK created sql incremental model sales.shopee_new_id ................... [MERGE 0 in 0.33s]
[2025-05-22T19:20:57.571+0000] {logging_mixin.py:190} INFO - 19:20:57  1 of 11 OK created sql incremental model sales.mercadolivre_orders_results ..... [MERGE 190 in 0.34s]
[2025-05-22T19:20:57.575+0000] {logging_mixin.py:190} INFO - 19:20:57  3 of 11 START sql incremental model sales.shopee_orders_results ................ [RUN]
[2025-05-22T19:20:57.581+0000] {logging_mixin.py:190} INFO - 19:20:57  4 of 11 START sql incremental model sales.dim_mercadolivre_buyer ............... [RUN]
[2025-05-22T19:20:57.583+0000] {logging_mixin.py:190} INFO - 19:20:57  5 of 11 START sql incremental model sales.dim_mercadolivre_date ................ [RUN]
[2025-05-22T19:20:57.584+0000] {logging_mixin.py:190} INFO - 19:20:57  6 of 11 START sql incremental model sales.dim_mercadolivre_orders_status ....... [RUN]
[2025-05-22T19:20:57.735+0000] {logging_mixin.py:190} INFO - 19:20:57  3 of 11 ERROR creating sql incremental model sales.shopee_orders_results ....... [ERROR in 0.15s]
[2025-05-22T19:20:57.744+0000] {logging_mixin.py:190} INFO - 19:20:57  7 of 11 START sql incremental model sales.dim_mercadolivre_product ............. [RUN]
[2025-05-22T19:20:57.898+0000] {logging_mixin.py:190} INFO - 19:20:57  4 of 11 OK created sql incremental model sales.dim_mercadolivre_buyer .......... [MERGE 188 in 0.31s]
[2025-05-22T19:20:57.901+0000] {logging_mixin.py:190} INFO - 19:20:57  6 of 11 OK created sql incremental model sales.dim_mercadolivre_orders_status .. [MERGE 190 in 0.29s]
[2025-05-22T19:20:57.904+0000] {logging_mixin.py:190} INFO - 19:20:57  5 of 11 OK created sql incremental model sales.dim_mercadolivre_date ........... [MERGE 190 in 0.31s]
[2025-05-22T19:20:57.919+0000] {logging_mixin.py:190} INFO - 19:20:57  8 of 11 SKIP relation sales.dim_shopee_buyer ................................... [SKIP]
[2025-05-22T19:20:57.924+0000] {logging_mixin.py:190} INFO - 19:20:57  9 of 11 SKIP relation sales.dim_shopee_date .................................... [SKIP]
[2025-05-22T19:20:57.926+0000] {logging_mixin.py:190} INFO - 19:20:57  10 of 11 SKIP relation sales.dim_shopee_orders_status .......................... [SKIP]
[2025-05-22T19:20:57.941+0000] {logging_mixin.py:190} INFO - 19:20:57  11 of 11 SKIP relation sales.dim_shopee_product ................................ [SKIP]
[2025-05-22T19:20:57.968+0000] {logging_mixin.py:190} INFO - 19:20:57  7 of 11 OK created sql incremental model sales.dim_mercadolivre_product ........ [MERGE 186 in 0.20s]
[2025-05-22T19:20:57.992+0000] {logging_mixin.py:190} INFO - 19:20:57
[2025-05-22T19:20:57.994+0000] {logging_mixin.py:190} INFO - 19:20:57  Finished running 11 incremental models in 0 hours 0 minutes and 0.88 seconds (0.88s).
[2025-05-22T19:20:58.067+0000] {logging_mixin.py:190} INFO - 19:20:58
[2025-05-22T19:20:58.069+0000] {logging_mixin.py:190} INFO - 19:20:58  Completed with 1 error, 0 partial successes, and 0 warnings:
[2025-05-22T19:20:58.070+0000] {logging_mixin.py:190} INFO - 19:20:58
[2025-05-22T19:20:58.072+0000] {logging_mixin.py:190} INFO - 19:20:58    Database Error in model shopee_orders_results (models/core/shopee_orders_results.sql)
  syntax error at or near "AS"
  LINE 87: ...EXT), '_dbt_utils_surrogate_key_null_') as TEXT)) AS product...
                                                                ^
  compiled code at target/run/e_commerce_sales/models/core/shopee_orders_results.sql
[2025-05-22T19:20:58.073+0000] {logging_mixin.py:190} INFO - 19:20:58
[2025-05-22T19:20:58.075+0000] {logging_mixin.py:190} INFO - 19:20:58  Done. PASS=6 WARN=0 ERROR=1 SKIP=4 TOTAL=11
[2025-05-22T19:20:58.970+0000] {logging_mixin.py:190} INFO - dbt run failed!
[2025-05-22T19:20:58.971+0000] {logging_mixin.py:190} INFO - None
[2025-05-22T19:20:58.972+0000] {taskinstance.py:3311} ERROR - Task failed with exception
Traceback (most recent call last):
  File "/home/airflow/.local/lib/python3.9/site-packages/airflow/models/taskinstance.py", line 767, in _execute_task
    result = _execute_callable(context=context, **execute_callable_kwargs)
  File "/home/airflow/.local/lib/python3.9/site-packages/airflow/models/taskinstance.py", line 733, in _execute_callable
    return ExecutionCallableRunner(
  File "/home/airflow/.local/lib/python3.9/site-packages/airflow/utils/operator_helpers.py", line 252, in run
    return self.func(*args, **kwargs)
  File "/home/airflow/.local/lib/python3.9/site-packages/airflow/models/baseoperator.py", line 422, in wrapper
    return func(self, *args, **kwargs)
  File "/home/airflow/.local/lib/python3.9/site-packages/airflow/operators/python.py", line 238, in execute
    return_value = self.execute_callable()
  File "/home/airflow/.local/lib/python3.9/site-packages/airflow/operators/python.py", line 256, in execute_callable
    return runner.run(*self.op_args, **self.op_kwargs)
  File "/home/airflow/.local/lib/python3.9/site-packages/airflow/utils/operator_helpers.py", line 252, in run
    return self.func(*args, **kwargs)
  File "/opt/airflow/dbt/run_dbt.py", line 22, in transform_data
    raise RuntimeError("dbt run failed")
RuntimeError: dbt run failed
[2025-05-22T19:20:58.981+0000] {taskinstance.py:1225} INFO - Marking task as FAILED. dag_id=04_transform_data, task_id=run_dbt, run_id=manual__2025-05-22T19:20:44.447246+00:00, execution_date=20250522T192044, start_date=20250522T192053, end_date=20250522T192058
[2025-05-22T19:20:58.994+0000] {taskinstance.py:340} INFO - ::group::Post task execution logs
[2025-05-22T19:20:58.995+0000] {standard_task_runner.py:124} ERROR - Failed to execute job 220 for task run_dbt (dbt run failed; 4060)
Traceback (most recent call last):
  File "/home/airflow/.local/lib/python3.9/site-packages/airflow/task/task_runner/standard_task_runner.py", line 117, in _start_by_fork
    ret = args.func(args, dag=self.dag)
  File "/home/airflow/.local/lib/python3.9/site-packages/airflow/cli/cli_config.py", line 49, in command
    return func(*args, **kwargs)
  File "/home/airflow/.local/lib/python3.9/site-packages/airflow/utils/cli.py", line 116, in wrapper
    return f(*args, **kwargs)
  File "/home/airflow/.local/lib/python3.9/site-packages/airflow/cli/commands/task_command.py", line 483, in task_run
    task_return_code = _run_task_by_selected_method(args, _dag, ti)
  File "/home/airflow/.local/lib/python3.9/site-packages/airflow/cli/commands/task_command.py", line 256, in _run_task_by_selected_method
    return _run_raw_task(args, ti)
  File "/home/airflow/.local/lib/python3.9/site-packages/airflow/cli/commands/task_command.py", line 341, in _run_raw_task
    return ti._run_raw_task(
  File "/home/airflow/.local/lib/python3.9/site-packages/airflow/utils/session.py", line 97, in wrapper
    return func(*args, session=session, **kwargs)
  File "/home/airflow/.local/lib/python3.9/site-packages/airflow/models/taskinstance.py", line 3005, in _run_raw_task
    return _run_raw_task(
  File "/home/airflow/.local/lib/python3.9/site-packages/airflow/models/taskinstance.py", line 273, in _run_raw_task
    TaskInstance._execute_task_with_callbacks(
  File "/home/airflow/.local/lib/python3.9/site-packages/airflow/models/taskinstance.py", line 3159, in _execute_task_with_callbacks
    result = self._execute_task(context, task_orig)
  File "/home/airflow/.local/lib/python3.9/site-packages/airflow/models/taskinstance.py", line 3183, in _execute_task
    return _execute_task(self, context, task_orig)
  File "/home/airflow/.local/lib/python3.9/site-packages/airflow/models/taskinstance.py", line 767, in _execute_task
    result = _execute_callable(context=context, **execute_callable_kwargs)
  File "/home/airflow/.local/lib/python3.9/site-packages/airflow/models/taskinstance.py", line 733, in _execute_callable
    return ExecutionCallableRunner(
  File "/home/airflow/.local/lib/python3.9/site-packages/airflow/utils/operator_helpers.py", line 252, in run
    return self.func(*args, **kwargs)
  File "/home/airflow/.local/lib/python3.9/site-packages/airflow/models/baseoperator.py", line 422, in wrapper
    return func(self, *args, **kwargs)
  File "/home/airflow/.local/lib/python3.9/site-packages/airflow/operators/python.py", line 238, in execute
    return_value = self.execute_callable()
  File "/home/airflow/.local/lib/python3.9/site-packages/airflow/operators/python.py", line 256, in execute_callable
    return runner.run(*self.op_args, **self.op_kwargs)
  File "/home/airflow/.local/lib/python3.9/site-packages/airflow/utils/operator_helpers.py", line 252, in run
    return self.func(*args, **kwargs)
  File "/opt/airflow/dbt/run_dbt.py", line 22, in transform_data
    raise RuntimeError("dbt run failed")
RuntimeError: dbt run failed
[2025-05-22T19:20:59.039+0000] {local_task_job_runner.py:266} INFO - Task exited with return code 1
[2025-05-22T19:20:59.058+0000] {taskinstance.py:3895} INFO - 0 downstream tasks scheduled from follow-on schedule check
[2025-05-22T19:20:59.061+0000] {local_task_job_runner.py:245} INFO - ::endgroup::
