[2025-05-22T14:17:48.845+0000] {local_task_job_runner.py:123} INFO - ::group::Pre task execution logs
[2025-05-22T14:17:48.863+0000] {taskinstance.py:2613} INFO - Dependencies all met for dep_context=non-requeueable deps ti=<TaskInstance: 04_transform_data.run_dbt manual__2025-05-22T14:17:46.317804+00:00 [queued]>
[2025-05-22T14:17:48.871+0000] {taskinstance.py:2613} INFO - Dependencies all met for dep_context=requeueable deps ti=<TaskInstance: 04_transform_data.run_dbt manual__2025-05-22T14:17:46.317804+00:00 [queued]>
[2025-05-22T14:17:48.873+0000] {taskinstance.py:2866} INFO - Starting attempt 1 of 1
[2025-05-22T14:17:48.886+0000] {taskinstance.py:2889} INFO - Executing <Task(PythonOperator): run_dbt> on 2025-05-22 14:17:46.317804+00:00
[2025-05-22T14:17:48.891+0000] {standard_task_runner.py:72} INFO - Started process 879 to run task
[2025-05-22T14:17:48.894+0000] {standard_task_runner.py:104} INFO - Running: ['***', 'tasks', 'run', '04_transform_data', 'run_dbt', 'manual__2025-05-22T14:17:46.317804+00:00', '--job-id', '177', '--raw', '--subdir', 'DAGS_FOLDER/04_transform_data.py', '--cfg-path', '/tmp/tmpr55t_ulb']
[2025-05-22T14:17:48.896+0000] {standard_task_runner.py:105} INFO - Job 177: Subtask run_dbt
[2025-05-22T14:17:48.949+0000] {task_command.py:467} INFO - Running <TaskInstance: 04_transform_data.run_dbt manual__2025-05-22T14:17:46.317804+00:00 [running]> on host e27e96d1841a
[2025-05-22T14:17:49.037+0000] {taskinstance.py:3132} INFO - Exporting env vars: AIRFLOW_CTX_DAG_OWNER='***' AIRFLOW_CTX_DAG_ID='04_transform_data' AIRFLOW_CTX_TASK_ID='run_dbt' AIRFLOW_CTX_EXECUTION_DATE='2025-05-22T14:17:46.317804+00:00' AIRFLOW_CTX_TRY_NUMBER='1' AIRFLOW_CTX_DAG_RUN_ID='manual__2025-05-22T14:17:46.317804+00:00'
[2025-05-22T14:17:49.039+0000] {taskinstance.py:731} INFO - ::endgroup::
[2025-05-22T14:17:50.708+0000] {logging_mixin.py:190} INFO - 14:17:50  Running with dbt=1.9.4
[2025-05-22T14:17:51.100+0000] {logging_mixin.py:190} INFO - 14:17:51  Registered adapter: postgres=1.9.0
[2025-05-22T14:17:52.282+0000] {logging_mixin.py:190} INFO - 14:17:52  [WARNING]: Configuration paths exist in your dbt_project.yml file which do not apply to any resources.
There are 1 unused configuration paths:
- models.e_commerce_sales.example
[2025-05-22T14:17:52.460+0000] {logging_mixin.py:190} INFO - 14:17:52  Found 12 models, 12 sources, 433 macros
[2025-05-22T14:17:52.464+0000] {logging_mixin.py:190} INFO - 14:17:52
[2025-05-22T14:17:52.466+0000] {logging_mixin.py:190} INFO - 14:17:52  Concurrency: 4 threads (target='dev')
[2025-05-22T14:17:52.468+0000] {logging_mixin.py:190} INFO - 14:17:52
[2025-05-22T14:17:52.600+0000] {logging_mixin.py:190} INFO - 14:17:52  1 of 12 START sql incremental model sales.mercadolivre_orders_results .......... [RUN]
[2025-05-22T14:17:52.603+0000] {logging_mixin.py:190} INFO - 14:17:52  2 of 12 START sql incremental model sales.shopee_new_id ........................ [RUN]
[2025-05-22T14:17:52.828+0000] {logging_mixin.py:190} INFO - 14:17:52  1 of 12 ERROR creating sql incremental model sales.mercadolivre_orders_results . [ERROR in 0.21s]
[2025-05-22T14:17:52.849+0000] {logging_mixin.py:190} INFO - 14:17:52  3 of 12 SKIP relation sales.dim_mercadolivre_buyer ............................. [SKIP]
[2025-05-22T14:17:52.851+0000] {logging_mixin.py:190} INFO - 14:17:52  4 of 12 SKIP relation sales.dim_mercadolivre_date .............................. [SKIP]
[2025-05-22T14:17:52.852+0000] {logging_mixin.py:190} INFO - 14:17:52  5 of 12 SKIP relation sales.dim_mercadolivre_orders_status ..................... [SKIP]
[2025-05-22T14:17:52.862+0000] {logging_mixin.py:190} INFO - 14:17:52  6 of 12 SKIP relation sales.dim_mercadolivre_product ........................... [SKIP]
[2025-05-22T14:17:52.885+0000] {logging_mixin.py:190} INFO - 14:17:52  7 of 12 SKIP relation sales.mercadolivre_profits ............................... [SKIP]
[2025-05-22T14:17:52.948+0000] {logging_mixin.py:190} INFO - 14:17:52  2 of 12 OK created sql incremental model sales.shopee_new_id ................... [MERGE 0 in 0.34s]
[2025-05-22T14:17:52.954+0000] {logging_mixin.py:190} INFO - 14:17:52  8 of 12 START sql incremental model sales.shopee_orders_results ................ [RUN]
[2025-05-22T14:17:53.070+0000] {logging_mixin.py:190} INFO - 14:17:53  8 of 12 OK created sql incremental model sales.shopee_orders_results ........... [MERGE 0 in 0.11s]
[2025-05-22T14:17:53.077+0000] {logging_mixin.py:190} INFO - 14:17:53  9 of 12 START sql incremental model sales.dim_shopee_buyer_id .................. [RUN]
[2025-05-22T14:17:53.078+0000] {logging_mixin.py:190} INFO - 14:17:53  10 of 12 START sql incremental model sales.dim_shopee_date ..................... [RUN]
[2025-05-22T14:17:53.080+0000] {logging_mixin.py:190} INFO - 14:17:53  11 of 12 START sql incremental model sales.dim_shopee_orders_status ............ [RUN]
[2025-05-22T14:17:53.082+0000] {logging_mixin.py:190} INFO - 14:17:53  12 of 12 START sql incremental model sales.dim_shopee_product .................. [RUN]
[2025-05-22T14:17:53.343+0000] {logging_mixin.py:190} INFO - 14:17:53  9 of 12 OK created sql incremental model sales.dim_shopee_buyer_id ............. [MERGE 0 in 0.26s]
[2025-05-22T14:17:53.356+0000] {logging_mixin.py:190} INFO - 14:17:53  11 of 12 OK created sql incremental model sales.dim_shopee_orders_status ....... [MERGE 0 in 0.27s]
[2025-05-22T14:17:53.359+0000] {logging_mixin.py:190} INFO - 14:17:53  12 of 12 OK created sql incremental model sales.dim_shopee_product ............. [MERGE 0 in 0.27s]
[2025-05-22T14:17:53.362+0000] {logging_mixin.py:190} INFO - 14:17:53  10 of 12 OK created sql incremental model sales.dim_shopee_date ................ [MERGE 0 in 0.27s]
[2025-05-22T14:17:53.387+0000] {logging_mixin.py:190} INFO - 14:17:53
[2025-05-22T14:17:53.388+0000] {logging_mixin.py:190} INFO - 14:17:53  Finished running 12 incremental models in 0 hours 0 minutes and 0.92 seconds (0.92s).
[2025-05-22T14:17:53.455+0000] {logging_mixin.py:190} INFO - 14:17:53
[2025-05-22T14:17:53.457+0000] {logging_mixin.py:190} INFO - 14:17:53  Completed with 1 error, 0 partial successes, and 0 warnings:
[2025-05-22T14:17:53.459+0000] {logging_mixin.py:190} INFO - 14:17:53
[2025-05-22T14:17:53.460+0000] {logging_mixin.py:190} INFO - 14:17:53    Database Error in model mercadolivre_orders_results (models/core/mercadolivre_orders_results.sql)
  column payments.sh_cost does not exist
  LINE 42:      SUM(payments.sh_cost) AS agg_sh_cost,
                    ^
  compiled code at target/run/e_commerce_sales/models/core/mercadolivre_orders_results.sql
[2025-05-22T14:17:53.462+0000] {logging_mixin.py:190} INFO - 14:17:53
[2025-05-22T14:17:53.463+0000] {logging_mixin.py:190} INFO - 14:17:53  Done. PASS=6 WARN=0 ERROR=1 SKIP=5 TOTAL=12
[2025-05-22T14:17:54.474+0000] {logging_mixin.py:190} INFO - dbt run failed!
[2025-05-22T14:17:54.478+0000] {logging_mixin.py:190} INFO - None
[2025-05-22T14:17:54.480+0000] {taskinstance.py:3311} ERROR - Task failed with exception
Traceback (most recent call last):
  File "/home/airflow/.local/lib/python3.9/site-packages/airflow/models/taskinstance.py", line 767, in _execute_task
    result = _execute_callable(context=context, **execute_callable_kwargs)
  File "/home/airflow/.local/lib/python3.9/site-packages/airflow/models/taskinstance.py", line 733, in _execute_callable
    return ExecutionCallableRunner(
  File "/home/airflow/.local/lib/python3.9/site-packages/airflow/utils/operator_helpers.py", line 252, in run
    return self.func(*args, **kwargs)
  File "/home/airflow/.local/lib/python3.9/site-packages/airflow/models/baseoperator.py", line 422, in wrapper
    return func(self, *args, **kwargs)
  File "/home/airflow/.local/lib/python3.9/site-packages/airflow/operators/python.py", line 238, in execute
    return_value = self.execute_callable()
  File "/home/airflow/.local/lib/python3.9/site-packages/airflow/operators/python.py", line 256, in execute_callable
    return runner.run(*self.op_args, **self.op_kwargs)
  File "/home/airflow/.local/lib/python3.9/site-packages/airflow/utils/operator_helpers.py", line 252, in run
    return self.func(*args, **kwargs)
  File "/opt/airflow/dbt/run_dbt.py", line 22, in transform_data
    raise RuntimeError("dbt run failed")
RuntimeError: dbt run failed
[2025-05-22T14:17:54.491+0000] {taskinstance.py:1225} INFO - Marking task as FAILED. dag_id=04_transform_data, task_id=run_dbt, run_id=manual__2025-05-22T14:17:46.317804+00:00, execution_date=20250522T141746, start_date=20250522T141748, end_date=20250522T141754
[2025-05-22T14:17:54.505+0000] {taskinstance.py:340} INFO - ::group::Post task execution logs
[2025-05-22T14:17:54.506+0000] {standard_task_runner.py:124} ERROR - Failed to execute job 177 for task run_dbt (dbt run failed; 879)
Traceback (most recent call last):
  File "/home/airflow/.local/lib/python3.9/site-packages/airflow/task/task_runner/standard_task_runner.py", line 117, in _start_by_fork
    ret = args.func(args, dag=self.dag)
  File "/home/airflow/.local/lib/python3.9/site-packages/airflow/cli/cli_config.py", line 49, in command
    return func(*args, **kwargs)
  File "/home/airflow/.local/lib/python3.9/site-packages/airflow/utils/cli.py", line 116, in wrapper
    return f(*args, **kwargs)
  File "/home/airflow/.local/lib/python3.9/site-packages/airflow/cli/commands/task_command.py", line 483, in task_run
    task_return_code = _run_task_by_selected_method(args, _dag, ti)
  File "/home/airflow/.local/lib/python3.9/site-packages/airflow/cli/commands/task_command.py", line 256, in _run_task_by_selected_method
    return _run_raw_task(args, ti)
  File "/home/airflow/.local/lib/python3.9/site-packages/airflow/cli/commands/task_command.py", line 341, in _run_raw_task
    return ti._run_raw_task(
  File "/home/airflow/.local/lib/python3.9/site-packages/airflow/utils/session.py", line 97, in wrapper
    return func(*args, session=session, **kwargs)
  File "/home/airflow/.local/lib/python3.9/site-packages/airflow/models/taskinstance.py", line 3005, in _run_raw_task
    return _run_raw_task(
  File "/home/airflow/.local/lib/python3.9/site-packages/airflow/models/taskinstance.py", line 273, in _run_raw_task
    TaskInstance._execute_task_with_callbacks(
  File "/home/airflow/.local/lib/python3.9/site-packages/airflow/models/taskinstance.py", line 3159, in _execute_task_with_callbacks
    result = self._execute_task(context, task_orig)
  File "/home/airflow/.local/lib/python3.9/site-packages/airflow/models/taskinstance.py", line 3183, in _execute_task
    return _execute_task(self, context, task_orig)
  File "/home/airflow/.local/lib/python3.9/site-packages/airflow/models/taskinstance.py", line 767, in _execute_task
    result = _execute_callable(context=context, **execute_callable_kwargs)
  File "/home/airflow/.local/lib/python3.9/site-packages/airflow/models/taskinstance.py", line 733, in _execute_callable
    return ExecutionCallableRunner(
  File "/home/airflow/.local/lib/python3.9/site-packages/airflow/utils/operator_helpers.py", line 252, in run
    return self.func(*args, **kwargs)
  File "/home/airflow/.local/lib/python3.9/site-packages/airflow/models/baseoperator.py", line 422, in wrapper
    return func(self, *args, **kwargs)
  File "/home/airflow/.local/lib/python3.9/site-packages/airflow/operators/python.py", line 238, in execute
    return_value = self.execute_callable()
  File "/home/airflow/.local/lib/python3.9/site-packages/airflow/operators/python.py", line 256, in execute_callable
    return runner.run(*self.op_args, **self.op_kwargs)
  File "/home/airflow/.local/lib/python3.9/site-packages/airflow/utils/operator_helpers.py", line 252, in run
    return self.func(*args, **kwargs)
  File "/opt/airflow/dbt/run_dbt.py", line 22, in transform_data
    raise RuntimeError("dbt run failed")
RuntimeError: dbt run failed
[2025-05-22T14:17:54.534+0000] {local_task_job_runner.py:266} INFO - Task exited with return code 1
[2025-05-22T14:17:54.552+0000] {taskinstance.py:3895} INFO - 0 downstream tasks scheduled from follow-on schedule check
[2025-05-22T14:17:54.554+0000] {local_task_job_runner.py:245} INFO - ::endgroup::
