[2025-06-09T20:12:53.228+0000] {local_task_job_runner.py:123} INFO - ::group::Pre task execution logs
[2025-06-09T20:12:53.247+0000] {taskinstance.py:2613} INFO - Dependencies all met for dep_context=non-requeueable deps ti=<TaskInstance: 05_transform_data.run_dbt manual__2025-06-09T20:12:43.029750+00:00 [queued]>
[2025-06-09T20:12:53.256+0000] {taskinstance.py:2613} INFO - Dependencies all met for dep_context=requeueable deps ti=<TaskInstance: 05_transform_data.run_dbt manual__2025-06-09T20:12:43.029750+00:00 [queued]>
[2025-06-09T20:12:53.258+0000] {taskinstance.py:2866} INFO - Starting attempt 1 of 1
[2025-06-09T20:12:53.271+0000] {taskinstance.py:2889} INFO - Executing <Task(PythonOperator): run_dbt> on 2025-06-09 20:12:43.029750+00:00
[2025-06-09T20:12:53.276+0000] {standard_task_runner.py:72} INFO - Started process 2437 to run task
[2025-06-09T20:12:53.280+0000] {standard_task_runner.py:104} INFO - Running: ['***', 'tasks', 'run', '05_transform_data', 'run_dbt', 'manual__2025-06-09T20:12:43.029750+00:00', '--job-id', '557', '--raw', '--subdir', 'DAGS_FOLDER/05_transform_data.py', '--cfg-path', '/tmp/tmpiab5xg0f']
[2025-06-09T20:12:53.282+0000] {standard_task_runner.py:105} INFO - Job 557: Subtask run_dbt
[2025-06-09T20:12:53.335+0000] {task_command.py:467} INFO - Running <TaskInstance: 05_transform_data.run_dbt manual__2025-06-09T20:12:43.029750+00:00 [running]> on host 28e6a58e4107
[2025-06-09T20:12:53.417+0000] {taskinstance.py:3132} INFO - Exporting env vars: AIRFLOW_CTX_DAG_OWNER='***' AIRFLOW_CTX_DAG_ID='05_transform_data' AIRFLOW_CTX_TASK_ID='run_dbt' AIRFLOW_CTX_EXECUTION_DATE='2025-06-09T20:12:43.029750+00:00' AIRFLOW_CTX_TRY_NUMBER='1' AIRFLOW_CTX_DAG_RUN_ID='manual__2025-06-09T20:12:43.029750+00:00'
[2025-06-09T20:12:53.418+0000] {taskinstance.py:731} INFO - ::endgroup::
[2025-06-09T20:12:55.005+0000] {logging_mixin.py:190} INFO - 20:12:55  Running with dbt=1.9.5
[2025-06-09T20:12:55.380+0000] {logging_mixin.py:190} INFO - 20:12:55  Registered adapter: postgres=1.9.0
[2025-06-09T20:12:55.857+0000] {logging_mixin.py:190} INFO - 20:12:55  Unable to do partial parsing because a project config has changed
[2025-06-09T20:12:58.773+0000] {logging_mixin.py:190} INFO - 20:12:58  Encountered an error:
Compilation Error
  Model 'model.e_commerce_sales.dim_mercadolivre_buyer' (models/core/dim_mercadolivre_buyer.sql) depends on a source named 'entry_ml.stg_mercadolivre' which was not found
[2025-06-09T20:12:59.510+0000] {logging_mixin.py:190} INFO - dbt run failed!
[2025-06-09T20:12:59.512+0000] {logging_mixin.py:190} INFO - Compilation Error
  Model 'model.e_commerce_sales.dim_mercadolivre_buyer' (models/core/dim_mercadolivre_buyer.sql) depends on a source named 'entry_ml.stg_mercadolivre' which was not found
[2025-06-09T20:12:59.513+0000] {taskinstance.py:3311} ERROR - Task failed with exception
Traceback (most recent call last):
  File "/home/airflow/.local/lib/python3.9/site-packages/airflow/models/taskinstance.py", line 767, in _execute_task
    result = _execute_callable(context=context, **execute_callable_kwargs)
  File "/home/airflow/.local/lib/python3.9/site-packages/airflow/models/taskinstance.py", line 733, in _execute_callable
    return ExecutionCallableRunner(
  File "/home/airflow/.local/lib/python3.9/site-packages/airflow/utils/operator_helpers.py", line 252, in run
    return self.func(*args, **kwargs)
  File "/home/airflow/.local/lib/python3.9/site-packages/airflow/models/baseoperator.py", line 422, in wrapper
    return func(self, *args, **kwargs)
  File "/home/airflow/.local/lib/python3.9/site-packages/airflow/operators/python.py", line 238, in execute
    return_value = self.execute_callable()
  File "/home/airflow/.local/lib/python3.9/site-packages/airflow/operators/python.py", line 256, in execute_callable
    return runner.run(*self.op_args, **self.op_kwargs)
  File "/home/airflow/.local/lib/python3.9/site-packages/airflow/utils/operator_helpers.py", line 252, in run
    return self.func(*args, **kwargs)
  File "/opt/airflow/dbt_files/run_dbt.py", line 22, in transform_data
    raise RuntimeError("dbt run failed")
RuntimeError: dbt run failed
[2025-06-09T20:12:59.525+0000] {taskinstance.py:1225} INFO - Marking task as FAILED. dag_id=05_transform_data, task_id=run_dbt, run_id=manual__2025-06-09T20:12:43.029750+00:00, execution_date=20250609T201243, start_date=20250609T201253, end_date=20250609T201259
[2025-06-09T20:12:59.537+0000] {taskinstance.py:340} INFO - ::group::Post task execution logs
[2025-06-09T20:12:59.538+0000] {standard_task_runner.py:124} ERROR - Failed to execute job 557 for task run_dbt (dbt run failed; 2437)
Traceback (most recent call last):
  File "/home/airflow/.local/lib/python3.9/site-packages/airflow/task/task_runner/standard_task_runner.py", line 117, in _start_by_fork
    ret = args.func(args, dag=self.dag)
  File "/home/airflow/.local/lib/python3.9/site-packages/airflow/cli/cli_config.py", line 49, in command
    return func(*args, **kwargs)
  File "/home/airflow/.local/lib/python3.9/site-packages/airflow/utils/cli.py", line 116, in wrapper
    return f(*args, **kwargs)
  File "/home/airflow/.local/lib/python3.9/site-packages/airflow/cli/commands/task_command.py", line 483, in task_run
    task_return_code = _run_task_by_selected_method(args, _dag, ti)
  File "/home/airflow/.local/lib/python3.9/site-packages/airflow/cli/commands/task_command.py", line 256, in _run_task_by_selected_method
    return _run_raw_task(args, ti)
  File "/home/airflow/.local/lib/python3.9/site-packages/airflow/cli/commands/task_command.py", line 341, in _run_raw_task
    return ti._run_raw_task(
  File "/home/airflow/.local/lib/python3.9/site-packages/airflow/utils/session.py", line 97, in wrapper
    return func(*args, session=session, **kwargs)
  File "/home/airflow/.local/lib/python3.9/site-packages/airflow/models/taskinstance.py", line 3005, in _run_raw_task
    return _run_raw_task(
  File "/home/airflow/.local/lib/python3.9/site-packages/airflow/models/taskinstance.py", line 273, in _run_raw_task
    TaskInstance._execute_task_with_callbacks(
  File "/home/airflow/.local/lib/python3.9/site-packages/airflow/models/taskinstance.py", line 3159, in _execute_task_with_callbacks
    result = self._execute_task(context, task_orig)
  File "/home/airflow/.local/lib/python3.9/site-packages/airflow/models/taskinstance.py", line 3183, in _execute_task
    return _execute_task(self, context, task_orig)
  File "/home/airflow/.local/lib/python3.9/site-packages/airflow/models/taskinstance.py", line 767, in _execute_task
    result = _execute_callable(context=context, **execute_callable_kwargs)
  File "/home/airflow/.local/lib/python3.9/site-packages/airflow/models/taskinstance.py", line 733, in _execute_callable
    return ExecutionCallableRunner(
  File "/home/airflow/.local/lib/python3.9/site-packages/airflow/utils/operator_helpers.py", line 252, in run
    return self.func(*args, **kwargs)
  File "/home/airflow/.local/lib/python3.9/site-packages/airflow/models/baseoperator.py", line 422, in wrapper
    return func(self, *args, **kwargs)
  File "/home/airflow/.local/lib/python3.9/site-packages/airflow/operators/python.py", line 238, in execute
    return_value = self.execute_callable()
  File "/home/airflow/.local/lib/python3.9/site-packages/airflow/operators/python.py", line 256, in execute_callable
    return runner.run(*self.op_args, **self.op_kwargs)
  File "/home/airflow/.local/lib/python3.9/site-packages/airflow/utils/operator_helpers.py", line 252, in run
    return self.func(*args, **kwargs)
  File "/opt/airflow/dbt_files/run_dbt.py", line 22, in transform_data
    raise RuntimeError("dbt run failed")
RuntimeError: dbt run failed
[2025-06-09T20:12:59.557+0000] {local_task_job_runner.py:266} INFO - Task exited with return code 1
[2025-06-09T20:12:59.574+0000] {taskinstance.py:3895} INFO - 0 downstream tasks scheduled from follow-on schedule check
[2025-06-09T20:12:59.577+0000] {local_task_job_runner.py:245} INFO - ::endgroup::
