[2025-06-11T22:07:57.823+0000] {local_task_job_runner.py:123} INFO - ::group::Pre task execution logs
[2025-06-11T22:07:57.842+0000] {taskinstance.py:2613} INFO - Dependencies all met for dep_context=non-requeueable deps ti=<TaskInstance: 05_transform_data_dev.run_dbt manual__2025-06-11T22:07:48.225357+00:00 [queued]>
[2025-06-11T22:07:57.851+0000] {taskinstance.py:2613} INFO - Dependencies all met for dep_context=requeueable deps ti=<TaskInstance: 05_transform_data_dev.run_dbt manual__2025-06-11T22:07:48.225357+00:00 [queued]>
[2025-06-11T22:07:57.852+0000] {taskinstance.py:2866} INFO - Starting attempt 1 of 1
[2025-06-11T22:07:57.864+0000] {taskinstance.py:2889} INFO - Executing <Task(PythonOperator): run_dbt> on 2025-06-11 22:07:48.225357+00:00
[2025-06-11T22:07:57.868+0000] {standard_task_runner.py:72} INFO - Started process 4155 to run task
[2025-06-11T22:07:57.871+0000] {standard_task_runner.py:104} INFO - Running: ['***', 'tasks', 'run', '05_transform_data_dev', 'run_dbt', 'manual__2025-06-11T22:07:48.225357+00:00', '--job-id', '928', '--raw', '--subdir', 'DAGS_FOLDER/05_transform_data_dev.py', '--cfg-path', '/tmp/tmplzltxioe']
[2025-06-11T22:07:57.873+0000] {standard_task_runner.py:105} INFO - Job 928: Subtask run_dbt
[2025-06-11T22:07:57.923+0000] {task_command.py:467} INFO - Running <TaskInstance: 05_transform_data_dev.run_dbt manual__2025-06-11T22:07:48.225357+00:00 [running]> on host 28e6a58e4107
[2025-06-11T22:07:57.998+0000] {taskinstance.py:3132} INFO - Exporting env vars: AIRFLOW_CTX_DAG_OWNER='***' AIRFLOW_CTX_DAG_ID='05_transform_data_dev' AIRFLOW_CTX_TASK_ID='run_dbt' AIRFLOW_CTX_EXECUTION_DATE='2025-06-11T22:07:48.225357+00:00' AIRFLOW_CTX_TRY_NUMBER='1' AIRFLOW_CTX_DAG_RUN_ID='manual__2025-06-11T22:07:48.225357+00:00'
[2025-06-11T22:07:58.000+0000] {taskinstance.py:731} INFO - ::endgroup::
[2025-06-11T22:07:59.595+0000] {logging_mixin.py:190} INFO - 22:07:59  Running with dbt=1.9.5
[2025-06-11T22:07:59.970+0000] {logging_mixin.py:190} INFO - 22:07:59  Registered adapter: postgres=1.9.0
[2025-06-11T22:08:00.485+0000] {logging_mixin.py:190} INFO - 22:08:00  Unable to do partial parsing because config vars, config profile, or config target have changed
[2025-06-11T22:08:00.490+0000] {logging_mixin.py:190} INFO - 22:08:00  Unable to do partial parsing because profile has changed
[2025-06-11T22:08:03.648+0000] {logging_mixin.py:190} INFO - 22:08:03  [WARNING]: Configuration paths exist in your dbt_project.yml file which do not apply to any resources.
There are 1 unused configuration paths:
- models.e_commerce_sales.example
[2025-06-11T22:08:03.843+0000] {logging_mixin.py:190} INFO - 22:08:03  Found 21 models, 12 sources, 549 macros, 1 unit test
[2025-06-11T22:08:03.847+0000] {logging_mixin.py:190} INFO - 22:08:03
[2025-06-11T22:08:03.849+0000] {logging_mixin.py:190} INFO - 22:08:03  Concurrency: 4 threads (target='dev')
[2025-06-11T22:08:03.850+0000] {logging_mixin.py:190} INFO - 22:08:03
[2025-06-11T22:08:04.048+0000] {logging_mixin.py:190} INFO - 22:08:04  1 of 21 START sql incremental model sales_stg.stg_mercadolivre ................. [RUN]
[2025-06-11T22:08:04.049+0000] {logging_mixin.py:190} INFO - 22:08:04  2 of 21 START sql incremental model sales_stg.stg_mercadolivre__order_items .... [RUN]
[2025-06-11T22:08:04.051+0000] {logging_mixin.py:190} INFO - 22:08:04  3 of 21 START sql incremental model sales_stg.stg_mercadolivre__payments ....... [RUN]
[2025-06-11T22:08:04.052+0000] {logging_mixin.py:190} INFO - 22:08:04  4 of 21 START sql incremental model sales_stg.stg_mercadolivre_sh .............. [RUN]
[2025-06-11T22:08:04.286+0000] {logging_mixin.py:190} INFO - 22:08:04  1 of 21 ERROR creating sql incremental model sales_stg.stg_mercadolivre ........ [ERROR in 0.23s]
[2025-06-11T22:08:04.288+0000] {logging_mixin.py:190} INFO - 22:08:04  4 of 21 ERROR creating sql incremental model sales_stg.stg_mercadolivre_sh ..... [ERROR in 0.23s]
[2025-06-11T22:08:04.290+0000] {logging_mixin.py:190} INFO - 22:08:04  2 of 21 ERROR creating sql incremental model sales_stg.stg_mercadolivre__order_items  [ERROR in 0.23s]
[2025-06-11T22:08:04.292+0000] {logging_mixin.py:190} INFO - 22:08:04  3 of 21 ERROR creating sql incremental model sales_stg.stg_mercadolivre__payments  [ERROR in 0.23s]
[2025-06-11T22:08:04.301+0000] {logging_mixin.py:190} INFO - 22:08:04  5 of 21 START sql incremental model sales_stg.stg_shopee ....................... [RUN]
[2025-06-11T22:08:04.318+0000] {logging_mixin.py:190} INFO - 22:08:04  6 of 21 SKIP relation sales.mercadolivre_orders_results ........................ [SKIP]
[2025-06-11T22:08:04.324+0000] {logging_mixin.py:190} INFO - 22:08:04  7 of 21 SKIP relation sales.dim_mercadolivre_buyer ............................. [SKIP]
[2025-06-11T22:08:04.326+0000] {logging_mixin.py:190} INFO - 22:08:04  8 of 21 SKIP relation sales.dim_mercadolivre_date .............................. [SKIP]
[2025-06-11T22:08:04.328+0000] {logging_mixin.py:190} INFO - 22:08:04  9 of 21 SKIP relation sales.dim_mercadolivre_orders_status ..................... [SKIP]
[2025-06-11T22:08:04.345+0000] {logging_mixin.py:190} INFO - 22:08:04  10 of 21 SKIP relation sales.dim_mercadolivre_product .......................... [SKIP]
[2025-06-11T22:08:04.348+0000] {logging_mixin.py:190} INFO - 22:08:04  11 of 21 SKIP relation sales.sum_mercadolivre_monthly_profit ................... [SKIP]
[2025-06-11T22:08:04.352+0000] {logging_mixin.py:190} INFO - 22:08:04  12 of 21 SKIP relation sales.sum_mercadolivre_monthly_revenue .................. [SKIP]
[2025-06-11T22:08:04.357+0000] {logging_mixin.py:190} INFO - 22:08:04  13 of 21 SKIP relation sales.sum_mercadolivre_monthly_sold ..................... [SKIP]
[2025-06-11T22:08:04.376+0000] {logging_mixin.py:190} INFO - 22:08:04  5 of 21 ERROR creating sql incremental model sales_stg.stg_shopee .............. [ERROR in 0.07s]
[2025-06-11T22:08:04.382+0000] {logging_mixin.py:190} INFO - 22:08:04  14 of 21 SKIP relation sales.shopee_orders_results ............................. [SKIP]
[2025-06-11T22:08:04.388+0000] {logging_mixin.py:190} INFO - 22:08:04  15 of 21 SKIP relation sales.dim_shopee_buyer .................................. [SKIP]
[2025-06-11T22:08:04.389+0000] {logging_mixin.py:190} INFO - 22:08:04  16 of 21 SKIP relation sales.dim_shopee_date ................................... [SKIP]
[2025-06-11T22:08:04.391+0000] {logging_mixin.py:190} INFO - 22:08:04  17 of 21 SKIP relation sales.dim_shopee_orders_status .......................... [SKIP]
[2025-06-11T22:08:04.393+0000] {logging_mixin.py:190} INFO - 22:08:04  18 of 21 SKIP relation sales.dim_shopee_product ................................ [SKIP]
[2025-06-11T22:08:04.402+0000] {logging_mixin.py:190} INFO - 22:08:04  19 of 21 SKIP relation sales.sum_shopee_monthly_profit ......................... [SKIP]
[2025-06-11T22:08:04.403+0000] {logging_mixin.py:190} INFO - 22:08:04  20 of 21 SKIP relation sales.sum_shopee_monthly_revenue ........................ [SKIP]
[2025-06-11T22:08:04.404+0000] {logging_mixin.py:190} INFO - 22:08:04  21 of 21 SKIP relation sales.sum_shopee_products_sold .......................... [SKIP]
[2025-06-11T22:08:04.430+0000] {logging_mixin.py:190} INFO - 22:08:04
[2025-06-11T22:08:04.431+0000] {logging_mixin.py:190} INFO - 22:08:04  Finished running 15 incremental models, 6 view models in 0 hours 0 minutes and 0.58 seconds (0.58s).
[2025-06-11T22:08:04.509+0000] {logging_mixin.py:190} INFO - 22:08:04
[2025-06-11T22:08:04.512+0000] {logging_mixin.py:190} INFO - 22:08:04  Completed with 5 errors, 0 partial successes, and 0 warnings:
[2025-06-11T22:08:04.513+0000] {logging_mixin.py:190} INFO - 22:08:04
[2025-06-11T22:08:04.515+0000] {logging_mixin.py:190} INFO - 22:08:04    Database Error in model stg_mercadolivre (models/staging/stg_mercadolivre.sql)
  cross-database references are not implemented: "sales_db.entry.entry_mercadolivre"
  LINE 53:         FROM "sales_db"."entry"."entry_mercadolivre", max_ti...
                        ^
  compiled code at target/run/e_commerce_sales/models/staging/stg_mercadolivre.sql
[2025-06-11T22:08:04.516+0000] {logging_mixin.py:190} INFO - 22:08:04
[2025-06-11T22:08:04.517+0000] {logging_mixin.py:190} INFO - 22:08:04    Database Error in model stg_mercadolivre_sh (models/staging/stg_mercadolivre_sh.sql)
  cross-database references are not implemented: "sales_db.entry.entry_mercadolivre_sh"
  LINE 117:         FROM "sales_db"."entry"."entry_mercadolivre_sh", max...
                         ^
  compiled code at target/run/e_commerce_sales/models/staging/stg_mercadolivre_sh.sql
[2025-06-11T22:08:04.519+0000] {logging_mixin.py:190} INFO - 22:08:04
[2025-06-11T22:08:04.520+0000] {logging_mixin.py:190} INFO - 22:08:04    Database Error in model stg_mercadolivre__order_items (models/staging/stg_mercadolivre__order_items.sql)
  cross-database references are not implemented: "sales_db.entry.entry_mercadolivre__order_items"
  LINE 39:         FROM "sales_db"."entry"."entry_mercadolivre__order_i...
                        ^
  compiled code at target/run/e_commerce_sales/models/staging/stg_mercadolivre__order_items.sql
[2025-06-11T22:08:04.521+0000] {logging_mixin.py:190} INFO - 22:08:04
[2025-06-11T22:08:04.523+0000] {logging_mixin.py:190} INFO - 22:08:04    Database Error in model stg_mercadolivre__payments (models/staging/stg_mercadolivre__payments.sql)
  cross-database references are not implemented: "sales_db.entry.entry_mercadolivre__payments"
  LINE 54:         FROM "sales_db"."entry"."entry_mercadolivre__payment...
                        ^
  compiled code at target/run/e_commerce_sales/models/staging/stg_mercadolivre__payments.sql
[2025-06-11T22:08:04.524+0000] {logging_mixin.py:190} INFO - 22:08:04
[2025-06-11T22:08:04.526+0000] {logging_mixin.py:190} INFO - 22:08:04    Database Error in model stg_shopee (models/staging/stg_shopee.sql)
  cross-database references are not implemented: "sales_db.entry.entry_shopee"
  LINE 76:     FROM "sales_db"."entry"."entry_shopee"
                    ^
  compiled code at target/run/e_commerce_sales/models/staging/stg_shopee.sql
[2025-06-11T22:08:04.527+0000] {logging_mixin.py:190} INFO - 22:08:04
[2025-06-11T22:08:04.528+0000] {logging_mixin.py:190} INFO - 22:08:04  Done. PASS=0 WARN=0 ERROR=5 SKIP=16 TOTAL=21
[2025-06-11T22:08:05.381+0000] {logging_mixin.py:190} INFO - dbt run failed!
[2025-06-11T22:08:05.384+0000] {logging_mixin.py:190} INFO - None
[2025-06-11T22:08:05.386+0000] {taskinstance.py:3311} ERROR - Task failed with exception
Traceback (most recent call last):
  File "/home/airflow/.local/lib/python3.9/site-packages/airflow/models/taskinstance.py", line 767, in _execute_task
    result = _execute_callable(context=context, **execute_callable_kwargs)
  File "/home/airflow/.local/lib/python3.9/site-packages/airflow/models/taskinstance.py", line 733, in _execute_callable
    return ExecutionCallableRunner(
  File "/home/airflow/.local/lib/python3.9/site-packages/airflow/utils/operator_helpers.py", line 252, in run
    return self.func(*args, **kwargs)
  File "/home/airflow/.local/lib/python3.9/site-packages/airflow/models/baseoperator.py", line 422, in wrapper
    return func(self, *args, **kwargs)
  File "/home/airflow/.local/lib/python3.9/site-packages/airflow/operators/python.py", line 238, in execute
    return_value = self.execute_callable()
  File "/home/airflow/.local/lib/python3.9/site-packages/airflow/operators/python.py", line 256, in execute_callable
    return runner.run(*self.op_args, **self.op_kwargs)
  File "/home/airflow/.local/lib/python3.9/site-packages/airflow/utils/operator_helpers.py", line 252, in run
    return self.func(*args, **kwargs)
  File "/opt/airflow/dbt_files/run_dbt.py", line 24, in transform_data
    raise RuntimeError("dbt run failed")
RuntimeError: dbt run failed
[2025-06-11T22:08:05.398+0000] {taskinstance.py:1225} INFO - Marking task as FAILED. dag_id=05_transform_data_dev, task_id=run_dbt, run_id=manual__2025-06-11T22:07:48.225357+00:00, execution_date=20250611T220748, start_date=20250611T220757, end_date=20250611T220805
[2025-06-11T22:08:05.410+0000] {taskinstance.py:340} INFO - ::group::Post task execution logs
[2025-06-11T22:08:05.411+0000] {standard_task_runner.py:124} ERROR - Failed to execute job 928 for task run_dbt (dbt run failed; 4155)
Traceback (most recent call last):
  File "/home/airflow/.local/lib/python3.9/site-packages/airflow/task/task_runner/standard_task_runner.py", line 117, in _start_by_fork
    ret = args.func(args, dag=self.dag)
  File "/home/airflow/.local/lib/python3.9/site-packages/airflow/cli/cli_config.py", line 49, in command
    return func(*args, **kwargs)
  File "/home/airflow/.local/lib/python3.9/site-packages/airflow/utils/cli.py", line 116, in wrapper
    return f(*args, **kwargs)
  File "/home/airflow/.local/lib/python3.9/site-packages/airflow/cli/commands/task_command.py", line 483, in task_run
    task_return_code = _run_task_by_selected_method(args, _dag, ti)
  File "/home/airflow/.local/lib/python3.9/site-packages/airflow/cli/commands/task_command.py", line 256, in _run_task_by_selected_method
    return _run_raw_task(args, ti)
  File "/home/airflow/.local/lib/python3.9/site-packages/airflow/cli/commands/task_command.py", line 341, in _run_raw_task
    return ti._run_raw_task(
  File "/home/airflow/.local/lib/python3.9/site-packages/airflow/utils/session.py", line 97, in wrapper
    return func(*args, session=session, **kwargs)
  File "/home/airflow/.local/lib/python3.9/site-packages/airflow/models/taskinstance.py", line 3005, in _run_raw_task
    return _run_raw_task(
  File "/home/airflow/.local/lib/python3.9/site-packages/airflow/models/taskinstance.py", line 273, in _run_raw_task
    TaskInstance._execute_task_with_callbacks(
  File "/home/airflow/.local/lib/python3.9/site-packages/airflow/models/taskinstance.py", line 3159, in _execute_task_with_callbacks
    result = self._execute_task(context, task_orig)
  File "/home/airflow/.local/lib/python3.9/site-packages/airflow/models/taskinstance.py", line 3183, in _execute_task
    return _execute_task(self, context, task_orig)
  File "/home/airflow/.local/lib/python3.9/site-packages/airflow/models/taskinstance.py", line 767, in _execute_task
    result = _execute_callable(context=context, **execute_callable_kwargs)
  File "/home/airflow/.local/lib/python3.9/site-packages/airflow/models/taskinstance.py", line 733, in _execute_callable
    return ExecutionCallableRunner(
  File "/home/airflow/.local/lib/python3.9/site-packages/airflow/utils/operator_helpers.py", line 252, in run
    return self.func(*args, **kwargs)
  File "/home/airflow/.local/lib/python3.9/site-packages/airflow/models/baseoperator.py", line 422, in wrapper
    return func(self, *args, **kwargs)
  File "/home/airflow/.local/lib/python3.9/site-packages/airflow/operators/python.py", line 238, in execute
    return_value = self.execute_callable()
  File "/home/airflow/.local/lib/python3.9/site-packages/airflow/operators/python.py", line 256, in execute_callable
    return runner.run(*self.op_args, **self.op_kwargs)
  File "/home/airflow/.local/lib/python3.9/site-packages/airflow/utils/operator_helpers.py", line 252, in run
    return self.func(*args, **kwargs)
  File "/opt/airflow/dbt_files/run_dbt.py", line 24, in transform_data
    raise RuntimeError("dbt run failed")
RuntimeError: dbt run failed
[2025-06-11T22:08:05.434+0000] {local_task_job_runner.py:266} INFO - Task exited with return code 1
[2025-06-11T22:08:05.449+0000] {taskinstance.py:3895} INFO - 0 downstream tasks scheduled from follow-on schedule check
[2025-06-11T22:08:05.452+0000] {local_task_job_runner.py:245} INFO - ::endgroup::
