[2025-06-05T20:17:12.654+0000] {local_task_job_runner.py:123} INFO - ::group::Pre task execution logs
[2025-06-05T20:17:12.671+0000] {taskinstance.py:2613} INFO - Dependencies all met for dep_context=non-requeueable deps ti=<TaskInstance: 04_transform_data.run_dbt manual__2025-06-05T20:17:03.008576+00:00 [queued]>
[2025-06-05T20:17:12.679+0000] {taskinstance.py:2613} INFO - Dependencies all met for dep_context=requeueable deps ti=<TaskInstance: 04_transform_data.run_dbt manual__2025-06-05T20:17:03.008576+00:00 [queued]>
[2025-06-05T20:17:12.680+0000] {taskinstance.py:2866} INFO - Starting attempt 1 of 1
[2025-06-05T20:17:12.693+0000] {taskinstance.py:2889} INFO - Executing <Task(PythonOperator): run_dbt> on 2025-06-05 20:17:03.008576+00:00
[2025-06-05T20:17:12.703+0000] {standard_task_runner.py:72} INFO - Started process 2709 to run task
[2025-06-05T20:17:12.708+0000] {standard_task_runner.py:104} INFO - Running: ['***', 'tasks', 'run', '04_transform_data', 'run_dbt', 'manual__2025-06-05T20:17:03.008576+00:00', '--job-id', '351', '--raw', '--subdir', 'DAGS_FOLDER/04_transform_data.py', '--cfg-path', '/tmp/tmpo4_qc738']
[2025-06-05T20:17:12.711+0000] {standard_task_runner.py:105} INFO - Job 351: Subtask run_dbt
[2025-06-05T20:17:12.764+0000] {task_command.py:467} INFO - Running <TaskInstance: 04_transform_data.run_dbt manual__2025-06-05T20:17:03.008576+00:00 [running]> on host 28e6a58e4107
[2025-06-05T20:17:12.841+0000] {taskinstance.py:3132} INFO - Exporting env vars: AIRFLOW_CTX_DAG_OWNER='***' AIRFLOW_CTX_DAG_ID='04_transform_data' AIRFLOW_CTX_TASK_ID='run_dbt' AIRFLOW_CTX_EXECUTION_DATE='2025-06-05T20:17:03.008576+00:00' AIRFLOW_CTX_TRY_NUMBER='1' AIRFLOW_CTX_DAG_RUN_ID='manual__2025-06-05T20:17:03.008576+00:00'
[2025-06-05T20:17:12.843+0000] {taskinstance.py:731} INFO - ::endgroup::
[2025-06-05T20:17:14.342+0000] {logging_mixin.py:190} INFO - 20:17:14  Running with dbt=1.9.5
[2025-06-05T20:17:14.681+0000] {logging_mixin.py:190} INFO - 20:17:14  Registered adapter: postgres=1.9.0
[2025-06-05T20:17:15.950+0000] {logging_mixin.py:190} INFO - 20:17:15  [WARNING]: Configuration paths exist in your dbt_project.yml file which do not apply to any resources.
There are 1 unused configuration paths:
- models.e_commerce_sales.example
[2025-06-05T20:17:16.311+0000] {logging_mixin.py:190} INFO - 20:17:16  Found 11 models, 12 sources, 549 macros, 1 unit test
[2025-06-05T20:17:16.315+0000] {logging_mixin.py:190} INFO - 20:17:16
[2025-06-05T20:17:16.317+0000] {logging_mixin.py:190} INFO - 20:17:16  Concurrency: 4 threads (target='dev')
[2025-06-05T20:17:16.319+0000] {logging_mixin.py:190} INFO - 20:17:16
[2025-06-05T20:17:16.454+0000] {logging_mixin.py:190} INFO - 20:17:16  1 of 11 START sql incremental model sales.dim_shopee_product ................... [RUN]
[2025-06-05T20:17:16.456+0000] {logging_mixin.py:190} INFO - 20:17:16  2 of 11 START sql incremental model sales.mercadolivre_orders_results .......... [RUN]
[2025-06-05T20:17:16.458+0000] {logging_mixin.py:190} INFO - 20:17:16  3 of 11 START sql incremental model sales.shopee_new_id ........................ [RUN]
[2025-06-05T20:17:16.673+0000] {logging_mixin.py:190} INFO - 20:17:16  1 of 11 ERROR creating sql incremental model sales.dim_shopee_product .......... [ERROR in 0.21s]
[2025-06-05T20:17:16.753+0000] {logging_mixin.py:190} INFO - 20:17:16  3 of 11 OK created sql incremental model sales.shopee_new_id ................... [SELECT 2875 in 0.29s]
[2025-06-05T20:17:16.755+0000] {logging_mixin.py:190} INFO - 20:17:16  2 of 11 OK created sql incremental model sales.mercadolivre_orders_results ..... [SELECT 190 in 0.29s]
[2025-06-05T20:17:16.761+0000] {logging_mixin.py:190} INFO - 20:17:16  4 of 11 START sql incremental model sales.shopee_orders_results ................ [RUN]
[2025-06-05T20:17:16.766+0000] {logging_mixin.py:190} INFO - 20:17:16  5 of 11 START sql incremental model sales.dim_mercadolivre_buyer ............... [RUN]
[2025-06-05T20:17:16.768+0000] {logging_mixin.py:190} INFO - 20:17:16  6 of 11 START sql incremental model sales.dim_mercadolivre_date ................ [RUN]
[2025-06-05T20:17:16.770+0000] {logging_mixin.py:190} INFO - 20:17:16  7 of 11 START sql incremental model sales.dim_mercadolivre_orders_status ....... [RUN]
[2025-06-05T20:17:16.942+0000] {logging_mixin.py:190} INFO - 20:17:16  7 of 11 OK created sql incremental model sales.dim_mercadolivre_orders_status .. [SELECT 190 in 0.16s]
[2025-06-05T20:17:16.944+0000] {logging_mixin.py:190} INFO - 20:17:16  5 of 11 OK created sql incremental model sales.dim_mercadolivre_buyer .......... [SELECT 188 in 0.17s]
[2025-06-05T20:17:16.952+0000] {logging_mixin.py:190} INFO - 20:17:16  8 of 11 START sql incremental model sales.dim_mercadolivre_product ............. [RUN]
[2025-06-05T20:17:16.956+0000] {logging_mixin.py:190} INFO - 20:17:16  6 of 11 OK created sql incremental model sales.dim_mercadolivre_date ........... [SELECT 190 in 0.18s]
[2025-06-05T20:17:17.028+0000] {logging_mixin.py:190} INFO - 20:17:17  4 of 11 OK created sql incremental model sales.shopee_orders_results ........... [SELECT 2727 in 0.26s]
[2025-06-05T20:17:17.059+0000] {logging_mixin.py:190} INFO - 20:17:17  9 of 11 START sql incremental model sales.dim_shopee_buyer ..................... [RUN]
[2025-06-05T20:17:17.061+0000] {logging_mixin.py:190} INFO - 20:17:17  10 of 11 START sql incremental model sales.dim_shopee_date ..................... [RUN]
[2025-06-05T20:17:17.063+0000] {logging_mixin.py:190} INFO - 20:17:17  11 of 11 START sql incremental model sales.dim_shopee_orders_status ............ [RUN]
[2025-06-05T20:17:17.235+0000] {logging_mixin.py:190} INFO - 20:17:17  8 of 11 OK created sql incremental model sales.dim_mercadolivre_product ........ [MERGE 65 in 0.28s]
[2025-06-05T20:17:17.280+0000] {logging_mixin.py:190} INFO - 20:17:17  9 of 11 OK created sql incremental model sales.dim_shopee_buyer ................ [SELECT 7887 in 0.21s]
[2025-06-05T20:17:17.305+0000] {logging_mixin.py:190} INFO - 20:17:17  11 of 11 OK created sql incremental model sales.dim_shopee_orders_status ....... [SELECT 8193 in 0.23s]
[2025-06-05T20:17:17.312+0000] {logging_mixin.py:190} INFO - 20:17:17  10 of 11 OK created sql incremental model sales.dim_shopee_date ................ [SELECT 8181 in 0.24s]
[2025-06-05T20:17:17.335+0000] {logging_mixin.py:190} INFO - 20:17:17
[2025-06-05T20:17:17.337+0000] {logging_mixin.py:190} INFO - 20:17:17  Finished running 11 incremental models in 0 hours 0 minutes and 1.01 seconds (1.01s).
[2025-06-05T20:17:17.415+0000] {logging_mixin.py:190} INFO - 20:17:17
[2025-06-05T20:17:17.416+0000] {logging_mixin.py:190} INFO - 20:17:17  Completed with 1 error, 0 partial successes, and 0 warnings:
[2025-06-05T20:17:17.417+0000] {logging_mixin.py:190} INFO - 20:17:17
[2025-06-05T20:17:17.419+0000] {logging_mixin.py:190} INFO - 20:17:17    Database Error in model dim_shopee_product (models/core/dim_shopee_product.sql)
  relation "sales.shopee_orders_results" does not exist
  LINE 19:  FROM sales.shopee_orders_results
                 ^
[2025-06-05T20:17:17.420+0000] {logging_mixin.py:190} INFO - 20:17:17
[2025-06-05T20:17:17.422+0000] {logging_mixin.py:190} INFO - 20:17:17  Done. PASS=10 WARN=0 ERROR=1 SKIP=0 TOTAL=11
[2025-06-05T20:17:18.255+0000] {logging_mixin.py:190} INFO - dbt run failed!
[2025-06-05T20:17:18.257+0000] {logging_mixin.py:190} INFO - None
[2025-06-05T20:17:18.258+0000] {taskinstance.py:3311} ERROR - Task failed with exception
Traceback (most recent call last):
  File "/home/airflow/.local/lib/python3.9/site-packages/airflow/models/taskinstance.py", line 767, in _execute_task
    result = _execute_callable(context=context, **execute_callable_kwargs)
  File "/home/airflow/.local/lib/python3.9/site-packages/airflow/models/taskinstance.py", line 733, in _execute_callable
    return ExecutionCallableRunner(
  File "/home/airflow/.local/lib/python3.9/site-packages/airflow/utils/operator_helpers.py", line 252, in run
    return self.func(*args, **kwargs)
  File "/home/airflow/.local/lib/python3.9/site-packages/airflow/models/baseoperator.py", line 422, in wrapper
    return func(self, *args, **kwargs)
  File "/home/airflow/.local/lib/python3.9/site-packages/airflow/operators/python.py", line 238, in execute
    return_value = self.execute_callable()
  File "/home/airflow/.local/lib/python3.9/site-packages/airflow/operators/python.py", line 256, in execute_callable
    return runner.run(*self.op_args, **self.op_kwargs)
  File "/home/airflow/.local/lib/python3.9/site-packages/airflow/utils/operator_helpers.py", line 252, in run
    return self.func(*args, **kwargs)
  File "/opt/airflow/dbt_files/run_dbt.py", line 22, in transform_data
    raise RuntimeError("dbt run failed")
RuntimeError: dbt run failed
[2025-06-05T20:17:18.268+0000] {taskinstance.py:1225} INFO - Marking task as FAILED. dag_id=04_transform_data, task_id=run_dbt, run_id=manual__2025-06-05T20:17:03.008576+00:00, execution_date=20250605T201703, start_date=20250605T201712, end_date=20250605T201718
[2025-06-05T20:17:18.278+0000] {taskinstance.py:340} INFO - ::group::Post task execution logs
[2025-06-05T20:17:18.280+0000] {standard_task_runner.py:124} ERROR - Failed to execute job 351 for task run_dbt (dbt run failed; 2709)
Traceback (most recent call last):
  File "/home/airflow/.local/lib/python3.9/site-packages/airflow/task/task_runner/standard_task_runner.py", line 117, in _start_by_fork
    ret = args.func(args, dag=self.dag)
  File "/home/airflow/.local/lib/python3.9/site-packages/airflow/cli/cli_config.py", line 49, in command
    return func(*args, **kwargs)
  File "/home/airflow/.local/lib/python3.9/site-packages/airflow/utils/cli.py", line 116, in wrapper
    return f(*args, **kwargs)
  File "/home/airflow/.local/lib/python3.9/site-packages/airflow/cli/commands/task_command.py", line 483, in task_run
    task_return_code = _run_task_by_selected_method(args, _dag, ti)
  File "/home/airflow/.local/lib/python3.9/site-packages/airflow/cli/commands/task_command.py", line 256, in _run_task_by_selected_method
    return _run_raw_task(args, ti)
  File "/home/airflow/.local/lib/python3.9/site-packages/airflow/cli/commands/task_command.py", line 341, in _run_raw_task
    return ti._run_raw_task(
  File "/home/airflow/.local/lib/python3.9/site-packages/airflow/utils/session.py", line 97, in wrapper
    return func(*args, session=session, **kwargs)
  File "/home/airflow/.local/lib/python3.9/site-packages/airflow/models/taskinstance.py", line 3005, in _run_raw_task
    return _run_raw_task(
  File "/home/airflow/.local/lib/python3.9/site-packages/airflow/models/taskinstance.py", line 273, in _run_raw_task
    TaskInstance._execute_task_with_callbacks(
  File "/home/airflow/.local/lib/python3.9/site-packages/airflow/models/taskinstance.py", line 3159, in _execute_task_with_callbacks
    result = self._execute_task(context, task_orig)
  File "/home/airflow/.local/lib/python3.9/site-packages/airflow/models/taskinstance.py", line 3183, in _execute_task
    return _execute_task(self, context, task_orig)
  File "/home/airflow/.local/lib/python3.9/site-packages/airflow/models/taskinstance.py", line 767, in _execute_task
    result = _execute_callable(context=context, **execute_callable_kwargs)
  File "/home/airflow/.local/lib/python3.9/site-packages/airflow/models/taskinstance.py", line 733, in _execute_callable
    return ExecutionCallableRunner(
  File "/home/airflow/.local/lib/python3.9/site-packages/airflow/utils/operator_helpers.py", line 252, in run
    return self.func(*args, **kwargs)
  File "/home/airflow/.local/lib/python3.9/site-packages/airflow/models/baseoperator.py", line 422, in wrapper
    return func(self, *args, **kwargs)
  File "/home/airflow/.local/lib/python3.9/site-packages/airflow/operators/python.py", line 238, in execute
    return_value = self.execute_callable()
  File "/home/airflow/.local/lib/python3.9/site-packages/airflow/operators/python.py", line 256, in execute_callable
    return runner.run(*self.op_args, **self.op_kwargs)
  File "/home/airflow/.local/lib/python3.9/site-packages/airflow/utils/operator_helpers.py", line 252, in run
    return self.func(*args, **kwargs)
  File "/opt/airflow/dbt_files/run_dbt.py", line 22, in transform_data
    raise RuntimeError("dbt run failed")
RuntimeError: dbt run failed
[2025-06-05T20:17:18.330+0000] {local_task_job_runner.py:266} INFO - Task exited with return code 1
[2025-06-05T20:17:18.348+0000] {taskinstance.py:3895} INFO - 0 downstream tasks scheduled from follow-on schedule check
[2025-06-05T20:17:18.352+0000] {local_task_job_runner.py:245} INFO - ::endgroup::
