[2025-05-22T14:22:14.407+0000] {local_task_job_runner.py:123} INFO - ::group::Pre task execution logs
[2025-05-22T14:22:14.426+0000] {taskinstance.py:2613} INFO - Dependencies all met for dep_context=non-requeueable deps ti=<TaskInstance: 04_transform_data.run_dbt manual__2025-05-22T14:22:12.637353+00:00 [queued]>
[2025-05-22T14:22:14.435+0000] {taskinstance.py:2613} INFO - Dependencies all met for dep_context=requeueable deps ti=<TaskInstance: 04_transform_data.run_dbt manual__2025-05-22T14:22:12.637353+00:00 [queued]>
[2025-05-22T14:22:14.437+0000] {taskinstance.py:2866} INFO - Starting attempt 1 of 1
[2025-05-22T14:22:14.449+0000] {taskinstance.py:2889} INFO - Executing <Task(PythonOperator): run_dbt> on 2025-05-22 14:22:12.637353+00:00
[2025-05-22T14:22:14.454+0000] {standard_task_runner.py:72} INFO - Started process 974 to run task
[2025-05-22T14:22:14.457+0000] {standard_task_runner.py:104} INFO - Running: ['***', 'tasks', 'run', '04_transform_data', 'run_dbt', 'manual__2025-05-22T14:22:12.637353+00:00', '--job-id', '180', '--raw', '--subdir', 'DAGS_FOLDER/04_transform_data.py', '--cfg-path', '/tmp/tmpvaw79t8s']
[2025-05-22T14:22:14.459+0000] {standard_task_runner.py:105} INFO - Job 180: Subtask run_dbt
[2025-05-22T14:22:14.511+0000] {task_command.py:467} INFO - Running <TaskInstance: 04_transform_data.run_dbt manual__2025-05-22T14:22:12.637353+00:00 [running]> on host e27e96d1841a
[2025-05-22T14:22:14.593+0000] {taskinstance.py:3132} INFO - Exporting env vars: AIRFLOW_CTX_DAG_OWNER='***' AIRFLOW_CTX_DAG_ID='04_transform_data' AIRFLOW_CTX_TASK_ID='run_dbt' AIRFLOW_CTX_EXECUTION_DATE='2025-05-22T14:22:12.637353+00:00' AIRFLOW_CTX_TRY_NUMBER='1' AIRFLOW_CTX_DAG_RUN_ID='manual__2025-05-22T14:22:12.637353+00:00'
[2025-05-22T14:22:14.595+0000] {taskinstance.py:731} INFO - ::endgroup::
[2025-05-22T14:22:16.205+0000] {logging_mixin.py:190} INFO - 14:22:16  Running with dbt=1.9.4
[2025-05-22T14:22:16.546+0000] {logging_mixin.py:190} INFO - 14:22:16  Registered adapter: postgres=1.9.0
[2025-05-22T14:22:17.665+0000] {logging_mixin.py:190} INFO - 14:22:17  [WARNING]: Configuration paths exist in your dbt_project.yml file which do not apply to any resources.
There are 1 unused configuration paths:
- models.e_commerce_sales.example
[2025-05-22T14:22:17.831+0000] {logging_mixin.py:190} INFO - 14:22:17  Found 12 models, 12 sources, 433 macros
[2025-05-22T14:22:17.836+0000] {logging_mixin.py:190} INFO - 14:22:17
[2025-05-22T14:22:17.837+0000] {logging_mixin.py:190} INFO - 14:22:17  Concurrency: 4 threads (target='dev')
[2025-05-22T14:22:17.838+0000] {logging_mixin.py:190} INFO - 14:22:17
[2025-05-22T14:22:17.970+0000] {logging_mixin.py:190} INFO - 14:22:17  1 of 12 START sql incremental model sales.mercadolivre_orders_results .......... [RUN]
[2025-05-22T14:22:17.972+0000] {logging_mixin.py:190} INFO - 14:22:17  2 of 12 START sql incremental model sales.shopee_new_id ........................ [RUN]
[2025-05-22T14:22:18.198+0000] {logging_mixin.py:190} INFO - 14:22:18  1 of 12 ERROR creating sql incremental model sales.mercadolivre_orders_results . [ERROR in 0.21s]
[2025-05-22T14:22:18.220+0000] {logging_mixin.py:190} INFO - 14:22:18  3 of 12 SKIP relation sales.dim_mercadolivre_buyer ............................. [SKIP]
[2025-05-22T14:22:18.221+0000] {logging_mixin.py:190} INFO - 14:22:18  4 of 12 SKIP relation sales.dim_mercadolivre_date .............................. [SKIP]
[2025-05-22T14:22:18.223+0000] {logging_mixin.py:190} INFO - 14:22:18  5 of 12 SKIP relation sales.dim_mercadolivre_orders_status ..................... [SKIP]
[2025-05-22T14:22:18.234+0000] {logging_mixin.py:190} INFO - 14:22:18  6 of 12 SKIP relation sales.dim_mercadolivre_product ........................... [SKIP]
[2025-05-22T14:22:18.267+0000] {logging_mixin.py:190} INFO - 14:22:18  7 of 12 SKIP relation sales.mercadolivre_profits ............................... [SKIP]
[2025-05-22T14:22:18.317+0000] {logging_mixin.py:190} INFO - 14:22:18  2 of 12 OK created sql incremental model sales.shopee_new_id ................... [MERGE 0 in 0.34s]
[2025-05-22T14:22:18.323+0000] {logging_mixin.py:190} INFO - 14:22:18  8 of 12 START sql incremental model sales.shopee_orders_results ................ [RUN]
[2025-05-22T14:22:18.442+0000] {logging_mixin.py:190} INFO - 14:22:18  8 of 12 OK created sql incremental model sales.shopee_orders_results ........... [MERGE 0 in 0.12s]
[2025-05-22T14:22:18.448+0000] {logging_mixin.py:190} INFO - 14:22:18  9 of 12 START sql incremental model sales.dim_shopee_buyer_id .................. [RUN]
[2025-05-22T14:22:18.450+0000] {logging_mixin.py:190} INFO - 14:22:18  10 of 12 START sql incremental model sales.dim_shopee_date ..................... [RUN]
[2025-05-22T14:22:18.451+0000] {logging_mixin.py:190} INFO - 14:22:18  11 of 12 START sql incremental model sales.dim_shopee_orders_status ............ [RUN]
[2025-05-22T14:22:18.453+0000] {logging_mixin.py:190} INFO - 14:22:18  12 of 12 START sql incremental model sales.dim_shopee_product .................. [RUN]
[2025-05-22T14:22:18.749+0000] {logging_mixin.py:190} INFO - 14:22:18  9 of 12 OK created sql incremental model sales.dim_shopee_buyer_id ............. [MERGE 0 in 0.29s]
[2025-05-22T14:22:18.756+0000] {logging_mixin.py:190} INFO - 14:22:18  11 of 12 OK created sql incremental model sales.dim_shopee_orders_status ....... [MERGE 0 in 0.29s]
[2025-05-22T14:22:18.759+0000] {logging_mixin.py:190} INFO - 14:22:18  12 of 12 OK created sql incremental model sales.dim_shopee_product ............. [MERGE 0 in 0.29s]
[2025-05-22T14:22:18.761+0000] {logging_mixin.py:190} INFO - 14:22:18  10 of 12 OK created sql incremental model sales.dim_shopee_date ................ [MERGE 0 in 0.30s]
[2025-05-22T14:22:18.789+0000] {logging_mixin.py:190} INFO - 14:22:18
[2025-05-22T14:22:18.790+0000] {logging_mixin.py:190} INFO - 14:22:18  Finished running 12 incremental models in 0 hours 0 minutes and 0.95 seconds (0.95s).
[2025-05-22T14:22:18.858+0000] {logging_mixin.py:190} INFO - 14:22:18
[2025-05-22T14:22:18.860+0000] {logging_mixin.py:190} INFO - 14:22:18  Completed with 1 error, 0 partial successes, and 0 warnings:
[2025-05-22T14:22:18.862+0000] {logging_mixin.py:190} INFO - 14:22:18
[2025-05-22T14:22:18.863+0000] {logging_mixin.py:190} INFO - 14:22:18    Database Error in model mercadolivre_orders_results (models/core/mercadolivre_orders_results.sql)
  missing FROM-clause entry for table "add_timestamp"
  LINE 60:            add_timestamp.ld_timestamp
                      ^
  compiled code at target/run/e_commerce_sales/models/core/mercadolivre_orders_results.sql
[2025-05-22T14:22:18.865+0000] {logging_mixin.py:190} INFO - 14:22:18
[2025-05-22T14:22:18.866+0000] {logging_mixin.py:190} INFO - 14:22:18  Done. PASS=6 WARN=0 ERROR=1 SKIP=5 TOTAL=12
[2025-05-22T14:22:19.725+0000] {logging_mixin.py:190} INFO - dbt run failed!
[2025-05-22T14:22:19.726+0000] {logging_mixin.py:190} INFO - None
[2025-05-22T14:22:19.727+0000] {taskinstance.py:3311} ERROR - Task failed with exception
Traceback (most recent call last):
  File "/home/airflow/.local/lib/python3.9/site-packages/airflow/models/taskinstance.py", line 767, in _execute_task
    result = _execute_callable(context=context, **execute_callable_kwargs)
  File "/home/airflow/.local/lib/python3.9/site-packages/airflow/models/taskinstance.py", line 733, in _execute_callable
    return ExecutionCallableRunner(
  File "/home/airflow/.local/lib/python3.9/site-packages/airflow/utils/operator_helpers.py", line 252, in run
    return self.func(*args, **kwargs)
  File "/home/airflow/.local/lib/python3.9/site-packages/airflow/models/baseoperator.py", line 422, in wrapper
    return func(self, *args, **kwargs)
  File "/home/airflow/.local/lib/python3.9/site-packages/airflow/operators/python.py", line 238, in execute
    return_value = self.execute_callable()
  File "/home/airflow/.local/lib/python3.9/site-packages/airflow/operators/python.py", line 256, in execute_callable
    return runner.run(*self.op_args, **self.op_kwargs)
  File "/home/airflow/.local/lib/python3.9/site-packages/airflow/utils/operator_helpers.py", line 252, in run
    return self.func(*args, **kwargs)
  File "/opt/airflow/dbt/run_dbt.py", line 22, in transform_data
    raise RuntimeError("dbt run failed")
RuntimeError: dbt run failed
[2025-05-22T14:22:19.738+0000] {taskinstance.py:1225} INFO - Marking task as FAILED. dag_id=04_transform_data, task_id=run_dbt, run_id=manual__2025-05-22T14:22:12.637353+00:00, execution_date=20250522T142212, start_date=20250522T142214, end_date=20250522T142219
[2025-05-22T14:22:19.750+0000] {taskinstance.py:340} INFO - ::group::Post task execution logs
[2025-05-22T14:22:19.752+0000] {standard_task_runner.py:124} ERROR - Failed to execute job 180 for task run_dbt (dbt run failed; 974)
Traceback (most recent call last):
  File "/home/airflow/.local/lib/python3.9/site-packages/airflow/task/task_runner/standard_task_runner.py", line 117, in _start_by_fork
    ret = args.func(args, dag=self.dag)
  File "/home/airflow/.local/lib/python3.9/site-packages/airflow/cli/cli_config.py", line 49, in command
    return func(*args, **kwargs)
  File "/home/airflow/.local/lib/python3.9/site-packages/airflow/utils/cli.py", line 116, in wrapper
    return f(*args, **kwargs)
  File "/home/airflow/.local/lib/python3.9/site-packages/airflow/cli/commands/task_command.py", line 483, in task_run
    task_return_code = _run_task_by_selected_method(args, _dag, ti)
  File "/home/airflow/.local/lib/python3.9/site-packages/airflow/cli/commands/task_command.py", line 256, in _run_task_by_selected_method
    return _run_raw_task(args, ti)
  File "/home/airflow/.local/lib/python3.9/site-packages/airflow/cli/commands/task_command.py", line 341, in _run_raw_task
    return ti._run_raw_task(
  File "/home/airflow/.local/lib/python3.9/site-packages/airflow/utils/session.py", line 97, in wrapper
    return func(*args, session=session, **kwargs)
  File "/home/airflow/.local/lib/python3.9/site-packages/airflow/models/taskinstance.py", line 3005, in _run_raw_task
    return _run_raw_task(
  File "/home/airflow/.local/lib/python3.9/site-packages/airflow/models/taskinstance.py", line 273, in _run_raw_task
    TaskInstance._execute_task_with_callbacks(
  File "/home/airflow/.local/lib/python3.9/site-packages/airflow/models/taskinstance.py", line 3159, in _execute_task_with_callbacks
    result = self._execute_task(context, task_orig)
  File "/home/airflow/.local/lib/python3.9/site-packages/airflow/models/taskinstance.py", line 3183, in _execute_task
    return _execute_task(self, context, task_orig)
  File "/home/airflow/.local/lib/python3.9/site-packages/airflow/models/taskinstance.py", line 767, in _execute_task
    result = _execute_callable(context=context, **execute_callable_kwargs)
  File "/home/airflow/.local/lib/python3.9/site-packages/airflow/models/taskinstance.py", line 733, in _execute_callable
    return ExecutionCallableRunner(
  File "/home/airflow/.local/lib/python3.9/site-packages/airflow/utils/operator_helpers.py", line 252, in run
    return self.func(*args, **kwargs)
  File "/home/airflow/.local/lib/python3.9/site-packages/airflow/models/baseoperator.py", line 422, in wrapper
    return func(self, *args, **kwargs)
  File "/home/airflow/.local/lib/python3.9/site-packages/airflow/operators/python.py", line 238, in execute
    return_value = self.execute_callable()
  File "/home/airflow/.local/lib/python3.9/site-packages/airflow/operators/python.py", line 256, in execute_callable
    return runner.run(*self.op_args, **self.op_kwargs)
  File "/home/airflow/.local/lib/python3.9/site-packages/airflow/utils/operator_helpers.py", line 252, in run
    return self.func(*args, **kwargs)
  File "/opt/airflow/dbt/run_dbt.py", line 22, in transform_data
    raise RuntimeError("dbt run failed")
RuntimeError: dbt run failed
[2025-05-22T14:22:19.773+0000] {local_task_job_runner.py:266} INFO - Task exited with return code 1
[2025-05-22T14:22:19.790+0000] {taskinstance.py:3895} INFO - 0 downstream tasks scheduled from follow-on schedule check
[2025-05-22T14:22:19.793+0000] {local_task_job_runner.py:245} INFO - ::endgroup::
