[2025-05-21T20:19:19.369+0000] {local_task_job_runner.py:123} INFO - ::group::Pre task execution logs
[2025-05-21T20:19:19.388+0000] {taskinstance.py:2613} INFO - Dependencies all met for dep_context=non-requeueable deps ti=<TaskInstance: 04_transform_data.run_dbt manual__2025-05-21T20:19:17.387488+00:00 [queued]>
[2025-05-21T20:19:19.396+0000] {taskinstance.py:2613} INFO - Dependencies all met for dep_context=requeueable deps ti=<TaskInstance: 04_transform_data.run_dbt manual__2025-05-21T20:19:17.387488+00:00 [queued]>
[2025-05-21T20:19:19.398+0000] {taskinstance.py:2866} INFO - Starting attempt 1 of 1
[2025-05-21T20:19:19.410+0000] {taskinstance.py:2889} INFO - Executing <Task(PythonOperator): run_dbt> on 2025-05-21 20:19:17.387488+00:00
[2025-05-21T20:19:19.414+0000] {standard_task_runner.py:72} INFO - Started process 4932 to run task
[2025-05-21T20:19:19.418+0000] {standard_task_runner.py:104} INFO - Running: ['***', 'tasks', 'run', '04_transform_data', 'run_dbt', 'manual__2025-05-21T20:19:17.387488+00:00', '--job-id', '124', '--raw', '--subdir', 'DAGS_FOLDER/04_transform_data.py', '--cfg-path', '/tmp/tmp12b2e_wu']
[2025-05-21T20:19:19.420+0000] {standard_task_runner.py:105} INFO - Job 124: Subtask run_dbt
[2025-05-21T20:19:19.472+0000] {task_command.py:467} INFO - Running <TaskInstance: 04_transform_data.run_dbt manual__2025-05-21T20:19:17.387488+00:00 [running]> on host e27e96d1841a
[2025-05-21T20:19:19.554+0000] {taskinstance.py:3132} INFO - Exporting env vars: AIRFLOW_CTX_DAG_OWNER='***' AIRFLOW_CTX_DAG_ID='04_transform_data' AIRFLOW_CTX_TASK_ID='run_dbt' AIRFLOW_CTX_EXECUTION_DATE='2025-05-21T20:19:17.387488+00:00' AIRFLOW_CTX_TRY_NUMBER='1' AIRFLOW_CTX_DAG_RUN_ID='manual__2025-05-21T20:19:17.387488+00:00'
[2025-05-21T20:19:19.556+0000] {taskinstance.py:731} INFO - ::endgroup::
[2025-05-21T20:19:21.175+0000] {logging_mixin.py:190} INFO - 20:19:21  Running with dbt=1.9.4
[2025-05-21T20:19:21.515+0000] {logging_mixin.py:190} INFO - 20:19:21  Registered adapter: postgres=1.9.0
[2025-05-21T20:19:22.791+0000] {logging_mixin.py:190} INFO - 20:19:22  [WARNING]: Configuration paths exist in your dbt_project.yml file which do not apply to any resources.
There are 1 unused configuration paths:
- models.e_commerce_sales.example
[2025-05-21T20:19:22.977+0000] {logging_mixin.py:190} INFO - 20:19:22  Found 11 models, 12 sources, 433 macros
[2025-05-21T20:19:22.982+0000] {logging_mixin.py:190} INFO - 20:19:22
[2025-05-21T20:19:22.984+0000] {logging_mixin.py:190} INFO - 20:19:22  Concurrency: 4 threads (target='dev')
[2025-05-21T20:19:22.986+0000] {logging_mixin.py:190} INFO - 20:19:22
[2025-05-21T20:19:23.126+0000] {logging_mixin.py:190} INFO - 20:19:23  1 of 11 START sql incremental model sales.mercadolivre_orders_results .......... [RUN]
[2025-05-21T20:19:23.128+0000] {logging_mixin.py:190} INFO - 20:19:23  2 of 11 START sql incremental model sales.shopee_new_id ........................ [RUN]
[2025-05-21T20:19:23.445+0000] {logging_mixin.py:190} INFO - 20:19:23  1 of 11 OK created sql incremental model sales.mercadolivre_orders_results ..... [SELECT 255 in 0.30s]
[2025-05-21T20:19:23.452+0000] {logging_mixin.py:190} INFO - 20:19:23  3 of 11 START sql incremental model sales.dim_mercadolivre_buyer ............... [RUN]
[2025-05-21T20:19:23.455+0000] {logging_mixin.py:190} INFO - 20:19:23  4 of 11 START sql incremental model sales.dim_mercadolivre_date ................ [RUN]
[2025-05-21T20:19:23.456+0000] {logging_mixin.py:190} INFO - 20:19:23  5 of 11 START sql incremental model sales.dim_mercadolivre_product ............. [RUN]
[2025-05-21T20:19:23.540+0000] {logging_mixin.py:190} INFO - 20:19:23  2 of 11 OK created sql incremental model sales.shopee_new_id ................... [MERGE 0 in 0.40s]
[2025-05-21T20:19:23.549+0000] {logging_mixin.py:190} INFO - 20:19:23  6 of 11 START sql incremental model sales.mercadolivre_profits ................. [RUN]
[2025-05-21T20:19:23.746+0000] {logging_mixin.py:190} INFO - 20:19:23  3 of 11 ERROR creating sql incremental model sales.dim_mercadolivre_buyer ...... [ERROR in 0.28s]
[2025-05-21T20:19:23.759+0000] {logging_mixin.py:190} INFO - 20:19:23  5 of 11 OK created sql incremental model sales.dim_mercadolivre_product ........ [MERGE 250 in 0.29s]
[2025-05-21T20:19:23.761+0000] {logging_mixin.py:190} INFO - 20:19:23  4 of 11 OK created sql incremental model sales.dim_mercadolivre_date ........... [MERGE 272 in 0.29s]
[2025-05-21T20:19:23.763+0000] {logging_mixin.py:190} INFO - 20:19:23  7 of 11 START sql incremental model sales.shopee_orders_results ................ [RUN]
[2025-05-21T20:19:23.798+0000] {logging_mixin.py:190} INFO - 20:19:23  6 of 11 OK created sql incremental model sales.mercadolivre_profits ............ [MERGE 250 in 0.24s]
[2025-05-21T20:19:23.891+0000] {logging_mixin.py:190} INFO - 20:19:23  7 of 11 OK created sql incremental model sales.shopee_orders_results ........... [MERGE 0 in 0.12s]
[2025-05-21T20:19:23.898+0000] {logging_mixin.py:190} INFO - 20:19:23  8 of 11 START sql incremental model sales.dim_shopee_buyer_id .................. [RUN]
[2025-05-21T20:19:23.900+0000] {logging_mixin.py:190} INFO - 20:19:23  9 of 11 START sql incremental model sales.dim_shopee_date ...................... [RUN]
[2025-05-21T20:19:23.902+0000] {logging_mixin.py:190} INFO - 20:19:23  10 of 11 START sql incremental model sales.dim_shopee_orders_status ............ [RUN]
[2025-05-21T20:19:23.903+0000] {logging_mixin.py:190} INFO - 20:19:23  11 of 11 START sql incremental model sales.dim_shopee_product .................. [RUN]
[2025-05-21T20:19:24.198+0000] {logging_mixin.py:190} INFO - 20:19:24  9 of 11 OK created sql incremental model sales.dim_shopee_date ................. [MERGE 0 in 0.29s]
[2025-05-21T20:19:24.202+0000] {logging_mixin.py:190} INFO - 20:19:24  11 of 11 OK created sql incremental model sales.dim_shopee_product ............. [MERGE 0 in 0.29s]
[2025-05-21T20:19:24.211+0000] {logging_mixin.py:190} INFO - 20:19:24  10 of 11 OK created sql incremental model sales.dim_shopee_orders_status ....... [MERGE 0 in 0.30s]
[2025-05-21T20:19:24.214+0000] {logging_mixin.py:190} INFO - 20:19:24  8 of 11 OK created sql incremental model sales.dim_shopee_buyer_id ............. [MERGE 0 in 0.31s]
[2025-05-21T20:19:24.240+0000] {logging_mixin.py:190} INFO - 20:19:24
[2025-05-21T20:19:24.242+0000] {logging_mixin.py:190} INFO - 20:19:24  Finished running 11 incremental models in 0 hours 0 minutes and 1.25 seconds (1.25s).
[2025-05-21T20:19:24.322+0000] {logging_mixin.py:190} INFO - 20:19:24
[2025-05-21T20:19:24.323+0000] {logging_mixin.py:190} INFO - 20:19:24  Completed with 1 error, 0 partial successes, and 0 warnings:
[2025-05-21T20:19:24.325+0000] {logging_mixin.py:190} INFO - 20:19:24
[2025-05-21T20:19:24.327+0000] {logging_mixin.py:190} INFO - 20:19:24    Database Error in model dim_mercadolivre_buyer (models/core/dim_mercadolivre_buyer.sql)
  MERGE command cannot affect row a second time
  HINT:  Ensure that not more than one source row matches any one target row.
  compiled code at target/run/e_commerce_sales/models/core/dim_mercadolivre_buyer.sql
[2025-05-21T20:19:24.329+0000] {logging_mixin.py:190} INFO - 20:19:24
[2025-05-21T20:19:24.330+0000] {logging_mixin.py:190} INFO - 20:19:24  Done. PASS=10 WARN=0 ERROR=1 SKIP=0 TOTAL=11
[2025-05-21T20:19:25.244+0000] {logging_mixin.py:190} INFO - dbt run failed!
[2025-05-21T20:19:25.245+0000] {logging_mixin.py:190} INFO - None
[2025-05-21T20:19:25.246+0000] {taskinstance.py:3311} ERROR - Task failed with exception
Traceback (most recent call last):
  File "/home/airflow/.local/lib/python3.9/site-packages/airflow/models/taskinstance.py", line 767, in _execute_task
    result = _execute_callable(context=context, **execute_callable_kwargs)
  File "/home/airflow/.local/lib/python3.9/site-packages/airflow/models/taskinstance.py", line 733, in _execute_callable
    return ExecutionCallableRunner(
  File "/home/airflow/.local/lib/python3.9/site-packages/airflow/utils/operator_helpers.py", line 252, in run
    return self.func(*args, **kwargs)
  File "/home/airflow/.local/lib/python3.9/site-packages/airflow/models/baseoperator.py", line 422, in wrapper
    return func(self, *args, **kwargs)
  File "/home/airflow/.local/lib/python3.9/site-packages/airflow/operators/python.py", line 238, in execute
    return_value = self.execute_callable()
  File "/home/airflow/.local/lib/python3.9/site-packages/airflow/operators/python.py", line 256, in execute_callable
    return runner.run(*self.op_args, **self.op_kwargs)
  File "/home/airflow/.local/lib/python3.9/site-packages/airflow/utils/operator_helpers.py", line 252, in run
    return self.func(*args, **kwargs)
  File "/opt/airflow/dbt/run_dbt.py", line 22, in transform_data
    raise RuntimeError("dbt run failed")
RuntimeError: dbt run failed
[2025-05-21T20:19:25.256+0000] {taskinstance.py:1225} INFO - Marking task as FAILED. dag_id=04_transform_data, task_id=run_dbt, run_id=manual__2025-05-21T20:19:17.387488+00:00, execution_date=20250521T201917, start_date=20250521T201919, end_date=20250521T201925
[2025-05-21T20:19:25.268+0000] {taskinstance.py:340} INFO - ::group::Post task execution logs
[2025-05-21T20:19:25.269+0000] {standard_task_runner.py:124} ERROR - Failed to execute job 124 for task run_dbt (dbt run failed; 4932)
Traceback (most recent call last):
  File "/home/airflow/.local/lib/python3.9/site-packages/airflow/task/task_runner/standard_task_runner.py", line 117, in _start_by_fork
    ret = args.func(args, dag=self.dag)
  File "/home/airflow/.local/lib/python3.9/site-packages/airflow/cli/cli_config.py", line 49, in command
    return func(*args, **kwargs)
  File "/home/airflow/.local/lib/python3.9/site-packages/airflow/utils/cli.py", line 116, in wrapper
    return f(*args, **kwargs)
  File "/home/airflow/.local/lib/python3.9/site-packages/airflow/cli/commands/task_command.py", line 483, in task_run
    task_return_code = _run_task_by_selected_method(args, _dag, ti)
  File "/home/airflow/.local/lib/python3.9/site-packages/airflow/cli/commands/task_command.py", line 256, in _run_task_by_selected_method
    return _run_raw_task(args, ti)
  File "/home/airflow/.local/lib/python3.9/site-packages/airflow/cli/commands/task_command.py", line 341, in _run_raw_task
    return ti._run_raw_task(
  File "/home/airflow/.local/lib/python3.9/site-packages/airflow/utils/session.py", line 97, in wrapper
    return func(*args, session=session, **kwargs)
  File "/home/airflow/.local/lib/python3.9/site-packages/airflow/models/taskinstance.py", line 3005, in _run_raw_task
    return _run_raw_task(
  File "/home/airflow/.local/lib/python3.9/site-packages/airflow/models/taskinstance.py", line 273, in _run_raw_task
    TaskInstance._execute_task_with_callbacks(
  File "/home/airflow/.local/lib/python3.9/site-packages/airflow/models/taskinstance.py", line 3159, in _execute_task_with_callbacks
    result = self._execute_task(context, task_orig)
  File "/home/airflow/.local/lib/python3.9/site-packages/airflow/models/taskinstance.py", line 3183, in _execute_task
    return _execute_task(self, context, task_orig)
  File "/home/airflow/.local/lib/python3.9/site-packages/airflow/models/taskinstance.py", line 767, in _execute_task
    result = _execute_callable(context=context, **execute_callable_kwargs)
  File "/home/airflow/.local/lib/python3.9/site-packages/airflow/models/taskinstance.py", line 733, in _execute_callable
    return ExecutionCallableRunner(
  File "/home/airflow/.local/lib/python3.9/site-packages/airflow/utils/operator_helpers.py", line 252, in run
    return self.func(*args, **kwargs)
  File "/home/airflow/.local/lib/python3.9/site-packages/airflow/models/baseoperator.py", line 422, in wrapper
    return func(self, *args, **kwargs)
  File "/home/airflow/.local/lib/python3.9/site-packages/airflow/operators/python.py", line 238, in execute
    return_value = self.execute_callable()
  File "/home/airflow/.local/lib/python3.9/site-packages/airflow/operators/python.py", line 256, in execute_callable
    return runner.run(*self.op_args, **self.op_kwargs)
  File "/home/airflow/.local/lib/python3.9/site-packages/airflow/utils/operator_helpers.py", line 252, in run
    return self.func(*args, **kwargs)
  File "/opt/airflow/dbt/run_dbt.py", line 22, in transform_data
    raise RuntimeError("dbt run failed")
RuntimeError: dbt run failed
[2025-05-21T20:19:25.295+0000] {local_task_job_runner.py:266} INFO - Task exited with return code 1
[2025-05-21T20:19:25.312+0000] {taskinstance.py:3895} INFO - 0 downstream tasks scheduled from follow-on schedule check
[2025-05-21T20:19:25.318+0000] {local_task_job_runner.py:245} INFO - ::endgroup::
